Workbook

Sheet Buff.CM
A1: #ID | B1: #조건 | C1: #조건 값 (백분율) | D1: #지속시간 천분율 | E1: #맥스 스택 | F1: #추가 스택 | G1: #Buff Effect | H1: #END Effect | I1: #Ture버프 해제불가 | J1: #사망 버프삭제 | K1: #버프, 디버프 | L1: #프리팹 | M1: #아이콘 | N1: #이름 | O1: #설명 | P1: #자동 설명 | Q1: #Hud 노출
A2: Id | B2: ActiveCondition | C2: ConditionValue | D2: Duration | E2: MaxStack | F2: AddStack | G2: Effects | H2: EndEffects | I2: Removeable | J2: RemoveDead | K2: BuffType | L2: Prefabs | M2: Icon | N2: Name | O2: Desc | P2: UseAutoDesc | Q2: Showhit
A3: *string | B3: ActiveCondition? | C3: string | D3: int | E3: int | F3: int | G3: [$BuffEffect] | H3: [$SkillEffect] | I3: bool | J3: bool | K3: bool | L3: [string] | M3: string | N3: string | O3: string | P3: bool | Q3: bool
A4: common | B4: common | C4: common | D4: common | E4: common | F4: common | G4: common | H4: common | I4: common | J4: common | K4: common | L4: client | M4: client | N4: client | O4: client | P4: client | Q4: common
A5: comingsoon | D5: 0 | E5: 0 | F5: 0 | G5: comingsoon | I5: FALSE | J5: FALSE | K5: TRUE | P5: FALSE | Q5: FALSE
A6: comingsoon.test.buff.01 | D6: 10000 | E6: 0 | F6: 0 | G6: comingsoon.test.buff.buffeffect.01 | I6: FALSE | J6: FALSE | K6: TRUE | M6: icon_battle_damagederate | P6: FALSE | Q6: FALSE
A7: comingsoon.test.buff.02 | D7: 10000 | E7: 0 | F7: 0 | G7: comingsoon.test.buff.buffeffect.02 | I7: FALSE | J7: FALSE | K7: TRUE | M7: icon_battle_damagederate | P7: FALSE | Q7: FALSE
A8: resist.cc | D8: 0 | E8: 0 | F8: 0 | G8: resist.cc | I8: FALSE | J8: FALSE | K8: TRUE | P8: FALSE | Q8: FALSE
A9: ccimmune | D9: 20000 | E9: 0 | F9: 0 | G9: ccimmune | I9: FALSE | J9: FALSE | K9: TRUE | L9: Effect/Prefab/10_buff/EFF_buff_invincible Effect/Prefab/10_buff/EFF_immune | M9: icon_battle_ccimmune | N9: Buff.Name.CCImmune | O9: Buff.Desc.CCImmune | P9: FALSE | Q9: FALSE
A10: damageimmune | D10: 5000 | E10: 0 | F10: 0 | G10: damageimmune burndamageimmune poisondamageimmune bleeddamageimmune | I10: FALSE | J10: FALSE | K10: TRUE | L10: Effect/Prefab/10_buff/EFF_buff_invincible Effect/Prefab/10_buff/EFF_immune | M10: icon_battle_damageimmune | N10: Buff.Name.DamageImmune | O10: Buff.Desc.DamageImmune | P10: FALSE | Q10: FALSE
A11: normaldamageimmune | D11: 5000 | E11: 0 | F11: 0 | G11: damageimmune | I11: FALSE | J11: FALSE | K11: TRUE | L11: Effect/Prefab/10_buff/EFF_buff_invincible Effect/Prefab/10_buff/EFF_immune | M11: icon_battle_damageimmune | N11: Buff.Name.NormalDamageImmune | O11: Buff.Desc.NormalDamageImmune | P11: FALSE | Q11: FALSE
A12: dotdamageimmune | D12: 5000 | E12: 0 | F12: 0 | G12: burndamageimmune poisondamageimmune bleeddamageimmune | I12: FALSE | J12: FALSE | K12: TRUE | L12: Effect/Prefab/10_buff/EFF_buff_invincible Effect/Prefab/10_buff/EFF_immune | M12: icon_battle_damageimmune | N12: Buff.Name.DotDamageImmune | O12: Buff.Desc.DotDamageImmune | P12: FALSE | Q12: FALSE
A13: pre.damageimmune | D13: 0 | E13: 0 | F13: 0 | G13: damageimmune burndamageimmune poisondamageimmune bleeddamageimmune | I13: FALSE | J13: FALSE | K13: TRUE | L13: Effect/Prefab/10_buff/EFF_buff_invincible Effect/Prefab/10_buff/EFF_immune | M13: icon_battle_damageimmune | N13: Buff.Name.DamageImmune | O13: Buff.Desc.DamageImmune | P13: FALSE | Q13: FALSE
A14: pre.normaldamageimmune | D14: 0 | E14: 0 | F14: 0 | G14: damageimmune | I14: FALSE | J14: FALSE | K14: TRUE | L14: Effect/Prefab/10_buff/EFF_buff_invincible Effect/Prefab/10_buff/EFF_immune | M14: icon_battle_damageimmune | N14: Buff.Name.NormalDamageImmune | O14: Buff.Desc.NormalDamageImmune | P14: FALSE | Q14: FALSE
A15: pre.dotdamageimmune | D15: 0 | E15: 0 | F15: 0 | G15: burndamageimmune poisondamageimmune bleeddamageimmune | I15: FALSE | J15: FALSE | K15: TRUE | L15: Effect/Prefab/10_buff/EFF_buff_invincible Effect/Prefab/10_buff/EFF_immune | M15: icon_battle_damageimmune | N15: Buff.Name.DotDamageImmune | O15: Buff.Desc.DotDamageImmune | P15: FALSE | Q15: FALSE
A16: guardrate25 | D16: 0 | E16: 0 | F16: 0 | G16: guardrate25 | I16: FALSE | J16: FALSE | K16: TRUE | L16: Effect/Prefab/10_buff/EFF_buff_up | M16: icon_battle_guard | N16: Buff.Name.GuardUp | O16: Buff.Desc.GuardUp | P16: FALSE | Q16: FALSE
A17: guardrate28 | D17: 0 | E17: 0 | F17: 0 | G17: guardrate28 | I17: FALSE | J17: FALSE | K17: TRUE | L17: Effect/Prefab/10_buff/EFF_buff_up | M17: icon_battle_guard | N17: Buff.Name.GuardUp | O17: Buff.Desc.GuardUp | P17: FALSE | Q17: FALSE
A18: guardrate30 | D18: 0 | E18: 0 | F18: 0 | G18: guardrate30 | I18: FALSE | J18: FALSE | K18: TRUE | L18: Effect/Prefab/10_buff/EFF_buff_up | M18: icon_battle_guard | N18: Buff.Name.GuardUp | O18: Buff.Desc.GuardUp | P18: FALSE | Q18: FALSE
A19: guardrate35 | D19: 0 | E19: 0 | F19: 0 | G19: guardrate35 | I19: FALSE | J19: FALSE | K19: TRUE | L19: Effect/Prefab/10_buff/EFF_buff_up | M19: icon_battle_guard | N19: Buff.Name.GuardUp | O19: Buff.Desc.GuardUp | P19: FALSE | Q19: FALSE
A20: guardrate40 | D20: 0 | E20: 0 | F20: 0 | G20: guardrate40 | I20: FALSE | J20: FALSE | K20: TRUE | L20: Effect/Prefab/10_buff/EFF_buff_up | M20: icon_battle_guard | N20: Buff.Name.GuardUp | O20: Buff.Desc.GuardUp | P20: FALSE | Q20: FALSE
... A23: guardrate100 | D23: 0 | E23: 0 | F23: 0 | G23: guardrate100 | I23: FALSE | J23: FALSE | K23: TRUE | L23: Effect/Prefab/10_buff/EFF_buff_up | M23: icon_battle_guard | N23: Buff.Name.GuardUp | O23: Buff.Desc.GuardUp | P23: FALSE | Q23: FALSE
A24: critical.20 | D24: 0 | E24: 0 | F24: 0 | G24: critical.20 | I24: FALSE | J24: FALSE | K24: TRUE | M24: icon_battle_critical | N24: Buff.Name.CriticalUp | O24: Buff.Desc.CriticalUp | P24: FALSE | Q24: FALSE
A25: critical.30 | D25: 0 | E25: 0 | F25: 0 | G25: critical.30 | I25: FALSE | J25: FALSE | K25: TRUE | M25: icon_battle_critical | N25: Buff.Name.CriticalUp | O25: Buff.Desc.CriticalUp | P25: FALSE | Q25: FALSE
A26: critical.35 | D26: 0 | E26: 0 | F26: 0 | G26: critical.35 | I26: FALSE | J26: FALSE | K26: TRUE | M26: icon_battle_critical | N26: Buff.Name.CriticalUp | O26: Buff.Desc.CriticalUp | P26: FALSE | Q26: FALSE
A27: critical.40 | D27: 0 | E27: 0 | F27: 0 | G27: critical.40 | I27: FALSE | J27: FALSE | K27: TRUE | M27: icon_battle_critical | N27: Buff.Name.CriticalUp | O27: Buff.Desc.CriticalUp | P27: FALSE | Q27: FALSE
A28: critical.45 | D28: 0 | E28: 0 | F28: 0 | G28: critical.45 | I28: FALSE | J28: FALSE | K28: TRUE | M28: icon_battle_critical | N28: Buff.Name.CriticalUp | O28: Buff.Desc.CriticalUp | P28: FALSE | Q28: FALSE
A29: critical.50 | D29: 0 | E29: 0 | F29: 0 | G29: critical.50 | I29: FALSE | J29: FALSE | K29: TRUE | M29: icon_battle_critical | N29: Buff.Name.CriticalUp | O29: Buff.Desc.CriticalUp | P29: FALSE | Q29: FALSE
A30: critical.60 | D30: 0 | E30: 0 | F30: 0 | G30: critical.60 | I30: FALSE | J30: FALSE | K30: TRUE | M30: icon_battle_critical | N30: Buff.Name.CriticalUp | O30: Buff.Desc.CriticalUp | P30: FALSE | Q30: FALSE
A31: critical.100 | D31: 0 | E31: 0 | F31: 0 | G31: critical.100 | I31: FALSE | J31: FALSE | K31: TRUE | M31: icon_battle_critical | N31: Buff.Name.CriticalUp | O31: Buff.Desc.CriticalUp | P31: FALSE | Q31: FALSE
A32: ignoredefense.10 | D32: 0 | E32: 0 | F32: 0 | G32: ignoredefense.10 | I32: FALSE | J32: FALSE | K32: TRUE | M32: icon_battle_ignoredefense | N32: Buff.Name.IgnoredefenseUp | O32: Buff.Desc.IgnoredefenseUp | P32: FALSE | Q32: FALSE
A33: ignoredefense.20 | D33: 0 | E33: 0 | F33: 0 | G33: ignoredefense.20 | I33: FALSE | J33: FALSE | K33: TRUE | M33: icon_battle_ignoredefense | N33: Buff.Name.IgnoredefenseUp | O33: Buff.Desc.IgnoredefenseUp | P33: FALSE | Q33: FALSE
A34: ignoredefense.25 | D34: 0 | E34: 0 | F34: 0 | G34: ignoredefense.25 | I34: FALSE | J34: FALSE | K34: TRUE | M34: icon_battle_ignoredefense | N34: Buff.Name.IgnoredefenseUp | O34: Buff.Desc.IgnoredefenseUp | P34: FALSE | Q34: FALSE
A35: ignoredefense.30 | D35: 0 | E35: 0 | F35: 0 | G35: ignoredefense.30 | I35: FALSE | J35: FALSE | K35: TRUE | M35: icon_battle_ignoredefense | N35: Buff.Name.IgnoredefenseUp | O35: Buff.Desc.IgnoredefenseUp | P35: FALSE | Q35: FALSE
... A55: accuracy.100 | D55: 0 | E55: 0 | F55: 0 | G55: accuracy.100 | I55: FALSE | J55: FALSE | K55: TRUE | M55: icon_battle_accuracy | N55: Buff.Name.AccuracyUp | O55: Buff.Desc.AccuracyUp | P55: FALSE | Q55: FALSE
A56: knockback50 | D56: 50 | E56: 0 | F56: 0 | G56: knockback | I56: FALSE | J56: FALSE | K56: FALSE | P56: FALSE | Q56: FALSE
A57: knockback100 | D57: 100 | E57: 0 | F57: 0 | G57: knockback | I57: FALSE | J57: FALSE | K57: FALSE | P57: FALSE | Q57: FALSE
A58: knockback150 | D58: 150 | E58: 0 | F58: 0 | G58: knockback | I58: FALSE | J58: FALSE | K58: FALSE | P58: FALSE | Q58: FALSE
A59: knockback200 | D59: 200 | E59: 0 | F59: 0 | G59: knockback | I59: FALSE | J59: FALSE | K59: FALSE | P59: FALSE | Q59: FALSE
A60: knockback250 | D60: 250 | E60: 0 | F60: 0 | G60: knockback | I60: FALSE | J60: FALSE | K60: FALSE | P60: FALSE | Q60: FALSE
A61: knockback300 | D61: 300 | E61: 0 | F61: 0 | G61: knockback | I61: FALSE | J61: FALSE | K61: FALSE | P61: FALSE | Q61: FALSE
...

Sheet BuffEffect.CM
A1: #ID | B1: #조건 | C1: #조건 값 (백분율) | D1: #조건체크 반복주기 | E1: #사용횟수 기본값:1, 공백:무한 | F1: #타겟 | G1: #광여 타이 | H1: #값 | I1: #수 | J1: #타입 | K1: #값 | L1: #값 % | M1: #값 (상수) | N1: #이펙트 | O1: #사용 스택 | P1: #틱 | Q1: #이펙트 이름 | R1: #Hud
A2: Id | B2: ActiveCondition | C2: ConditionValue | D2: CoolTime | E2: LimitEffectCount | F2: TargetTendency | G2: AreaType | H2: AreaValue | I2: TargetCount | J2: #Type | K2: #Value1 | L2: #Value2 | M2: #Value3 | N2: Effect | O2: UseStack | P2: Tick | Q2: Name | R2: ShowHit
A3: *string | B3: ActiveCondition? | C3: string | D3: int | E3: int? | F3: TargetTendency | G3: AreaType | H3: [int] | I3: int | J3: #BuffEffectType | K3: #string | L3: #string | M3: #string | N3: dsl | O3: int | P3: int | Q3: string | R3: bool
A4: common | B4: common | C4: common | D4: common | E4: common | F4: common | G4: common | H4: common | I4: common | J4: # | K4: # | L4: # | M4: # | N4: common | O4: common | P4: common | Q4: client | R4: common
A5: none | D5: 0 | E5: 1 | F5: Self | G5: Single | I5: 0 | J5: None | N5: =J5&"("&IF(K5="","",K5)&IF(L5="","",", "&L5)&IF(M5="","",", "&M5)&")" -> None() | O5: 0 | P5: 0 | R5: FALSE
A6: comingsoon | D6: 0 | E6: 1 | F6: Self | G6: Single | I6: 0 | J6: None | N6: =J6&"("&IF(K6="","",K6)&IF(L6="","",", "&L6)&IF(M6="","",", "&M6)&")" -> None() | O6: 0 | P6: 0 | R6: TRUE
A7: comingsoon.test.buff.buffeffect.01 | D7: 0 | E7: 1 | F7: Self | G7: Single | I7: 0 | J7: Status | K7: DamageDerate | L7: 1000 | N7: =J7&"("&IF(K7="","",K7)&IF(L7="","",", "&L7)&IF(M7="","",", "&M7)&")" -> Status(DamageDerate, 1000) | O7: 0 | P7: 0 | R7: TRUE
A8: comingsoon.test.buff.buffeffect.02 | D8: 0 | E8: 1 | F8: Self | G8: Single | I8: 0 | J8: Status | K8: DamageDerate | L8: -1000 | N8: =J8&"("&IF(K8="","",K8)&IF(L8="","",", "&L8)&IF(M8="","",", "&M8)&")" -> Status(DamageDerate, -1000) | O8: 0 | P8: 0 | R8: TRUE
A9: ccimmune | D9: 0 | E9: 1 | F9: Self | G9: Single | I9: 0 | J9: DebuffResist | K9: CrowdControl | L9: 100 | N9: =J9&"("&IF(K9="","",K9)&IF(L9="","",", "&L9)&IF(M9="","",", "&M9)&")" -> DebuffResist(CrowdControl, 100) | O9: 0 | P9: 0 | R9: TRUE
A10: all.immune | D10: 0 | E10: 1 | F10: Self | G10: Single | I10: 0 | J10: DebuffResist | K10: All | L10: 100 | N10: =J10&"("&IF(K10="","",K10)&IF(L10="","",", "&L10)&IF(M10="","",", "&M10)&")" -> DebuffResist(All, 100) | O10: 0 | P10: 0 | R10: TRUE
A11: resist.cc | D11: 0 | E11: 1 | F11: Self | G11: Single | I11: 0 | J11: CCResist | K11: None | L11: 1000 | N11: =J11&"("&IF(K11="","",K11)&IF(L11="","",", "&L11)&IF(M11="","",", "&M11)&")" -> CCResist(None, 1000) | O11: 0 | P11: 0 | R11: TRUE
A12: resist.silence | D12: 0 | E12: 1 | F12: Self | G12: Single | I12: 0 | J12: CCResist | K12: Silence | L12: 1000 | N12: =J12&"("&IF(K12="","",K12)&IF(L12="","",", "&L12)&IF(M12="","",", "&M12)&")" -> CCResist(Silence, 1000) | O12: 0 | P12: 0 | R12: TRUE
A13: resist.blind | D13: 0 | E13: 1 | F13: Self | G13: Single | I13: 0 | J13: CCResist | K13: Blind | L13: 1000 | N13: =J13&"("&IF(K13="","",K13)&IF(L13="","",", "&L13)&IF(M13="","",", "&M13)&")" -> CCResist(Blind, 1000) | O13: 0 | P13: 0 | R13: TRUE
A14: resist.bind | D14: 0 | E14: 1 | F14: Self | G14: Single | I14: 0 | J14: CCResist | K14: Bind | L14: 1000 | N14: =J14&"("&IF(K14="","",K14)&IF(L14="","",", "&L14)&IF(M14="","",", "&M14)&")" -> CCResist(Bind, 1000) | O14: 0 | P14: 0 | R14: TRUE
A15: resist.wound | D15: 0 | E15: 1 | F15: Self | G15: Single | I15: 0 | J15: CCResist | K15: Wound | L15: 1000 | N15: =J15&"("&IF(K15="","",K15)&IF(L15="","",", "&L15)&IF(M15="","",", "&M15)&")" -> CCResist(Wound, 1000) | O15: 0 | P15: 0 | R15: TRUE
A16: resist.sleep | D16: 0 | E16: 1 | F16: Self | G16: Single | I16: 0 | J16: CCResist | K16: Sleep | L16: 1000 | N16: =J16&"("&IF(K16="","",K16)&IF(L16="","",", "&L16)&IF(M16="","",", "&M16)&")" -> CCResist(Sleep, 1000) | O16: 0 | P16: 0 | R16: TRUE
A17: resist.stun | D17: 0 | E17: 1 | F17: Self | G17: Single | I17: 0 | J17: CCResist | K17: Stun | L17: 1000 | N17: =J17&"("&IF(K17="","",K17)&IF(L17="","",", "&L17)&IF(M17="","",", "&M17)&")" -> CCResist(Stun, 1000) | O17: 0 | P17: 0 | R17: TRUE
A18: resist.shock | D18: 0 | E18: 1 | F18: Self | G18: Single | I18: 0 | J18: CCResist | K18: Shock | L18: 1000 | N18: =J18&"("&IF(K18="","",K18)&IF(L18="","",", "&L18)&IF(M18="","",", "&M18)&")" -> CCResist(Shock, 1000) | O18: 0 | P18: 0 | R18: TRUE
... A59: HealRatedown | D59: 0 | E59: 1 | F59: Self | G59: Single | I59: 0 | J59: Status | K59: ReceiveRecoveryRate | L59: -10000 | N59: =J59&"("&IF(K59="","",K59)&IF(L59="","",", "&L59)&IF(M59="","",", "&M59)&")" -> Status(ReceiveRecoveryRate, -10000) | O59: 0 | P59: 0 | R59: TRUE
A60: Invincible | D60: 0 | E60: 1 | F60: Self | G60: Single | I60: 0 | J60: Invincible | N60: =J60&"("&IF(K60="","",K60)&IF(L60="","",", "&L60)&IF(M60="","",", "&M60)&")" -> Invincible() | O60: 0 | P60: 0 | R60: TRUE
A61: stun | D61: 0 | E61: 1 | F61: Self | G61: Single | I61: 0 | J61: CrowdControl | K61: Stun | N61: =J61&"("&IF(K61="","",K61)&IF(L61="","",", "&L61)&IF(M61="","",", "&M61)&")" -> CrowdControl(Stun) | O61: 0 | P61: 0 | Q61: Buff.Name.Stun | R61: TRUE
A62: bind | D62: 0 | E62: 1 | F62: Self | G62: Single | I62: 0 | J62: CrowdControl | K62: Bind | N62: =J62&"("&IF(K62="","",K62)&IF(L62="","",", "&L62)&IF(M62="","",", "&M62)&")" -> CrowdControl(Bind) | O62: 0 | P62: 0 | Q62: Buff.Name.Bind | R62: TRUE
A63: freeze | D63: 0 | E63: 1 | F63: Self | G63: Single | I63: 0 | J63: CrowdControl | K63: Freeze | N63: =J63&"("&IF(K63="","",K63)&IF(L63="","",", "&L63)&IF(M63="","",", "&M63)&")" -> CrowdControl(Freeze) | O63: 0 | P63: 0 | Q63: Buff.Name.Freeze | R63: TRUE
A64: shock | D64: 0 | E64: 1 | F64: Self | G64: Single | I64: 0 | J64: CrowdControl | K64: Shock | N64: =J64&"("&IF(K64="","",K64)&IF(L64="","",", "&L64)&IF(M64="","",", "&M64)&")" -> CrowdControl(Shock) | O64: 0 | P64: 0 | Q64: Buff.Name.Shock | R64: TRUE
A65: paralysis | D65: 0 | E65: 1 | F65: Self | G65: Single | I65: 0 | J65: CrowdControl | K65: Paralysis | N65: =J65&"("&IF(K65="","",K65)&IF(L65="","",", "&L65)&IF(M65="","",", "&M65)&")" -> CrowdControl(Paralysis) | O65: 0 | P65: 0 | Q65: Buff.Name.Paralysis | R65: TRUE
A66: wound | D66: 0 | E66: 1 | F66: Self | G66: Single | I66: 0 | J66: CrowdControl | K66: Wound | N66: =J66&"("&IF(K66="","",K66)&IF(L66="","",", "&L66)&IF(M66="","",", "&M66)&")" -> CrowdControl(Wound) | O66: 0 | P66: 0 | Q66: Buff.Name.Wound | R66: TRUE
A67: fear | D67: 0 | E67: 1 | F67: Self | G67: Single | I67: 0 | J67: CrowdControl | K67: Fear | N67: =J67&"("&IF(K67="","",K67)&IF(L67="","",", "&L67)&IF(M67="","",", "&M67)&")" -> CrowdControl(Fear) | O67: 0 | P67: 0 | Q67: Buff.Name.Fear | R67: TRUE
A68: charm | D68: 0 | E68: 1 | F68: Self | G68: Single | I68: 0 | J68: CrowdControl | K68: Charm | N68: =J68&"("&IF(K68="","",K68)&IF(L68="","",", "&L68)&IF(M68="","",", "&M68)&")" -> CrowdControl(Charm) | O68: 0 | P68: 0 | Q68: Buff.Name.Charm | R68: TRUE
A69: silence | D69: 0 | E69: 1 | F69: Self | G69: Single | I69: 0 | J69: CrowdControl | K69: Silence | N69: =J69&"("&IF(K69="","",K69)&IF(L69="","",", "&L69)&IF(M69="","",", "&M69)&")" -> CrowdControl(Silence) | O69: 0 | P69: 0 | Q69: Buff.Name.Silence | R69: TRUE
A70: blind | D70: 0 | E70: 1 | F70: Self | G70: Single | I70: 0 | J70: CrowdControl | K70: Blind | N70: =J70&"("&IF(K70="","",K70)&IF(L70="","",", "&L70)&IF(M70="","",", "&M70)&")" -> CrowdControl(Blind) | O70: 0 | P70: 0 | Q70: Buff.Name.Blindess | R70: TRUE
A71: sleep | D71: 0 | E71: 1 | F71: Self | G71: Single | I71: 0 | J71: CrowdControl | K71: Sleep | N71: =J71&"("&IF(K71="","",K71)&IF(L71="","",", "&L71)&IF(M71="","",", "&M71)&")" -> CrowdControl(Sleep) | O71: 0 | P71: 0 | Q71: Buff.Name.Sleep | R71: TRUE
A72: exile | D72: 0 | E72: 1 | F72: Self | G72: Single | I72: 0 | J72: CrowdControl | K72: Exile | N72: =J72&"("&IF(K72="","",K72)&IF(L72="","",", "&L72)&IF(M72="","",", "&M72)&")" -> CrowdControl(Exile) | O72: 0 | P72: 0 | Q72: Buff.Name.exile | R72: TRUE
A73: knockback | D73: 0 | E73: 1 | F73: Self | G73: Single | I73: 0 | J73: CrowdControl | K73: Knockback | N73: =J73&"("&IF(K73="","",K73)&IF(L73="","",", "&L73)&IF(M73="","",", "&M73)&")" -> CrowdControl(Knockback) | O73: 0 | P73: 0 | Q73: Buff.Name.KnockBack | R73: TRUE
A74: airborne | D74: 0 | E74: 1 | F74: Self | G74: Single | I74: 0 | J74: CrowdControl | K74: Airborn | N74: =J74&"("&IF(K74="","",K74)&IF(L74="","",", "&L74)&IF(M74="","",", "&M74)&")" -> CrowdControl(Airborn) | O74: 0 | P74: 0 | R74: TRUE
A75: pushed | D75: 0 | E75: 1 | F75: Self | G75: Single | I75: 0 | J75: CrowdControl | K75: Pushed | N75: =J75&"("&IF(K75="","",K75)&IF(L75="","",", "&L75)&IF(M75="","",", "&M75)&")" -> CrowdControl(Pushed) | O75: 0 | P75: 0 | Q75: Buff.Name.Pushed | R75: TRUE
A76: Confusion | D76: 0 | E76: 1 | F76: Self | G76: Single | I76: 0 | J76: CrowdControl | K76: Confusion | N76: =J76&"("&IF(K76="","",K76)&IF(L76="","",", "&L76)&IF(M76="","",", "&M76)&")" -> CrowdControl(Confusion) | O76: 0 | P76: 0 | Q76: Buff.Name.Confusion | R76: TRUE
A77: DeathHeal | D77: 0 | E77: 1 | F77: Self | G77: Single | I77: 0 | J77: CrowdControl | K77: DeathHeal | L77: 1000 | N77: =J77&"("&IF(K77="","",K77)&IF(L77="","",", "&L77)&IF(M77="","",", "&M77)&")" -> CrowdControl(DeathHeal, 1000) | O77: 0 | P77: 0 | Q77: Buff.Name.DeathHeal | R77: TRUE
A78: provoke | D78: 0 | E78: 1 | F78: Self | G78: Single | I78: 0 | J78: Provoke | N78: =J78&"("&IF(K78="","",K78)&IF(L78="","",", "&L78)&IF(M78="","",", "&M78)&")" -> Provoke() | O78: 0 | P78: 0 | R78: TRUE
A79: aggro | D79: 0 | E79: 1 | F79: Self | G79: Single | I79: 0 | J79: Aggro | N79: =J79&"("&IF(K79="","",K79)&IF(L79="","",", "&L79)&IF(M79="","",", "&M79)&")" -> Aggro() | O79: 0 | P79: 0 | R79: TRUE
A80: linkall | D80: 0 | E80: 1 | F80: Self | G80: Single | I80: 0 | J80: Link | K80: All | N80: =J80&"("&IF(K80="","",K80)&IF(L80="","",", "&L80)&IF(M80="","",", "&M80)&")" -> Link(All) | O80: 0 | P80: 0 | R80: TRUE
...

Sheet Buff.T
A1: #ID | B1: #조건 | C1: #조건 값 (백분율) | D1: #지속시간 천분율 | E1: #맥스 스택 | F1: #추가 스택 | G1: #Buff Effect | H1: #END Effect | I1: #Ture버프 해제불가 | J1: #사망 버프삭제 | K1: #버프, 디버프 | L1: #프리팹 | M1: #버프 | N1: #아이콘 | O1: #이름 | P1: #설명 | Q1: #자동 설명 | R1: #Hud 노출
A2: Id | B2: ActiveCondition | C2: ConditionValue | D2: Duration | E2: MaxStack | F2: AddStack | G2: Effects | H2: EndEffects | I2: Removeable | J2: RemoveDead | K2: BuffType | L2: Prefabs | M2: # | N2: Icon | O2: Name | P2: Desc | Q2: UseAutoDesc | R2: Showhit
A3: *string | B3: ActiveCondition? | C3: string | D3: int | E3: int | F3: int | G3: [$BuffEffect] | H3: [$SkillEffect] | I3: bool | J3: bool | K3: bool | L3: [string] | M3: # | N3: string | O3: string | P3: string | Q3: bool | R3: bool
A4: common | B4: common | C4: common | D4: common | E4: common | F4: common | G4: common | H4: common | I4: common | J4: common | K4: common | L4: client | M4: # | N4: client | O4: client | P4: client | Q4: client | R4: common
A5: itus.ult.attack.self.buff.01 | D5: 2000 | E5: 0 | F5: 0 | G5: itus.ult.attack.shield.buff.buffeffect.01 | I5: FALSE | J5: TRUE | K5: TRUE | L5: Effect/Prefab/10_buff/EFF_buff_shield | M5: info.shield | N5: =_xlfn.IFNA(VLOOKUP($M5,Buff.CM!$A:$O,13,FALSE),"") -> icon_battle_shield | O5: =_xlfn.IFNA(VLOOKUP($M5,Buff.CM!$A:$O,14,FALSE),"") -> Buff.Name.Shield | P5: =_xlfn.IFNA(VLOOKUP($M5,Buff.CM!$A:$O,15,FALSE),"") -> Buff.Desc.Shield | Q5: FALSE | R5: FALSE
A6: itus.ult.attack.self.buff.02 | D6: 2000 | E6: 0 | F6: 0 | G6: itus.ult.attack.shield.buff.buffeffect.02 | I6: FALSE | J6: TRUE | K6: TRUE | L6: Effect/Prefab/10_buff/EFF_buff_shield | M6: info.shield | N6: =_xlfn.IFNA(VLOOKUP($M6,Buff.CM!$A:$O,13,FALSE),"") -> icon_battle_shield | O6: =_xlfn.IFNA(VLOOKUP($M6,Buff.CM!$A:$O,14,FALSE),"") -> Buff.Name.Shield | P6: =_xlfn.IFNA(VLOOKUP($M6,Buff.CM!$A:$O,15,FALSE),"") -> Buff.Desc.Shield | Q6: FALSE | R6: FALSE
A7: itus.ult.attack.self.buff.03 | D7: 2000 | E7: 0 | F7: 0 | G7: itus.ult.attack.shield.buff.buffeffect.03 | I7: FALSE | J7: TRUE | K7: TRUE | L7: Effect/Prefab/10_buff/EFF_buff_shield | M7: info.shield | N7: =_xlfn.IFNA(VLOOKUP($M7,Buff.CM!$A:$O,13,FALSE),"") -> icon_battle_shield | O7: =_xlfn.IFNA(VLOOKUP($M7,Buff.CM!$A:$O,14,FALSE),"") -> Buff.Name.Shield | P7: =_xlfn.IFNA(VLOOKUP($M7,Buff.CM!$A:$O,15,FALSE),"") -> Buff.Desc.Shield | Q7: FALSE | R7: FALSE
A8: itus.ult.attack.self.buff.04 | D8: 2000 | E8: 0 | F8: 0 | G8: itus.ult.attack.shield.buff.buffeffect.04 | I8: FALSE | J8: TRUE | K8: TRUE | L8: Effect/Prefab/10_buff/EFF_buff_shield | M8: info.shield | N8: =_xlfn.IFNA(VLOOKUP($M8,Buff.CM!$A:$O,13,FALSE),"") -> icon_battle_shield | O8: =_xlfn.IFNA(VLOOKUP($M8,Buff.CM!$A:$O,14,FALSE),"") -> Buff.Name.Shield | P8: =_xlfn.IFNA(VLOOKUP($M8,Buff.CM!$A:$O,15,FALSE),"") -> Buff.Desc.Shield | Q8: FALSE | R8: FALSE
A9: itus.ult.attack.self.buff.05 | D9: 2000 | E9: 0 | F9: 0 | G9: itus.ult.attack.shield.buff.buffeffect.05 | I9: FALSE | J9: TRUE | K9: TRUE | L9: Effect/Prefab/10_buff/EFF_buff_shield | M9: info.shield | N9: =_xlfn.IFNA(VLOOKUP($M9,Buff.CM!$A:$O,13,FALSE),"") -> icon_battle_shield | O9: =_xlfn.IFNA(VLOOKUP($M9,Buff.CM!$A:$O,14,FALSE),"") -> Buff.Name.Shield | P9: =_xlfn.IFNA(VLOOKUP($M9,Buff.CM!$A:$O,15,FALSE),"") -> Buff.Desc.Shield | Q9: FALSE | R9: FALSE
A10: itus.ult.attack.self.buff.06 | D10: 2000 | E10: 0 | F10: 0 | G10: itus.ult.attack.shield.buff.buffeffect.06 | I10: FALSE | J10: TRUE | K10: TRUE | L10: Effect/Prefab/10_buff/EFF_buff_shield | M10: info.shield | N10: =_xlfn.IFNA(VLOOKUP($M10,Buff.CM!$A:$O,13,FALSE),"") -> icon_battle_shield | O10: =_xlfn.IFNA(VLOOKUP($M10,Buff.CM!$A:$O,14,FALSE),"") -> Buff.Name.Shield | P10: =_xlfn.IFNA(VLOOKUP($M10,Buff.CM!$A:$O,15,FALSE),"") -> Buff.Desc.Shield | Q10: FALSE | R10: FALSE
A11: itus.ult.attack.self.buff.07 | D11: 2000 | E11: 0 | F11: 0 | G11: itus.ult.attack.shield.buff.buffeffect.07 | I11: FALSE | J11: TRUE | K11: TRUE | L11: Effect/Prefab/10_buff/EFF_buff_shield | M11: info.shield | N11: =_xlfn.IFNA(VLOOKUP($M11,Buff.CM!$A:$O,13,FALSE),"") -> icon_battle_shield | O11: =_xlfn.IFNA(VLOOKUP($M11,Buff.CM!$A:$O,14,FALSE),"") -> Buff.Name.Shield | P11: =_xlfn.IFNA(VLOOKUP($M11,Buff.CM!$A:$O,15,FALSE),"") -> Buff.Desc.Shield | Q11: FALSE | R11: FALSE
A12: itus.ult.self.buff.01 | D12: 0 | E12: 0 | F12: 0 | G12: itus.ult.self.buff.buffeffect.01 itus.ult.self.buff.buffeffect.02.01 itus.ult.self.buff.buffeffect.03.01 itus.ult.self.buff.buffeffect.04.01 | I12: TRUE | J12: TRUE | K12: TRUE | L12: Effect/Prefab/10_buff/EFF_buff_itus_ult_weapon | M12: info.itus.buff.ult | N12: =_xlfn.IFNA(VLOOKUP($M12,Buff.CM!$A:$O,13,FALSE),"") -> icon_battle_itus_buff_01 | O12: =_xlfn.IFNA(VLOOKUP($M12,Buff.CM!$A:$O,14,FALSE),"") -> info.itus.buff.ult | P12: =_xlfn.IFNA(VLOOKUP($M12,Buff.CM!$A:$O,15,FALSE),"") -> Desc.info.itus.buff.ult | Q12: FALSE | R12: FALSE
A13: itus.ult.self.buff.02 | D13: 0 | E13: 0 | F13: 0 | G13: itus.ult.self.buff.buffeffect.01 itus.ult.self.buff.buffeffect.02.02 itus.ult.self.buff.buffeffect.03.02 itus.ult.self.buff.buffeffect.04.02 | I13: TRUE | J13: TRUE | K13: TRUE | L13: Effect/Prefab/10_buff/EFF_buff_itus_ult_weapon | M13: info.itus.buff.ult | N13: =_xlfn.IFNA(VLOOKUP($M13,Buff.CM!$A:$O,13,FALSE),"") -> icon_battle_itus_buff_01 | O13: =_xlfn.IFNA(VLOOKUP($M13,Buff.CM!$A:$O,14,FALSE),"") -> info.itus.buff.ult | P13: =_xlfn.IFNA(VLOOKUP($M13,Buff.CM!$A:$O,15,FALSE),"") -> Desc.info.itus.buff.ult | Q13: FALSE | R13: FALSE
A14: itus.ult.self.buff.03 | D14: 0 | E14: 0 | F14: 0 | G14: itus.ult.self.buff.buffeffect.01 itus.ult.self.buff.buffeffect.02.03 itus.ult.self.buff.buffeffect.03.03 itus.ult.self.buff.buffeffect.04.03 | I14: TRUE | J14: TRUE | K14: TRUE | L14: Effect/Prefab/10_buff/EFF_buff_itus_ult_weapon | M14: info.itus.buff.ult | N14: =_xlfn.IFNA(VLOOKUP($M14,Buff.CM!$A:$O,13,FALSE),"") -> icon_battle_itus_buff_01 | O14: =_xlfn.IFNA(VLOOKUP($M14,Buff.CM!$A:$O,14,FALSE),"") -> info.itus.buff.ult | P14: =_xlfn.IFNA(VLOOKUP($M14,Buff.CM!$A:$O,15,FALSE),"") -> Desc.info.itus.buff.ult | Q14: FALSE | R14: FALSE
A15: itus.ult.self.buff.04 | D15: 0 | E15: 0 | F15: 0 | G15: itus.ult.self.buff.buffeffect.01 itus.ult.self.buff.buffeffect.02.04 itus.ult.self.buff.buffeffect.03.04 itus.ult.self.buff.buffeffect.04.04 | I15: TRUE | J15: TRUE | K15: TRUE | L15: Effect/Prefab/10_buff/EFF_buff_itus_ult_weapon | M15: info.itus.buff.ult | N15: =_xlfn.IFNA(VLOOKUP($M15,Buff.CM!$A:$O,13,FALSE),"") -> icon_battle_itus_buff_01 | O15: =_xlfn.IFNA(VLOOKUP($M15,Buff.CM!$A:$O,14,FALSE),"") -> info.itus.buff.ult | P15: =_xlfn.IFNA(VLOOKUP($M15,Buff.CM!$A:$O,15,FALSE),"") -> Desc.info.itus.buff.ult | Q15: FALSE | R15: FALSE
A16: itus.ult.self.buff.05 | D16: 0 | E16: 0 | F16: 0 | G16: itus.ult.self.buff.buffeffect.01 itus.ult.self.buff.buffeffect.02.05 itus.ult.self.buff.buffeffect.03.05 itus.ult.self.buff.buffeffect.04.05 | I16: TRUE | J16: TRUE | K16: TRUE | L16: Effect/Prefab/10_buff/EFF_buff_itus_ult_weapon | M16: info.itus.buff.ult | N16: =_xlfn.IFNA(VLOOKUP($M16,Buff.CM!$A:$O,13,FALSE),"") -> icon_battle_itus_buff_01 | O16: =_xlfn.IFNA(VLOOKUP($M16,Buff.CM!$A:$O,14,FALSE),"") -> info.itus.buff.ult | P16: =_xlfn.IFNA(VLOOKUP($M16,Buff.CM!$A:$O,15,FALSE),"") -> Desc.info.itus.buff.ult | Q16: FALSE | R16: FALSE
... A32: itus.ult.shield.buff.07 | D32: 2000 | E32: 0 | F32: 0 | G32: itus.ult.shield.buff.buffeffect.07 | I32: FALSE | J32: TRUE | K32: TRUE | L32: Effect/Prefab/10_buff/EFF_buff_shield | M32: info.shield | N32: =_xlfn.IFNA(VLOOKUP($M32,Buff.CM!$A:$O,13,FALSE),"") -> icon_battle_shield | O32: =_xlfn.IFNA(VLOOKUP($M32,Buff.CM!$A:$O,14,FALSE),"") -> Buff.Name.Shield | P32: =_xlfn.IFNA(VLOOKUP($M32,Buff.CM!$A:$O,15,FALSE),"") -> Buff.Desc.Shield | Q32: FALSE | R32: FALSE
A33: itus.ult.B.buff.01 | D33: 500 | E33: 0 | F33: 0 | G33: airborne | I33: FALSE | J33: FALSE | K33: FALSE | N33: =_xlfn.IFNA(VLOOKUP($M33,Buff.CM!$A:$O,13,FALSE),"") | O33: =_xlfn.IFNA(VLOOKUP($M33,Buff.CM!$A:$O,14,FALSE),"") | P33: =_xlfn.IFNA(VLOOKUP($M33,Buff.CM!$A:$O,15,FALSE),"") | Q33: FALSE | R33: FALSE
A34: itus.ult.B.buff.02 | D34: 500 | E34: 0 | F34: 0 | G34: airborne | I34: FALSE | J34: FALSE | K34: FALSE | N34: =_xlfn.IFNA(VLOOKUP($M34,Buff.CM!$A:$O,13,FALSE),"") | O34: =_xlfn.IFNA(VLOOKUP($M34,Buff.CM!$A:$O,14,FALSE),"") | P34: =_xlfn.IFNA(VLOOKUP($M34,Buff.CM!$A:$O,15,FALSE),"") | Q34: FALSE | R34: FALSE
A35: itus.ult.B.buff.03 | D35: 500 | E35: 0 | F35: 0 | G35: airborne | I35: FALSE | J35: FALSE | K35: FALSE | N35: =_xlfn.IFNA(VLOOKUP($M35,Buff.CM!$A:$O,13,FALSE),"") | O35: =_xlfn.IFNA(VLOOKUP($M35,Buff.CM!$A:$O,14,FALSE),"") | P35: =_xlfn.IFNA(VLOOKUP($M35,Buff.CM!$A:$O,15,FALSE),"") | Q35: FALSE | R35: FALSE
A36: itus.ult.B.buff.04 | D36: 500 | E36: 0 | F36: 0 | G36: airborne | I36: FALSE | J36: FALSE | K36: FALSE | N36: =_xlfn.IFNA(VLOOKUP($M36,Buff.CM!$A:$O,13,FALSE),"") | O36: =_xlfn.IFNA(VLOOKUP($M36,Buff.CM!$A:$O,14,FALSE),"") | P36: =_xlfn.IFNA(VLOOKUP($M36,Buff.CM!$A:$O,15,FALSE),"") | Q36: FALSE | R36: FALSE
A37: itus.ult.B.buff.05 | D37: 500 | E37: 0 | F37: 0 | G37: airborne | I37: FALSE | J37: FALSE | K37: FALSE | N37: =_xlfn.IFNA(VLOOKUP($M37,Buff.CM!$A:$O,13,FALSE),"") | O37: =_xlfn.IFNA(VLOOKUP($M37,Buff.CM!$A:$O,14,FALSE),"") | P37: =_xlfn.IFNA(VLOOKUP($M37,Buff.CM!$A:$O,15,FALSE),"") | Q37: FALSE | R37: FALSE
A38: itus.ult.B.buff.06 | D38: 500 | E38: 0 | F38: 0 | G38: airborne | I38: FALSE | J38: FALSE | K38: FALSE | N38: =_xlfn.IFNA(VLOOKUP($M38,Buff.CM!$A:$O,13,FALSE),"") | O38: =_xlfn.IFNA(VLOOKUP($M38,Buff.CM!$A:$O,14,FALSE),"") | P38: =_xlfn.IFNA(VLOOKUP($M38,Buff.CM!$A:$O,15,FALSE),"") | Q38: FALSE | R38: FALSE
A39: itus.ult.B.buff.07 | D39: 500 | E39: 0 | F39: 0 | G39: airborne | I39: FALSE | J39: FALSE | K39: FALSE | N39: =_xlfn.IFNA(VLOOKUP($M39,Buff.CM!$A:$O,13,FALSE),"") | O39: =_xlfn.IFNA(VLOOKUP($M39,Buff.CM!$A:$O,14,FALSE),"") | P39: =_xlfn.IFNA(VLOOKUP($M39,Buff.CM!$A:$O,15,FALSE),"") | Q39: FALSE | R39: FALSE
A40: itus.ult.B.post.buff.01 | D40: 5000 | E40: 0 | F40: 0 | G40: itus.ult.B.post.buff.buffeffect.01 | I40: FALSE | J40: FALSE | K40: TRUE | N40: =_xlfn.IFNA(VLOOKUP($M40,Buff.CM!$A:$O,13,FALSE),"") | O40: =_xlfn.IFNA(VLOOKUP($M40,Buff.CM!$A:$O,14,FALSE),"") | P40: =_xlfn.IFNA(VLOOKUP($M40,Buff.CM!$A:$O,15,FALSE),"") | Q40: FALSE | R40: FALSE
A41: itus.ult.B.post.buff.02 | D41: 5000 | E41: 0 | F41: 0 | G41: itus.ult.B.post.buff.buffeffect.02 | I41: FALSE | J41: FALSE | K41: TRUE | N41: =_xlfn.IFNA(VLOOKUP($M41,Buff.CM!$A:$O,13,FALSE),"") | O41: =_xlfn.IFNA(VLOOKUP($M41,Buff.CM!$A:$O,14,FALSE),"") | P41: =_xlfn.IFNA(VLOOKUP($M41,Buff.CM!$A:$O,15,FALSE),"") | Q41: FALSE | R41: FALSE
A42: itus.ult.B.post.buff.03 | D42: 5000 | E42: 0 | F42: 0 | G42: itus.ult.B.post.buff.buffeffect.03 | I42: FALSE | J42: FALSE | K42: TRUE | N42: =_xlfn.IFNA(VLOOKUP($M42,Buff.CM!$A:$O,13,FALSE),"") | O42: =_xlfn.IFNA(VLOOKUP($M42,Buff.CM!$A:$O,14,FALSE),"") | P42: =_xlfn.IFNA(VLOOKUP($M42,Buff.CM!$A:$O,15,FALSE),"") | Q42: FALSE | R42: FALSE
A43: itus.ult.B.post.buff.04 | D43: 5000 | E43: 0 | F43: 0 | G43: itus.ult.B.post.buff.buffeffect.04 | I43: FALSE | J43: FALSE | K43: TRUE | N43: =_xlfn.IFNA(VLOOKUP($M43,Buff.CM!$A:$O,13,FALSE),"") | O43: =_xlfn.IFNA(VLOOKUP($M43,Buff.CM!$A:$O,14,FALSE),"") | P43: =_xlfn.IFNA(VLOOKUP($M43,Buff.CM!$A:$O,15,FALSE),"") | Q43: FALSE | R43: FALSE
A44: itus.ult.B.post.buff.05 | D44: 5000 | E44: 0 | F44: 0 | G44: itus.ult.B.post.buff.buffeffect.05 | I44: FALSE | J44: FALSE | K44: TRUE | N44: =_xlfn.IFNA(VLOOKUP($M44,Buff.CM!$A:$O,13,FALSE),"") | O44: =_xlfn.IFNA(VLOOKUP($M44,Buff.CM!$A:$O,14,FALSE),"") | P44: =_xlfn.IFNA(VLOOKUP($M44,Buff.CM!$A:$O,15,FALSE),"") | Q44: FALSE | R44: FALSE
... A46: itus.ult.B.post.buff.07 | D46: 5000 | E46: 0 | F46: 0 | G46: itus.ult.B.post.buff.buffeffect.07 | I46: FALSE | J46: FALSE | K46: TRUE | N46: =_xlfn.IFNA(VLOOKUP($M46,Buff.CM!$A:$O,13,FALSE),"") | O46: =_xlfn.IFNA(VLOOKUP($M46,Buff.CM!$A:$O,14,FALSE),"") | P46: =_xlfn.IFNA(VLOOKUP($M46,Buff.CM!$A:$O,15,FALSE),"") | Q46: FALSE | R46: FALSE
A47: itus.ult.B.shield.buff.01 | D47: 2100 | E47: 0 | F47: 0 | G47: itus.ult.B.shield.buff.buffeffect.01 | I47: FALSE | J47: FALSE | K47: TRUE | L47: Effect/Prefab/10_buff/EFF_buff_shield | M47: info.shield | N47: =_xlfn.IFNA(VLOOKUP($M47,Buff.CM!$A:$O,13,FALSE),"") -> icon_battle_shield | O47: =_xlfn.IFNA(VLOOKUP($M47,Buff.CM!$A:$O,14,FALSE),"") -> Buff.Name.Shield | P47: =_xlfn.IFNA(VLOOKUP($M47,Buff.CM!$A:$O,15,FALSE),"") -> Buff.Desc.Shield | Q47: FALSE | R47: FALSE
A48: itus.ult.B.shield.buff.02 | D48: 2100 | E48: 0 | F48: 0 | G48: itus.ult.B.shield.buff.buffeffect.02 | I48: FALSE | J48: FALSE | K48: TRUE | L48: Effect/Prefab/10_buff/EFF_buff_shield | M48: info.shield | N48: =_xlfn.IFNA(VLOOKUP($M48,Buff.CM!$A:$O,13,FALSE),"") -> icon_battle_shield | O48: =_xlfn.IFNA(VLOOKUP($M48,Buff.CM!$A:$O,14,FALSE),"") -> Buff.Name.Shield | P48: =_xlfn.IFNA(VLOOKUP($M48,Buff.CM!$A:$O,15,FALSE),"") -> Buff.Desc.Shield | Q48: FALSE | R48: FALSE
A49: itus.ult.B.shield.buff.03 | D49: 2100 | E49: 0 | F49: 0 | G49: itus.ult.B.shield.buff.buffeffect.03 | I49: FALSE | J49: FALSE | K49: TRUE | L49: Effect/Prefab/10_buff/EFF_buff_shield | M49: info.shield | N49: =_xlfn.IFNA(VLOOKUP($M49,Buff.CM!$A:$O,13,FALSE),"") -> icon_battle_shield | O49: =_xlfn.IFNA(VLOOKUP($M49,Buff.CM!$A:$O,14,FALSE),"") -> Buff.Name.Shield | P49: =_xlfn.IFNA(VLOOKUP($M49,Buff.CM!$A:$O,15,FALSE),"") -> Buff.Desc.Shield | Q49: FALSE | R49: FALSE
A50: itus.ult.B.shield.buff.04 | D50: 2100 | E50: 0 | F50: 0 | G50: itus.ult.B.shield.buff.buffeffect.04 | I50: FALSE | J50: FALSE | K50: TRUE | L50: Effect/Prefab/10_buff/EFF_buff_shield | M50: info.shield | N50: =_xlfn.IFNA(VLOOKUP($M50,Buff.CM!$A:$O,13,FALSE),"") -> icon_battle_shield | O50: =_xlfn.IFNA(VLOOKUP($M50,Buff.CM!$A:$O,14,FALSE),"") -> Buff.Name.Shield | P50: =_xlfn.IFNA(VLOOKUP($M50,Buff.CM!$A:$O,15,FALSE),"") -> Buff.Desc.Shield | Q50: FALSE | R50: FALSE
A51: itus.ult.B.shield.buff.05 | D51: 2100 | E51: 0 | F51: 0 | G51: itus.ult.B.shield.buff.buffeffect.05 | I51: FALSE | J51: FALSE | K51: TRUE | L51: Effect/Prefab/10_buff/EFF_buff_shield | M51: info.shield | N51: =_xlfn.IFNA(VLOOKUP($M51,Buff.CM!$A:$O,13,FALSE),"") -> icon_battle_shield | O51: =_xlfn.IFNA(VLOOKUP($M51,Buff.CM!$A:$O,14,FALSE),"") -> Buff.Name.Shield | P51: =_xlfn.IFNA(VLOOKUP($M51,Buff.CM!$A:$O,15,FALSE),"") -> Buff.Desc.Shield | Q51: FALSE | R51: FALSE
A52: itus.ult.B.shield.buff.06 | D52: 2100 | E52: 0 | F52: 0 | G52: itus.ult.B.shield.buff.buffeffect.06 | I52: FALSE | J52: FALSE | K52: TRUE | L52: Effect/Prefab/10_buff/EFF_buff_shield | M52: info.shield | N52: =_xlfn.IFNA(VLOOKUP($M52,Buff.CM!$A:$O,13,FALSE),"") -> icon_battle_shield | O52: =_xlfn.IFNA(VLOOKUP($M52,Buff.CM!$A:$O,14,FALSE),"") -> Buff.Name.Shield | P52: =_xlfn.IFNA(VLOOKUP($M52,Buff.CM!$A:$O,15,FALSE),"") -> Buff.Desc.Shield | Q52: FALSE | R52: FALSE
A53: itus.ult.B.shield.buff.07 | D53: 2100 | E53: 0 | F53: 0 | G53: itus.ult.B.shield.buff.buffeffect.07 | I53: FALSE | J53: FALSE | K53: TRUE | L53: Effect/Prefab/10_buff/EFF_buff_shield | M53: info.shield | N53: =_xlfn.IFNA(VLOOKUP($M53,Buff.CM!$A:$O,13,FALSE),"") -> icon_battle_shield | O53: =_xlfn.IFNA(VLOOKUP($M53,Buff.CM!$A:$O,14,FALSE),"") -> Buff.Name.Shield | P53: =_xlfn.IFNA(VLOOKUP($M53,Buff.CM!$A:$O,15,FALSE),"") -> Buff.Desc.Shield | Q53: FALSE | R53: FALSE
A54: itus.ult.B.shield.buff.01.01 | D54: 1100 | E54: 0 | F54: 0 | G54: itus.ult.B.shield.buff.buffeffect.01.01 | I54: FALSE | J54: FALSE | K54: TRUE | L54: Effect/Prefab/10_buff/EFF_buff_shield | M54: info.shield | N54: =_xlfn.IFNA(VLOOKUP($M54,Buff.CM!$A:$O,13,FALSE),"") -> icon_battle_shield | O54: =_xlfn.IFNA(VLOOKUP($M54,Buff.CM!$A:$O,14,FALSE),"") -> Buff.Name.Shield | P54: =_xlfn.IFNA(VLOOKUP($M54,Buff.CM!$A:$O,15,FALSE),"") -> Buff.Desc.Shield | Q54: FALSE | R54: FALSE
A55: itus.ult.B.shield.buff.01.02 | D55: 1100 | E55: 0 | F55: 0 | G55: itus.ult.B.shield.buff.buffeffect.01.02 | I55: FALSE | J55: FALSE | K55: TRUE | L55: Effect/Prefab/10_buff/EFF_buff_shield | M55: info.shield | N55: =_xlfn.IFNA(VLOOKUP($M55,Buff.CM!$A:$O,13,FALSE),"") -> icon_battle_shield | O55: =_xlfn.IFNA(VLOOKUP($M55,Buff.CM!$A:$O,14,FALSE),"") -> Buff.Name.Shield | P55: =_xlfn.IFNA(VLOOKUP($M55,Buff.CM!$A:$O,15,FALSE),"") -> Buff.Desc.Shield | Q55: FALSE | R55: FALSE
A56: itus.ult.B.shield.buff.01.03 | D56: 1100 | E56: 0 | F56: 0 | G56: itus.ult.B.shield.buff.buffeffect.01.03 | I56: FALSE | J56: FALSE | K56: TRUE | L56: Effect/Prefab/10_buff/EFF_buff_shield | M56: info.shield | N56: =_xlfn.IFNA(VLOOKUP($M56,Buff.CM!$A:$O,13,FALSE),"") -> icon_battle_shield | O56: =_xlfn.IFNA(VLOOKUP($M56,Buff.CM!$A:$O,14,FALSE),"") -> Buff.Name.Shield | P56: =_xlfn.IFNA(VLOOKUP($M56,Buff.CM!$A:$O,15,FALSE),"") -> Buff.Desc.Shield | Q56: FALSE | R56: FALSE
...

Sheet BuffEffect.T
A1: #ID | B1: #조건 | C1: #조건 값 (백분율) | D1: #조건체크 반복주기 | E1: #사용횟수 기본값:1, 공백:무한 | F1: #타겟 | G1: #광여 타이 | H1: #값 | I1: #수 | J1: #타입 | K1: #값 | L1: #값 % | M1: #값 (상수) | N1: #이펙트 | O1: #사용 스택 | P1: #틱 | Q1: #이펙트 이름 | R1: #Hud
A2: Id | B2: ActiveCondition | C2: ConditionValue | D2: CoolTime | E2: LimitEffectCount | F2: TargetTendency | G2: AreaType | H2: AreaValue | I2: TargetCount | J2: #Type | K2: #Value1 | L2: #Value2 | M2: #Value3 | N2: Effect | O2: UseStack | P2: Tick | Q2: Name | R2: ShowHit
A3: *string | B3: ActiveCondition? | C3: string | D3: int | E3: int? | F3: TargetTendency | G3: AreaType | H3: [int] | I3: int | J3: #BuffEffectType | K3: #string | L3: #string | M3: #string | N3: dsl | O3: int | P3: int | Q3: string | R3: bool
A4: common | B4: common | C4: common | D4: common | E4: common | F4: common | G4: common | H4: common | I4: common | J4: # | K4: # | L4: # | M4: # | N4: common | O4: common | P4: common | Q4: client | R4: common
A5: itus.ult.self.buff.buffeffect.01 | D5: 0 | E5: 1 | F5: Self | G5: Single | I5: 0 | J5: ChangeSkill | K5: Normal | N5: =J5&"("&IF(K5="","",K5)&IF(L5="","",", "&L5)&IF(M5="","",", "&M5)&")" -> ChangeSkill(Normal) | O5: 0 | P5: 0 | R5: TRUE
A6: itus.ult.attack.shield.buff.buffeffect.01 | D6: 0 | E6: 1 | F6: Self | G6: Single | I6: 0 | J6: Shield | K6: Defense | L6: 1000 | N6: =J6&"("&IF(K6="","",K6)&IF(L6="","",", "&L6)&IF(M6="","",", "&M6)&")" -> Shield(Defense, 1000) | O6: 0 | P6: 0 | R6: TRUE
A7: itus.ult.attack.shield.buff.buffeffect.02 | D7: 0 | E7: 1 | F7: Self | G7: Single | I7: 0 | J7: Shield | K7: Defense | L7: 1250 | N7: =J7&"("&IF(K7="","",K7)&IF(L7="","",", "&L7)&IF(M7="","",", "&M7)&")" -> Shield(Defense, 1250) | O7: 0 | P7: 0 | R7: TRUE
A8: itus.ult.attack.shield.buff.buffeffect.03 | D8: 0 | E8: 1 | F8: Self | G8: Single | I8: 0 | J8: Shield | K8: Defense | L8: 1500 | N8: =J8&"("&IF(K8="","",K8)&IF(L8="","",", "&L8)&IF(M8="","",", "&M8)&")" -> Shield(Defense, 1500) | O8: 0 | P8: 0 | R8: TRUE
A9: itus.ult.attack.shield.buff.buffeffect.04 | D9: 0 | E9: 1 | F9: Self | G9: Single | I9: 0 | J9: Shield | K9: Defense | L9: 1750 | N9: =J9&"("&IF(K9="","",K9)&IF(L9="","",", "&L9)&IF(M9="","",", "&M9)&")" -> Shield(Defense, 1750) | O9: 0 | P9: 0 | R9: TRUE
A10: itus.ult.attack.shield.buff.buffeffect.05 | D10: 0 | E10: 1 | F10: Self | G10: Single | I10: 0 | J10: Shield | K10: Defense | L10: 2000 | N10: =J10&"("&IF(K10="","",K10)&IF(L10="","",", "&L10)&IF(M10="","",", "&M10)&")" -> Shield(Defense, 2000) | O10: 0 | P10: 0 | R10: TRUE
A11: itus.ult.attack.shield.buff.buffeffect.06 | D11: 0 | E11: 1 | F11: Self | G11: Single | I11: 0 | J11: Shield | K11: Defense | L11: 2000 | N11: =J11&"("&IF(K11="","",K11)&IF(L11="","",", "&L11)&IF(M11="","",", "&M11)&")" -> Shield(Defense, 2000) | O11: 0 | P11: 0 | R11: TRUE
A12: itus.ult.attack.shield.buff.buffeffect.07 | D12: 0 | E12: 1 | F12: Self | G12: Single | I12: 0 | J12: Shield | K12: Defense | L12: 2000 | N12: =J12&"("&IF(K12="","",K12)&IF(L12="","",", "&L12)&IF(M12="","",", "&M12)&")" -> Shield(Defense, 2000) | O12: 0 | P12: 0 | R12: TRUE
A13: itus.ult.self.buff.buffeffect.02.01 | D13: 0 | E13: 1 | F13: Self | G13: Single | I13: 0 | J13: Active | K13: itus.ult.self.buff.cost.skilleffect.01 | N13: =J13&"("&IF(K13="","",K13)&IF(L13="","",", "&L13)&IF(M13="","",", "&M13)&")" -> Active(itus.ult.self.buff.cost.skilleffect.01) | O13: 0 | P13: 500 | R13: TRUE
A14: itus.ult.self.buff.buffeffect.02.02 | D14: 0 | E14: 1 | F14: Self | G14: Single | I14: 0 | J14: Active | K14: itus.ult.self.buff.cost.skilleffect.02 | N14: =J14&"("&IF(K14="","",K14)&IF(L14="","",", "&L14)&IF(M14="","",", "&M14)&")" -> Active(itus.ult.self.buff.cost.skilleffect.02) | O14: 0 | P14: 500 | R14: TRUE
A15: itus.ult.self.buff.buffeffect.02.03 | D15: 0 | E15: 1 | F15: Self | G15: Single | I15: 0 | J15: Active | K15: itus.ult.self.buff.cost.skilleffect.03 | N15: =J15&"("&IF(K15="","",K15)&IF(L15="","",", "&L15)&IF(M15="","",", "&M15)&")" -> Active(itus.ult.self.buff.cost.skilleffect.03) | O15: 0 | P15: 500 | R15: TRUE
A16: itus.ult.self.buff.buffeffect.02.04 | D16: 0 | E16: 1 | F16: Self | G16: Single | I16: 0 | J16: Active | K16: itus.ult.self.buff.cost.skilleffect.04 | N16: =J16&"("&IF(K16="","",K16)&IF(L16="","",", "&L16)&IF(M16="","",", "&M16)&")" -> Active(itus.ult.self.buff.cost.skilleffect.04) | O16: 0 | P16: 500 | R16: TRUE
A17: itus.ult.self.buff.buffeffect.02.05 | D17: 0 | E17: 1 | F17: Self | G17: Single | I17: 0 | J17: Active | K17: itus.ult.self.buff.cost.skilleffect.05 | N17: =J17&"("&IF(K17="","",K17)&IF(L17="","",", "&L17)&IF(M17="","",", "&M17)&")" -> Active(itus.ult.self.buff.cost.skilleffect.05) | O17: 0 | P17: 500 | R17: TRUE
A18: itus.ult.self.buff.buffeffect.02.06 | D18: 0 | E18: 1 | F18: Self | G18: Single | I18: 0 | J18: Active | K18: itus.ult.self.buff.cost.skilleffect.06 | N18: =J18&"("&IF(K18="","",K18)&IF(L18="","",", "&L18)&IF(M18="","",", "&M18)&")" -> Active(itus.ult.self.buff.cost.skilleffect.06) | O18: 0 | P18: 500 | R18: TRUE
A19: itus.ult.self.buff.buffeffect.02.07 | D19: 0 | E19: 1 | F19: Self | G19: Single | I19: 0 | J19: Active | K19: itus.ult.self.buff.cost.skilleffect.07 | N19: =J19&"("&IF(K19="","",K19)&IF(L19="","",", "&L19)&IF(M19="","",", "&M19)&")" -> Active(itus.ult.self.buff.cost.skilleffect.07) | O19: 0 | P19: 500 | R19: TRUE
A20: itus.ult.self.buff.buffeffect.03.01 | D20: 0 | E20: 1 | F20: Self | G20: Single | I20: 0 | J20: SkillEffectModifier | K20: Op | L20: itus.ult.skill.effect.modifier.01 | N20: =J20&"("&IF(K20="","",K20)&IF(L20="","",", "&L20)&IF(M20="","",", "&M20)&")" -> SkillEffectModifier(Op, itus.ult.skill.effect.modifier.01) | O20: 0 | P20: 0 | R20: TRUE
A21: itus.ult.self.buff.buffeffect.03.02 | D21: 0 | E21: 1 | F21: Self | G21: Single | I21: 0 | J21: SkillEffectModifier | K21: Op | L21: itus.ult.skill.effect.modifier.02 | N21: =J21&"("&IF(K21="","",K21)&IF(L21="","",", "&L21)&IF(M21="","",", "&M21)&")" -> SkillEffectModifier(Op, itus.ult.skill.effect.modifier.02) | O21: 0 | P21: 0 | R21: TRUE
A22: itus.ult.self.buff.buffeffect.03.03 | D22: 0 | E22: 1 | F22: Self | G22: Single | I22: 0 | J22: SkillEffectModifier | K22: Op | L22: itus.ult.skill.effect.modifier.03 | N22: =J22&"("&IF(K22="","",K22)&IF(L22="","",", "&L22)&IF(M22="","",", "&M22)&")" -> SkillEffectModifier(Op, itus.ult.skill.effect.modifier.03) | O22: 0 | P22: 0 | R22: TRUE
A23: itus.ult.self.buff.buffeffect.03.04 | D23: 0 | E23: 1 | F23: Self | G23: Single | I23: 0 | J23: SkillEffectModifier | K23: Op | L23: itus.ult.skill.effect.modifier.04 | N23: =J23&"("&IF(K23="","",K23)&IF(L23="","",", "&L23)&IF(M23="","",", "&M23)&")" -> SkillEffectModifier(Op, itus.ult.skill.effect.modifier.04) | O23: 0 | P23: 0 | R23: TRUE
A24: itus.ult.self.buff.buffeffect.03.05 | D24: 0 | E24: 1 | F24: Self | G24: Single | I24: 0 | J24: SkillEffectModifier | K24: Op | L24: itus.ult.skill.effect.modifier.05 | N24: =J24&"("&IF(K24="","",K24)&IF(L24="","",", "&L24)&IF(M24="","",", "&M24)&")" -> SkillEffectModifier(Op, itus.ult.skill.effect.modifier.05) | O24: 0 | P24: 0 | R24: TRUE
A25: itus.ult.self.buff.buffeffect.03.06 | D25: 0 | E25: 1 | F25: Self | G25: Single | I25: 0 | J25: SkillEffectModifier | K25: Op | L25: itus.ult.skill.effect.modifier.06 | N25: =J25&"("&IF(K25="","",K25)&IF(L25="","",", "&L25)&IF(M25="","",", "&M25)&")" -> SkillEffectModifier(Op, itus.ult.skill.effect.modifier.06) | O25: 0 | P25: 0 | R25: TRUE
A26: itus.ult.self.buff.buffeffect.03.07 | D26: 0 | E26: 1 | F26: Self | G26: Single | I26: 0 | J26: SkillEffectModifier | K26: Op | L26: itus.ult.skill.effect.modifier.07 | N26: =J26&"("&IF(K26="","",K26)&IF(L26="","",", "&L26)&IF(M26="","",", "&M26)&")" -> SkillEffectModifier(Op, itus.ult.skill.effect.modifier.07) | O26: 0 | P26: 0 | R26: TRUE
A27: itus.ult.self.buff.buffeffect.04.01 | D27: 0 | E27: 1 | F27: Self | G27: Single | I27: 0 | J27: Effect | K27: OnHitNormal | L27: itus.ult.attack.event.effect.02.01 | N27: =J27&"("&IF(K27="","",K27)&IF(L27="","",", "&L27)&IF(M27="","",", "&M27)&")" -> Effect(OnHitNormal, itus.ult.attack.event.effect.02.01) | O27: 0 | P27: 500 | R27: TRUE
A28: itus.ult.self.buff.buffeffect.04.02 | D28: 0 | E28: 1 | F28: Self | G28: Single | I28: 0 | J28: Effect | K28: OnHitNormal | L28: itus.ult.attack.event.effect.02.02 | N28: =J28&"("&IF(K28="","",K28)&IF(L28="","",", "&L28)&IF(M28="","",", "&M28)&")" -> Effect(OnHitNormal, itus.ult.attack.event.effect.02.02) | O28: 0 | P28: 500 | R28: TRUE
A29: itus.ult.self.buff.buffeffect.04.03 | D29: 0 | E29: 1 | F29: Self | G29: Single | I29: 0 | J29: Effect | K29: OnHitNormal | L29: itus.ult.attack.event.effect.02.03 | N29: =J29&"("&IF(K29="","",K29)&IF(L29="","",", "&L29)&IF(M29="","",", "&M29)&")" -> Effect(OnHitNormal, itus.ult.attack.event.effect.02.03) | O29: 0 | P29: 500 | R29: TRUE
A30: itus.ult.self.buff.buffeffect.04.04 | D30: 0 | E30: 1 | F30: Self | G30: Single | I30: 0 | J30: Effect | K30: OnHitNormal | L30: itus.ult.attack.event.effect.02.04 | N30: =J30&"("&IF(K30="","",K30)&IF(L30="","",", "&L30)&IF(M30="","",", "&M30)&")" -> Effect(OnHitNormal, itus.ult.attack.event.effect.02.04) | O30: 0 | P30: 500 | R30: TRUE
A31: itus.ult.self.buff.buffeffect.04.05 | D31: 0 | E31: 1 | F31: Self | G31: Single | I31: 0 | J31: Effect | K31: OnHitNormal | L31: itus.ult.attack.event.effect.02.05 | N31: =J31&"("&IF(K31="","",K31)&IF(L31="","",", "&L31)&IF(M31="","",", "&M31)&")" -> Effect(OnHitNormal, itus.ult.attack.event.effect.02.05) | O31: 0 | P31: 500 | R31: TRUE
... A33: itus.ult.self.buff.buffeffect.04.07 | D33: 0 | E33: 1 | F33: Self | G33: Single | I33: 0 | J33: Effect | K33: OnHitNormal | L33: itus.ult.attack.event.effect.02.07 | N33: =J33&"("&IF(K33="","",K33)&IF(L33="","",", "&L33)&IF(M33="","",", "&M33)&")" -> Effect(OnHitNormal, itus.ult.attack.event.effect.02.07) | O33: 0 | P33: 500 | R33: TRUE
A34: itus.ult.shield.buff.buffeffect.01 | D34: 0 | E34: 1 | F34: Self | G34: Single | I34: 0 | J34: Shield | K34: Defense | L34: 1000 | N34: =J34&"("&IF(K34="","",K34)&IF(L34="","",", "&L34)&IF(M34="","",", "&M34)&")" -> Shield(Defense, 1000) | O34: 0 | P34: 0 | R34: TRUE
A35: itus.ult.shield.buff.buffeffect.02 | D35: 0 | E35: 1 | F35: Self | G35: Single | I35: 0 | J35: Shield | K35: Defense | L35: 1250 | N35: =J35&"("&IF(K35="","",K35)&IF(L35="","",", "&L35)&IF(M35="","",", "&M35)&")" -> Shield(Defense, 1250) | O35: 0 | P35: 0 | R35: TRUE
A36: itus.ult.shield.buff.buffeffect.03 | D36: 0 | E36: 1 | F36: Self | G36: Single | I36: 0 | J36: Shield | K36: Defense | L36: 1500 | N36: =J36&"("&IF(K36="","",K36)&IF(L36="","",", "&L36)&IF(M36="","",", "&M36)&")" -> Shield(Defense, 1500) | O36: 0 | P36: 0 | R36: TRUE
A37: itus.ult.shield.buff.buffeffect.04 | D37: 0 | E37: 1 | F37: Self | G37: Single | I37: 0 | J37: Shield | K37: Defense | L37: 1750 | N37: =J37&"("&IF(K37="","",K37)&IF(L37="","",", "&L37)&IF(M37="","",", "&M37)&")" -> Shield(Defense, 1750) | O37: 0 | P37: 0 | R37: TRUE
A38: itus.ult.shield.buff.buffeffect.05 | D38: 0 | E38: 1 | F38: Self | G38: Single | I38: 0 | J38: Shield | K38: Defense | L38: 2000 | N38: =J38&"("&IF(K38="","",K38)&IF(L38="","",", "&L38)&IF(M38="","",", "&M38)&")" -> Shield(Defense, 2000) | O38: 0 | P38: 0 | R38: TRUE
A39: itus.ult.shield.buff.buffeffect.06 | D39: 0 | E39: 1 | F39: Self | G39: Single | I39: 0 | J39: Shield | K39: Defense | L39: 2000 | N39: =J39&"("&IF(K39="","",K39)&IF(L39="","",", "&L39)&IF(M39="","",", "&M39)&")" -> Shield(Defense, 2000) | O39: 0 | P39: 0 | R39: TRUE
A40: itus.ult.shield.buff.buffeffect.07 | D40: 0 | E40: 1 | F40: Self | G40: Single | I40: 0 | J40: Shield | K40: Defense | L40: 2000 | N40: =J40&"("&IF(K40="","",K40)&IF(L40="","",", "&L40)&IF(M40="","",", "&M40)&")" -> Shield(Defense, 2000) | O40: 0 | P40: 0 | R40: TRUE
A41: itus.ult.B.post.buff.buffeffect.01 | D41: 0 | E41: 1 | F41: Self | G41: Single | I41: 0 | J41: Active | K41: itus.ult.B.post.buff.skilleffect.01 | N41: =J41&"("&IF(K41="","",K41)&IF(L41="","",", "&L41)&IF(M41="","",", "&M41)&")" -> Active(itus.ult.B.post.buff.skilleffect.01) | O41: 0 | P41: 1000 | R41: TRUE
...

Sheet Buff.A
A1: #ID | B1: #조건 | C1: #조건 값 (백분율) | D1: #지속시간 천분율 | E1: #맥스스택 | F1: #추가스택 | G1: #Buff Effect | H1: #END Effect | I1: #Ture 버프 해제 불가 | J1: #사망 버프삭제 | K1: #버프, 디버프 | L1: #프리팹 | M1: #버프 | N1: #아이콘 | O1: #이름 | P1: #설명 | Q1: #자동 설명 | R1: #Hud 노출
A2: Id | B2: ActiveCondition | C2: ConditionValue | D2: Duration | E2: MaxStack | F2: AddStack | G2: Effects | H2: EndEffects | I2: Removeable | J2: RemoveDead | K2: BuffType | L2: Prefabs | M2: # | N2: Icon | O2: Name | P2: Desc | Q2: UseAutoDesc | R2: Showhit
A3: *string | B3: ActiveCondition? | C3: string | D3: int | E3: int | F3: int | G3: [$BuffEffect] | H3: [$SkillEffect] | I3: bool | J3: bool | K3: bool | L3: [string] | M3: # | N3: string | O3: string | P3: string | Q3: bool | R3: bool
A4: common | B4: common | C4: common | D4: common | E4: common | F4: common | G4: common | H4: common | I4: common | J4: common | K4: common | L4: client | M4: # | N4: client | O4: client | P4: client | Q4: client | R4: common
A5: kaito.aile.summon.passive.buff.01 | D5: 0 | E5: 0 | F5: 0 | G5: kaito.aile.summon.passive.buff.buffeffect.01.01 kaito.aile.summon.passive.buff.buffeffect.02.01 kaito.aile.summon.passive.buff.dmg.down | I5: FALSE | J5: FALSE | K5: TRUE | N5: =_xlfn.IFNA(VLOOKUP($M5,Buff.CM!$A:$O,13,FALSE),"") | O5: =_xlfn.IFNA(VLOOKUP($M5,Buff.CM!$A:$O,14,FALSE),"") | P5: =_xlfn.IFNA(VLOOKUP($M5,Buff.CM!$A:$O,15,FALSE),"") | Q5: FALSE | R5: FALSE
A6: kaito.aile.summon.passive.buff.02 | D6: 0 | E6: 0 | F6: 0 | G6: kaito.aile.summon.passive.buff.buffeffect.01.02 kaito.aile.summon.passive.buff.buffeffect.02.02 kaito.aile.summon.passive.buff.dmg.down | I6: FALSE | J6: FALSE | K6: TRUE | N6: =_xlfn.IFNA(VLOOKUP($M6,Buff.CM!$A:$O,13,FALSE),"") | O6: =_xlfn.IFNA(VLOOKUP($M6,Buff.CM!$A:$O,14,FALSE),"") | P6: =_xlfn.IFNA(VLOOKUP($M6,Buff.CM!$A:$O,15,FALSE),"") | Q6: FALSE | R6: FALSE
A7: kaito.aile.summon.passive.buff.03 | D7: 0 | E7: 0 | F7: 0 | G7: kaito.aile.summon.passive.buff.buffeffect.01.03 kaito.aile.summon.passive.buff.buffeffect.02.03 kaito.aile.summon.passive.buff.dmg.down | I7: FALSE | J7: FALSE | K7: TRUE | N7: =_xlfn.IFNA(VLOOKUP($M7,Buff.CM!$A:$O,13,FALSE),"") | O7: =_xlfn.IFNA(VLOOKUP($M7,Buff.CM!$A:$O,14,FALSE),"") | P7: =_xlfn.IFNA(VLOOKUP($M7,Buff.CM!$A:$O,15,FALSE),"") | Q7: FALSE | R7: FALSE
A8: kaito.aile.summon.passive.buff.04 | D8: 0 | E8: 0 | F8: 0 | G8: kaito.aile.summon.passive.buff.buffeffect.01.04 kaito.aile.summon.passive.buff.buffeffect.02.04 kaito.aile.summon.passive.buff.dmg.down | I8: FALSE | J8: FALSE | K8: TRUE | N8: =_xlfn.IFNA(VLOOKUP($M8,Buff.CM!$A:$O,13,FALSE),"") | O8: =_xlfn.IFNA(VLOOKUP($M8,Buff.CM!$A:$O,14,FALSE),"") | P8: =_xlfn.IFNA(VLOOKUP($M8,Buff.CM!$A:$O,15,FALSE),"") | Q8: FALSE | R8: FALSE
A9: kaito.aile.summon.passive.buff.05 | D9: 0 | E9: 0 | F9: 0 | G9: kaito.aile.summon.passive.buff.buffeffect.01.05 kaito.aile.summon.passive.buff.buffeffect.02.05 kaito.aile.summon.passive.buff.dmg.down | I9: FALSE | J9: FALSE | K9: TRUE | N9: =_xlfn.IFNA(VLOOKUP($M9,Buff.CM!$A:$O,13,FALSE),"") | O9: =_xlfn.IFNA(VLOOKUP($M9,Buff.CM!$A:$O,14,FALSE),"") | P9: =_xlfn.IFNA(VLOOKUP($M9,Buff.CM!$A:$O,15,FALSE),"") | Q9: FALSE | R9: FALSE
A10: kaito.aile.summon.passive.buff.06 | D10: 0 | E10: 0 | F10: 0 | G10: kaito.aile.summon.passive.buff.buffeffect.01.06 kaito.aile.summon.passive.buff.buffeffect.02.06 kaito.aile.summon.passive.buff.dmg.down | I10: FALSE | J10: FALSE | K10: TRUE | N10: =_xlfn.IFNA(VLOOKUP($M10,Buff.CM!$A:$O,13,FALSE),"") | O10: =_xlfn.IFNA(VLOOKUP($M10,Buff.CM!$A:$O,14,FALSE),"") | P10: =_xlfn.IFNA(VLOOKUP($M10,Buff.CM!$A:$O,15,FALSE),"") | Q10: FALSE | R10: FALSE
A11: kaito.aile.summon.taunt.buff.01 | D11: 3000 | E11: 0 | F11: 0 | G11: provoke | I11: FALSE | J11: TRUE | K11: FALSE | L11: Effect/Prefab/10_buff/EFF_debuff_taunt | M11: info.taunt | N11: =_xlfn.IFNA(VLOOKUP($M11,Buff.CM!$A:$O,13,FALSE),"") -> icon_battle_provoke | O11: =_xlfn.IFNA(VLOOKUP($M11,Buff.CM!$A:$O,14,FALSE),"") -> Buff.Name.Provoke | P11: =_xlfn.IFNA(VLOOKUP($M11,Buff.CM!$A:$O,15,FALSE),"") -> Buff.Desc.Provoke | Q11: FALSE | R11: FALSE
A12: kaito.aile.summon.taunt.buff.02 | D12: 3000 | E12: 0 | F12: 0 | G12: provoke | I12: FALSE | J12: TRUE | K12: FALSE | L12: Effect/Prefab/10_buff/EFF_debuff_taunt | M12: info.taunt | N12: =_xlfn.IFNA(VLOOKUP($M12,Buff.CM!$A:$O,13,FALSE),"") -> icon_battle_provoke | O12: =_xlfn.IFNA(VLOOKUP($M12,Buff.CM!$A:$O,14,FALSE),"") -> Buff.Name.Provoke | P12: =_xlfn.IFNA(VLOOKUP($M12,Buff.CM!$A:$O,15,FALSE),"") -> Buff.Desc.Provoke | Q12: FALSE | R12: FALSE
A13: kaito.aile.summon.taunt.buff.03 | D13: 3000 | E13: 0 | F13: 0 | G13: provoke | I13: FALSE | J13: TRUE | K13: FALSE | L13: Effect/Prefab/10_buff/EFF_debuff_taunt | M13: info.taunt | N13: =_xlfn.IFNA(VLOOKUP($M13,Buff.CM!$A:$O,13,FALSE),"") -> icon_battle_provoke | O13: =_xlfn.IFNA(VLOOKUP($M13,Buff.CM!$A:$O,14,FALSE),"") -> Buff.Name.Provoke | P13: =_xlfn.IFNA(VLOOKUP($M13,Buff.CM!$A:$O,15,FALSE),"") -> Buff.Desc.Provoke | Q13: FALSE | R13: FALSE
A14: kaito.aile.summon.taunt.buff.04 | D14: 3000 | E14: 0 | F14: 0 | G14: provoke | I14: FALSE | J14: TRUE | K14: FALSE | L14: Effect/Prefab/10_buff/EFF_debuff_taunt | M14: info.taunt | N14: =_xlfn.IFNA(VLOOKUP($M14,Buff.CM!$A:$O,13,FALSE),"") -> icon_battle_provoke | O14: =_xlfn.IFNA(VLOOKUP($M14,Buff.CM!$A:$O,14,FALSE),"") -> Buff.Name.Provoke | P14: =_xlfn.IFNA(VLOOKUP($M14,Buff.CM!$A:$O,15,FALSE),"") -> Buff.Desc.Provoke | Q14: FALSE | R14: FALSE
A15: kaito.aile.summon.taunt.buff.05 | D15: 3000 | E15: 0 | F15: 0 | G15: provoke | I15: FALSE | J15: TRUE | K15: FALSE | L15: Effect/Prefab/10_buff/EFF_debuff_taunt | M15: info.taunt | N15: =_xlfn.IFNA(VLOOKUP($M15,Buff.CM!$A:$O,13,FALSE),"") -> icon_battle_provoke | O15: =_xlfn.IFNA(VLOOKUP($M15,Buff.CM!$A:$O,14,FALSE),"") -> Buff.Name.Provoke | P15: =_xlfn.IFNA(VLOOKUP($M15,Buff.CM!$A:$O,15,FALSE),"") -> Buff.Desc.Provoke | Q15: FALSE | R15: FALSE
A16: kaito.aile.summon.taunt.buff.06 | D16: 3000 | E16: 0 | F16: 0 | G16: provoke | I16: FALSE | J16: TRUE | K16: FALSE | L16: Effect/Prefab/10_buff/EFF_debuff_taunt | M16: info.taunt | N16: =_xlfn.IFNA(VLOOKUP($M16,Buff.CM!$A:$O,13,FALSE),"") -> icon_battle_provoke | O16: =_xlfn.IFNA(VLOOKUP($M16,Buff.CM!$A:$O,14,FALSE),"") -> Buff.Name.Provoke | P16: =_xlfn.IFNA(VLOOKUP($M16,Buff.CM!$A:$O,15,FALSE),"") -> Buff.Desc.Provoke | Q16: FALSE | R16: FALSE
A17: kaito.aile.summon.die.confuse.buff.01 | D17: 2000 | E17: 0 | F17: 0 | G17: shock shock.impossible.eprecharge | I17: FALSE | J17: FALSE | K17: FALSE | L17: Effect/Prefab/10_buff/EFF_debuff_stun | N17: =_xlfn.IFNA(VLOOKUP($M17,Buff.CM!$A:$O,13,FALSE),"") | O17: =_xlfn.IFNA(VLOOKUP($M17,Buff.CM!$A:$O,14,FALSE),"") | P17: =_xlfn.IFNA(VLOOKUP($M17,Buff.CM!$A:$O,15,FALSE),"") | Q17: FALSE | R17: FALSE
A18: kaito.aile.summon.die.confuse.buff.02 | D18: 3000 | E18: 0 | F18: 0 | G18: shock shock.impossible.eprecharge | I18: FALSE | J18: FALSE | K18: FALSE | L18: Effect/Prefab/10_buff/EFF_debuff_stun | N18: =_xlfn.IFNA(VLOOKUP($M18,Buff.CM!$A:$O,13,FALSE),"") | O18: =_xlfn.IFNA(VLOOKUP($M18,Buff.CM!$A:$O,14,FALSE),"") | P18: =_xlfn.IFNA(VLOOKUP($M18,Buff.CM!$A:$O,15,FALSE),"") | Q18: FALSE | R18: FALSE
A19: kaito.aile.summon.die.confuse.buff.03 | D19: 4000 | E19: 0 | F19: 0 | G19: shock shock.impossible.eprecharge | I19: FALSE | J19: FALSE | K19: FALSE | L19: Effect/Prefab/10_buff/EFF_debuff_stun | N19: =_xlfn.IFNA(VLOOKUP($M19,Buff.CM!$A:$O,13,FALSE),"") | O19: =_xlfn.IFNA(VLOOKUP($M19,Buff.CM!$A:$O,14,FALSE),"") | P19: =_xlfn.IFNA(VLOOKUP($M19,Buff.CM!$A:$O,15,FALSE),"") | Q19: FALSE | R19: FALSE
A20: kaito.aile.summon.die.confuse.buff.04 | D20: 4000 | E20: 0 | F20: 0 | G20: shock shock.impossible.eprecharge | I20: FALSE | J20: FALSE | K20: FALSE | L20: Effect/Prefab/10_buff/EFF_debuff_stun | N20: =_xlfn.IFNA(VLOOKUP($M20,Buff.CM!$A:$O,13,FALSE),"") | O20: =_xlfn.IFNA(VLOOKUP($M20,Buff.CM!$A:$O,14,FALSE),"") | P20: =_xlfn.IFNA(VLOOKUP($M20,Buff.CM!$A:$O,15,FALSE),"") | Q20: FALSE | R20: FALSE
A21: kaito.aile.summon.die.confuse.buff.05 | D21: 4000 | E21: 0 | F21: 0 | G21: shock shock.impossible.eprecharge | I21: FALSE | J21: FALSE | K21: FALSE | L21: Effect/Prefab/10_buff/EFF_debuff_stun | N21: =_xlfn.IFNA(VLOOKUP($M21,Buff.CM!$A:$O,13,FALSE),"") | O21: =_xlfn.IFNA(VLOOKUP($M21,Buff.CM!$A:$O,14,FALSE),"") | P21: =_xlfn.IFNA(VLOOKUP($M21,Buff.CM!$A:$O,15,FALSE),"") | Q21: FALSE | R21: FALSE
A22: kaito.aile.summon.die.confuse.buff.06 | D22: 4000 | E22: 0 | F22: 0 | G22: shock shock.impossible.eprecharge | I22: FALSE | J22: FALSE | K22: FALSE | L22: Effect/Prefab/10_buff/EFF_debuff_stun | N22: =_xlfn.IFNA(VLOOKUP($M22,Buff.CM!$A:$O,13,FALSE),"") | O22: =_xlfn.IFNA(VLOOKUP($M22,Buff.CM!$A:$O,14,FALSE),"") | P22: =_xlfn.IFNA(VLOOKUP($M22,Buff.CM!$A:$O,15,FALSE),"") | Q22: FALSE | R22: FALSE
A23: kaito.aile.ult.effect.event.shock.buff.01 | D23: 4000 | E23: 0 | F23: 0 | G23: shock shock.impossible.eprecharge | I23: FALSE | J23: FALSE | K23: FALSE | L23: Effect/Prefab/10_buff/EFF_debuff_stun | N23: =_xlfn.IFNA(VLOOKUP($M23,Buff.CM!$A:$O,13,FALSE),"") | O23: =_xlfn.IFNA(VLOOKUP($M23,Buff.CM!$A:$O,14,FALSE),"") | P23: =_xlfn.IFNA(VLOOKUP($M23,Buff.CM!$A:$O,15,FALSE),"") | Q23: FALSE | R23: FALSE
A24: kaito.aile.ult.effect.event.shock.buff.02 | D24: 5000 | E24: 0 | F24: 0 | G24: shock shock.impossible.eprecharge | I24: FALSE | J24: FALSE | K24: FALSE | L24: Effect/Prefab/10_buff/EFF_debuff_stun | N24: =_xlfn.IFNA(VLOOKUP($M24,Buff.CM!$A:$O,13,FALSE),"") | O24: =_xlfn.IFNA(VLOOKUP($M24,Buff.CM!$A:$O,14,FALSE),"") | P24: =_xlfn.IFNA(VLOOKUP($M24,Buff.CM!$A:$O,15,FALSE),"") | Q24: FALSE | R24: FALSE
A25: kaito.aile.ult.effect.event.shock.buff.03 | D25: 6000 | E25: 0 | F25: 0 | G25: shock shock.impossible.eprecharge | I25: FALSE | J25: FALSE | K25: FALSE | L25: Effect/Prefab/10_buff/EFF_debuff_stun | N25: =_xlfn.IFNA(VLOOKUP($M25,Buff.CM!$A:$O,13,FALSE),"") | O25: =_xlfn.IFNA(VLOOKUP($M25,Buff.CM!$A:$O,14,FALSE),"") | P25: =_xlfn.IFNA(VLOOKUP($M25,Buff.CM!$A:$O,15,FALSE),"") | Q25: FALSE | R25: FALSE
A26: kaito.aile.ult.effect.event.shock.buff.04 | D26: 7000 | E26: 0 | F26: 0 | G26: shock shock.impossible.eprecharge | I26: FALSE | J26: FALSE | K26: FALSE | L26: Effect/Prefab/10_buff/EFF_debuff_stun | N26: =_xlfn.IFNA(VLOOKUP($M26,Buff.CM!$A:$O,13,FALSE),"") | O26: =_xlfn.IFNA(VLOOKUP($M26,Buff.CM!$A:$O,14,FALSE),"") | P26: =_xlfn.IFNA(VLOOKUP($M26,Buff.CM!$A:$O,15,FALSE),"") | Q26: FALSE | R26: FALSE
A27: kaito.aile.ult.ex.buff | D27: 0 | E27: 0 | F27: 0 | G27: =A27&".buffeffect" -> kaito.aile.ult.ex.buff.buffeffect | I27: FALSE | J27: FALSE | K27: FALSE | N27: =_xlfn.IFNA(VLOOKUP($M27,Buff.CM!$A:$O,13,FALSE),"") | O27: =_xlfn.IFNA(VLOOKUP($M27,Buff.CM!$A:$O,14,FALSE),"") | P27: =_xlfn.IFNA(VLOOKUP($M27,Buff.CM!$A:$O,15,FALSE),"") | Q27: FALSE | R27: FALSE
A28: kaito.aile.passive.buff.01 | D28: 0 | E28: 0 | F28: 0 | G28: kaito.aile.passive.buff.buffeffect.01 | I28: FALSE | J28: FALSE | K28: TRUE | N28: =_xlfn.IFNA(VLOOKUP($M28,Buff.CM!$A:$O,13,FALSE),"") | O28: =_xlfn.IFNA(VLOOKUP($M28,Buff.CM!$A:$O,14,FALSE),"") | P28: =_xlfn.IFNA(VLOOKUP($M28,Buff.CM!$A:$O,15,FALSE),"") | Q28: FALSE | R28: FALSE
A29: kaito.aile.passive.buff.02 | D29: 0 | E29: 0 | F29: 0 | G29: kaito.aile.passive.buff.buffeffect.02 | I29: FALSE | J29: FALSE | K29: TRUE | N29: =_xlfn.IFNA(VLOOKUP($M29,Buff.CM!$A:$O,13,FALSE),"") | O29: =_xlfn.IFNA(VLOOKUP($M29,Buff.CM!$A:$O,14,FALSE),"") | P29: =_xlfn.IFNA(VLOOKUP($M29,Buff.CM!$A:$O,15,FALSE),"") | Q29: FALSE | R29: FALSE
A30: kaito.aile.passive.buff.03 | D30: 0 | E30: 0 | F30: 0 | G30: kaito.aile.passive.buff.buffeffect.03 | I30: FALSE | J30: FALSE | K30: TRUE | N30: =_xlfn.IFNA(VLOOKUP($M30,Buff.CM!$A:$O,13,FALSE),"") | O30: =_xlfn.IFNA(VLOOKUP($M30,Buff.CM!$A:$O,14,FALSE),"") | P30: =_xlfn.IFNA(VLOOKUP($M30,Buff.CM!$A:$O,15,FALSE),"") | Q30: FALSE | R30: FALSE
A31: kaito.aile.passive.buff.04 | D31: 0 | E31: 0 | F31: 0 | G31: kaito.aile.passive.buff.buffeffect.04 | I31: FALSE | J31: FALSE | K31: TRUE | N31: =_xlfn.IFNA(VLOOKUP($M31,Buff.CM!$A:$O,13,FALSE),"") | O31: =_xlfn.IFNA(VLOOKUP($M31,Buff.CM!$A:$O,14,FALSE),"") | P31: =_xlfn.IFNA(VLOOKUP($M31,Buff.CM!$A:$O,15,FALSE),"") | Q31: FALSE | R31: FALSE
