Workbook

Sheet #번안관리인덱스
D2: 국문 버전 | E2: 18 | F2: 번안 버전 | G2: 5
B3: *240104 | C3: *번안 관리용 코멘트 신규 번안을 적용할 시 국문을 변경하지 않아도 되면 6/6 국문을 변경해야 하면 7/6

Sheet Text.Name
A1: Id | B1: Reference | C1: Tag | D1: #국문버전 | E1: #번안버전 | F1: #담당자 | G1: #Comment | H1: ko | I1: en | J1: ja | K1: zh_CN | L1: zh_TW
A2: *string | B2: string | C2: string | D2: ="#현재 버전 : "&'#번안관리인덱스'!$E$2 -> #현재 버전 : 18 | E2: ="#현재 버전 : "&'#번안관리인덱스'!$G$2 -> #현재 버전 : 5 | F2: #담당자 등록 | G2: # | H2: string | I2: string | J2: string | K2: string | L2: string
A3: client | B3: client | C3: client | D3: #국문버전 관리 | E3: #번안버전 관리 | F3: #특정 없는 경우 '공용' | G3: # | H3: client | I3: client | J3: client | K3: client | L3: client
A4: #주요캐릭터 | B4: #주요캐릭터 | C4: #주요캐릭터 | D4: #주요캐릭터 | E4: #주요캐릭터 | F4: #주요캐릭터 | G4: #주요캐릭터 | H4: #주요캐릭터 | I4: #주요캐릭터 | J4: #주요캐릭터 | K4: #주요캐릭터 | L4: #주요캐릭터
A5: Name.Character.Mother | D5: 12 | E5: 5 | H5: 마릴라이트 | I5: Marillight | J5: マリルライト | K5: 玛丽莱特 | L5: 瑪麗萊特
A6: Name.Character.Luyten | D6: 12 | E6: 5 | H6: 루이텐 | I6: Luyten | J6: ルイテン | K6: 卢伊滕 | L6: 盧伊滕
A7: Name.Character.Pollux | D7: 12 | E7: 5 | H7: 폴럭스 | I7: Pollux | J7: ポラックス | K7: 波勒克斯 | L7: 波勒克斯
A8: Name.Character.Ehrii | D8: 12 | E8: 5 | H8: 에리이 | I8: Ehrii | J8: エリィ
A9: Name.Character.dummy | D9: 12 | E9: 5 | H9: 더미 | I9: Dummy | J9: ダミー
A10: Name.Character.melissa.summon | D10: 12 | E10: 5 | F10: 04번역 제외 | H10: 분신
A11: Name.Character.lue | D11: 12 | E11: 5 | H11: 루 | I11: Lue | J11: ルー
A12: Desc.Character.lue | D12: 12 | E12: 5 | H12: 기본 등급의 디펜더
A13: Name.Character.ermeil | D13: 12 | E13: 5 | H13: 에르메일 | I13: Ermeil | J13: エルメイル
A14: Desc.Character.ermeil | D14: 12 | E14: 5 | H14: 기본 등급의 어태커
A15: Name.Character.iolet | D15: 12 | E15: 5 | H15: 이올렛 | I15: Iolet | J15: イオレット
A16: Desc.Character.iolet | D16: 12 | E16: 5 | H16: 기본 등급의 레인저
A17: Name.Character.reen | D17: 12 | E17: 5 | H17: 린 | I17: Reen | J17: リン
A18: Desc.Character.reen | D18: 12 | E18: 5 | H18: 기본 등급의 서포터
A19: Name.Character.itus | D19: 12 | E19: 5 | H19: 아이투스 | I19: Itus | J19: アイトゥース | K19: 艾托斯 | L19: 艾托斯
A20: Desc.Character.itus | D20: 12 | E20: 5 | H20: 레비아탄과 함께하는 바다의 정복자
A21: Name.Character.melissa | D21: 12 | E21: 5 | H21: 메리샤 | I21: Melissa | J21: メリッサ | K21: 梅莉莎 | L21: 梅莉莎
A22: Desc.Character.melissa | D22: 12 | E22: 5 | H22: 은밀한 취미를 즐기는 조형사 언니
A23: Name.Character.lilian | D23: 12 | E23: 5 | H23: 릴리안 | I23: Lilian | J23: リリアン | K23: 莉莉安 | L23: 莉莉安
A24: Desc.Character.lilian | D24: 12 | E24: 5 | H24: 플라즈마로 모든 것을 정화하는 성기사
A25: Name.Character.daria | D25: 12 | E25: 5 | H25: 다리아 | I25: Daria | J25: ダリア | K25: 达莉亚 | L25: 達莉亞
A26: Desc.Character.daria | D26: 12 | E26: 5 | H26: 보드게임을 좋아하는 레이리얼 실드의 전략가
A27: Name.Character.snopril | D27: 12 | E27: 5 | H27: 스노프릴 | I27: Snopril | J27: スノプリル | K27: 斯诺弗里尔 | L27: 斯諾弗里爾
A28: Desc.Character.snopril | D28: 12 | E28: 5 | H28: 눈 덮인 문명에서 찾아온 부끄럼쟁이 소녀
A29: Name.Character.anne | D29: 12 | E29: 5 | H29: 앤 | I29: Anne | J29: アン | K29: 安妮 | L29: 安妮
A30: Desc.Character.anne | D30: 12 | E30: 5 | H30: 사교무도회의 에이스인 말괄량이 아가씨
A31: Name.Character.taina | D31: 12 | E31: 5 | H31: 타이나 | I31: Taina | J31: タイナ | K31: 泰娜 | L31: 泰娜
A32: Desc.Character.taina | D32: 12 | E32: 5 | H32: 최강이 되고자 하는 오델리아 학원의 불량아
A33: Name.Character.diana | D33: 12 | E33: 5 | H33: 다이아나 | I33: Diana | J33: ダイアナ | K33: 黛安娜 | L33: 黛安娜
A34: Desc.Character.diana | D34: 12 | E34: 5 | H34: 튼튼한 몸과 전기를 이용해 모두를 지키는 방패병
A35: Name.Character.kaito.aile | D35: 12 | E35: 5 | H35: 괴도 엘 | I35: Kaito.aile | J35: 怪盗・エール | K35: 怪盗·埃尔 | L35: 怪盜·埃爾
A36: Desc.Character.kaito.aile | D36: 12 | E36: 5 | H36: 매일 밤 괴도로 암약하는 소심한 마술사
A37: Name.Character.serapulsar | D37: 12 | E37: 5 | H37: 세라펄사 | I37: Serapulsar | J37: セーラパルサ | K37: 塞拉普尔萨 | L37: 塞拉普爾薩
A38: Desc.Character.serapulsar | D38: 12 | E38: 5 | H38: 올곧은 신념을 가진 빛의 대리인
A39: Name.Character.iras | D39: 12 | E39: 5 | H39: 아이라스 | I39: Iras | J39: アイラス | K39: 艾拉斯 | L39: 艾拉斯
A40: Desc.Character.iras | D40: 12 | E40: 5 | H40: 텔레파시 해킹이 특기인 유명 스트리머
...

Sheet Text.MainStory
A1: Id | B1: Reference | C1: Tag | D1: #국문버전 | E1: #번안버전 | F1: #담당자 | G1: #Comment | H1: ko | I1: en | J1: ja | K1: zh_CN | L1: zh_TW
A2: *string | B2: string | C2: string | D2: ="#현재 버전 : "&'#번안관리인덱스'!$E$2 -> #현재 버전 : 18 | E2: ="#현재 버전 : "&'#번안관리인덱스'!$G$2 -> #현재 버전 : 5 | F2: #담당자 등록 | G2: # | H2: string | I2: string | J2: string | K2: string | L2: string
A3: client | B3: client | C3: client | D3: #국문버전 관리 | E3: #번안버전 관리 | F3: #특정 없는 경우 '공용' | G3: # | H3: client | I3: client | J3: client | K3: client | L3: client
A4: Chapter01_title | D4: 10 | E4: 5 | F4: 김재송 | G4: 챕터1장 타이틀 제목 | H4: 가능성의 도시 아스니아 | I4: Starseed, The City of Possibilities | J4: 第1章 シード覚醒 | K4: 第1章 发现种子
A5: Chapter01_desc | D5: 10 | E5: 5 | F5: 김재송 | G5: 챕터1장 타이틀 제목 | H5: 레드시프트의 침공으로 위기에 빠진 아스니아를 구원하고 스타시드를 탈환하자. | I5: The stolen Seed must be reclaimed in order to survive. | J5: シードが発現したと\n思われるカッサンドラを追え！ | K5: 追寻可能出现种子的卡桑德拉！
A6: Chapter01_01_title | D6: 10 | E6: 5 | H6: 스타넷 다이브
A7: Chapter01_01_desc | D7: 10 | E7: 5 | H7: 리히에에게 레드시프트를 막아달라는 부탁을 받고 가상 세계 네트워크 스타넷으로 다이브한 아키텍트. 그러나 도착한 세계는 레드시프트의 아스니아 침공으로 격렬한 전투가 벌어지고 있었다. 추락한 건물의 자폭 시퀀스가 시작되어 빨리 빠져나가야 하는 상황이지만, 아키텍트는 스타시드를 회수하기로 결심한다.
A8: Chapter01_02_title | D8: 10 | E8: 5 | H8: 무너지는 연구소
A9: Chapter01_02_desc | D9: 10 | E9: 5 | H9: 스타시드를 놓고 갑자기 등장한 레드시프트 간부 카산드라와 전투를 벌이는 아이렌 일행. 그러나 노후화된 건물이 격렬한 전투의 여파를 이기지 못하고 붕괴하면서, 일행은 지하로 추락하고 만다.
A10: Chapter01_03_title | D10: 10 | E10: 5 | H10: 지상으로
A11: Chapter01_03_desc | D11: 10 | E11: 5 | H11: 지하에서 아이렌, 마나, 오로라와 합류한 아키텍트. 모두와 함께 다시 지상으로 올라가지만, 거리는 이미 레드시프트에게 점령당한 상태였다.
A12: Chapter01_04_title | D12: 10 | E12: 5 | H12: 시가지 돌파 1
A13: Chapter01_04_desc | D13: 10 | E13: 5 | H13: 레드시프트를 쓰러트린 일행은 스타시드의 힘을 이용해 능력을 강화하고, 적들에게 점령당한 시가지를 돌파해 본부로 가기로 한다.
A14: Chapter01_05_title | D14: 10 | E14: 5 | H14: 파괴된 시가지
A15: Chapter01_05_desc | D15: 10 | E15: 5 | H15: 평소 좋아하던 거리가 파괴된 모습을 보고 슬퍼하는 마나와 오로라. 그러나 언제 적들이 몰려올지 모르는 상황이었기 때문에, 아이렌과 함께 계속 본부로 이동한다.
A16: Chapter01_06_title | D16: 10 | E16: 5 | H16: 시가지 돌파 2
A17: Chapter01_06_desc | D17: 10 | E17: 5 | H17: 시가지를 돌파해 본부로 가는 길. 레드시프트를 뚫고 전진하느라 모두 기진맥진한 상태이기 때문에, 잠시 쉬어 가기로 한다.
... A63: Chapter01.5_03_desc | D63: 10 | E63: 5 | H63: 아스니아를 돌아본 이후, 아키텍트는 아이렌, 마릴라이트와 함께 초지능체 에라디카가 이끄는 세븐 테마즈의 문명인 아르세즈로 출발한다.
A64: Chapter02_title | D64: 10 | E64: 5 | H64: 예술의 도시 아르세즈 | I64: Arrival at Artcaise
A65: Chapter02_desc | D65: 10 | E65: 5 | H65: 환상서가에 도둑이 들었다! 서가의 사서 샤레를 도와 범인을 붙잡자. | I65: Solve the Mysterious Case and Earn Artcaise Citizenships
A66: Chapter02_01_title | D66: 10 | E66: 5 | H66: 그리운 꿈 1
A67: Chapter02_01_desc | D67: 10 | E67: 5 | H67: 아르세즈 환상서가의 사서 샤레는 꿈을 꾼다. 그것은 누군가의 그리운 기억. 그녀가 가장 존경하는 인물과, 누군가가 처음 만나는 순간의 광경이었다.
A68: Chapter02_02_title | D68: 10 | E68: 5 | H68: 아르세즈 입국
A69: Chapter02_02_desc | D69: 10 | E69: 5 | H69: 아르세즈에 도착한 일행은 심사관 샤레에게 입국을 거절당한다. 레드시프트의 문제를 말해도 마지노 방벽을 믿는 샤레의 태도는 변하지 않는다. 그러나 메이드 베르베타의 중재로, 일행은 정식 외교 사절이 아닌 관광객 신분으로 입국을 허가받는다.
A70: Chapter02_03_title | D70: 10 | E70: 5 | H70: 시엘관 탐방
A71: Chapter02_03_desc | D71: 10 | E71: 5 | H71: 샤레를 따라 시엘관을 둘러보는 일행. 마릴라이트는 평범한 책들과 너무나도 다른 시엘관의 서적들에 혼란스러워 한다. 그때 도서관 내부의 어디선가 폭발음이 들려오고, 일행은 사태를 파악하기 위해 샤레의 뒤를 따라 폭음의 진원지로 향한다.
A72: Chapter02_04_title | D72: 10 | E72: 5 | H72: 『내일로』 절도 사건
A73: Chapter02_04_desc | D73: 10 | E73: 5 | H73: 락카를 든 소녀에 의해 에라디카가 소중하게 여긴다는 『내일로』의 원본 서적이 탈취당하고 만다. 평소 에라디카를 존경하던 샤레는 충격을 이기지 못하고 쓰러지고, 또 다른 사서 벨리타가 한발 늦게 등장한다.
A74: Chapter02_05_title | D74: 10 | E74: 5 | H74: 범인의 흔적
A75: Chapter02_05_desc | D75: 10 | E75: 5 | H75: 쓰러진 샤레를 의무실로 옮긴 후, 일행은 범인의 정체에 대해 추리한다. 범인은 마치 유령처럼 감시 카메라에 흔적을 남기지 않고 잠입했지만, 베르베타가 바닥에 묻은 물감을 발견해서 추적할 실마리를 얻게 된다.
A76: Chapter02_06_title | D76: 10 | E76: 5 | H76: 페인트 추적
A77: Chapter02_06_desc | D77: 10 | E77: 5 | H77: 일행은 범인을 추적하기 위해 거리로 나온다. 디저트의 유혹에 빠진 마릴라이트를 데리고 범인의 흔적을 따라 뒷골목으로 향하는 일행. 그러나 흔적은 범인이 일부러 남긴 함정이었다. 막다른 골목에 다다른 일행을 드론들이 습격해온다.
... A85: Chapter02_10_desc | D85: 10 | E85: 5 | H85: 마릴라이트가 보여준 사진은 샤레가 다른 책 사이에 에라디카의 화보집을 끼워 몰래 훔쳐보고 있는 모습이었다. 절망하는 샤레에게 마릴라이트는 우호의 증표로 사진 자료를 넘겨주겠다고 말하고, 샤레는 그것을 받아들이며 우호의 증표로 일행의 정식 외교 사절로 인정해주기로 한다. 한편, 도서관에 혼자 남아있던 벨리타는 정체 불명의 상대와 통신으로 수상한 대화를 나눈다.
A86: Chapter03_title | D86: 10 | E86: 5 | H86: 품평회와 유령 소동 | I86: Let’s Become Artists!
A87: Chapter03_desc | D87: 10 | E87: 5 | H87: 아르세즈에 계속 머물기 위해서는 품평회에서 예술성을 인정받아야만 한다고? | I87: Study Art in Different Fields to Win an Award at the Printemps Fair
A88: Chapter03_01_title | D88: 10 | E88: 5 | H88: 그리운 꿈 2
A89: Chapter03_01_desc | D89: 10 | E89: 5 | H89: 아르세즈 환상서가의 사서 샤레는 꿈을 꾼다. 그것은 누군가의 그리운 기억. 그녀가 가장 존경하는 인물과, 누군가가 마지막으로 헤어지는 순간의 광경이었다. 아르세즈의 호화 호텔에서 숙박한 아키텍트 일행은 베르베타가 가져온 지나치게 비싼 숙박 요금 계산서를 받아들고 당황한다. 베르베타는 일행에게 돈을 내는 대신 품평회에 나갈 것을 제안하고, 돈이 없는 일행은 그 제안을 받아들인다.
A90: Chapter03_02_title | D90: 10 | E90: 5 | H90: 조향사 헬렌
A91: Chapter03_02_desc | D91: 10 | E91: 5 | H91: 품평회에 참가하기 전 아르세즈의 예술 문화를 체험하기 위해 밖으로 나온 일행은, 거리에서 막대를 흔들고 있는 조향사 헬렌을 발견한다. 헬렌은 최근 고민이 있다면서 일행에게 자신의 공방에 방문해줄 것을 부탁한다.
A92: Chapter03_03_title | D92: 10 | E92: 5 | H92: 유령의 냄새
...

Sheet Text.FacStory
A1: Id | B1: Reference | C1: Tag | D1: #국문버전 | E1: #번안버전 | F1: #담당자 | G1: #Comment | H1: ko | I1: en | J1: ja | K1: zh_CN | L1: zh_TW
A2: *string | B2: string | C2: string | D2: ="#현재 버전 : "&'#번안관리인덱스'!$E$2 -> #현재 버전 : 18 | E2: ="#현재 버전 : "&'#번안관리인덱스'!$G$2 -> #현재 버전 : 5 | F2: #담당자 등록 | G2: # | H2: string | I2: string | J2: string | K2: string | L2: string
A3: client | B3: client | C3: client | D3: #국문버전 관리 | E3: #번안버전 관리 | F3: #특정 없는 경우 '공용' | G3: # | H3: client | I3: client | J3: client | K3: client | L3: client
A4: Faction_Starseed_01 | D4: 11 | E4: 5 | G4: 세력 명칭 | H4: 보안국 | I4: National Security Bureau | J4: セキュリティ局 | K4: 安全局 | L4: 安全局
A5: Faction_Asnia_01 | D5: 11 | E5: 5 | G5: 세력 명칭 | H5: 아스니아
A6: Faction_Artsaise_00 | D6: 11 | E6: 5 | G6: 세력 명칭 | H6: 최고품평회 | I6: Critique Committee | J6: 最高品評会 | K6: 最高鉴定会 | L6: 最高鑑定會
A7: Faction_Artsaise_01 | D7: 11 | E7: 5 | G7: 세력 명칭 | H7: 순수예술과 | I7: Department of Fine Arts | J7: 純粋芸術課 | K7: 艺术系 | L7: 藝術系
A8: Faction_Artsaise_02 | D8: 11 | E8: 5 | G8: 세력 명칭 | H8: 응용예술과 | I8: Department of Applied Arts | J8: 応用芸術課 | K8: 应用艺术系 | L8: 應用藝術系
A9: Faction_Artsaise_03 | D9: 11 | E9: 5 | G9: 세력 명칭 | H9: 자유예술과 | I9: Department of Liberal Arts | J9: 自由芸術課 | K9: 自由艺术系 | L9: 自由藝術系
A10: Faction_Stings_01 | D10: 11 | E10: 5 | G10: 세력 명칭 | H10: 레이리얼 아스트라 | I10: Rayreal Astra | J10: レイリアルアストラ | K10: 雷利亚阿斯特拉 | L10: 雷利亞阿斯特拉
A11: Faction_Stings_02 | D11: 11 | E11: 5 | G11: 세력 명칭 | H11: 레이리얼 소드 | I11: Rayreal Sword | J11: レイリアルソード | K11: 雷利亚剑刃 | L11: 雷利亞劍刃
A12: Faction_Stings_03 | D12: 11 | E12: 5 | G12: 세력 명칭 | H12: 레이리얼 실드 | I12: Rayreal Shield | J12: レイリアルシールド | K12: 雷利亚护盾 | L12: 雷利亞護盾
A13: Faction_Stings_04 | D13: 11 | E13: 5 | G13: 세력 명칭 | H13: 레이리얼 알터 | I13: Rayreal Alter | J13: レイリアルアルター | K13: 雷利亚变体 | L13: 雷利亞變體
A14: Faction_Stings_05 | D14: 11 | E14: 5 | G14: 세력 명칭 | H14: 레이리얼 아스날 | I14: Rayreal Arsenal | J14: レイリアルアーセナル | K14: 雷利亚武装 | L14: 雷利亞武裝
A15: Faction_Ideolla_01 | D15: 11 | E15: 5 | G15: 세력 명칭 | H15: 물상 과학 | I15: Physical Science | J15: 物象科學 | K15: 物象科学 | L15: 物象科學
A16: Faction_Autolata_01 | D16: 11 | E16: 5 | G16: 세력 명칭 | H16: 대양의 나무 | I16: Ocean Tree | J16: 大洋の木 | K16: 海洋之树 | L16: 海洋之樹
A17: Faction_Autolata_02 | D17: 11 | E17: 5 | G17: 세력 명칭 | H17: 대지의 나무 | I17: Earth Tree | J17: 大地の木 | K17: 大地之树 | L17: 大地之樹
... A22: Faction_limerit_03 | D22: 11 | E22: 5 | G22: 세력 명칭 | H22: ITS 과학 학교 | I22: ITS Science High School | J22: ITS科学高校 | K22: ITS科学学校 | L22: ITS科學學校
A23: Faction_limerit_01_01 | D23: 11 | H23: 고민상담부
A24: Story.Faction_Asnia_01_desc | D24: 11 | E24: 5 | G24: 세력 스토리 설명 문구 | H24: 아스니아 프록시안들의 일상을 감상합니다. | I24: Starseed - Check out the daily life of Proxyans of the National Security Bureau. | J24: スターシード - セキュリティ局のプロキシアンの日常を閲覧します。 | K24: 浏览阿斯尼亚AI影姬们的日常生活。 | L24: 瀏覽阿斯尼亞AI影姬們的日常生活。
A25: Story.Faction_Artsaise_01_desc | D25: 11 | E25: 5 | G25: 세력 스토리 설명 문구 | H25: 아르세즈 - 순수예술과 프록시안들의 일상을 감상합니다. | I25: Artcaise - Check out the daily life of Proxyans from the Department of Fine Arts. | J25: アルセーズ - 純粋芸術課のプロキシアンの日常を閲覧します。 | K25: 浏览阿尔塞斯 - 艺术系AI影姬们的日常生活。 | L25: 瀏覽阿爾塞斯 - 藝術系AI影姬們的日常生活。
A26: Story.Faction_Artsaise_02_desc | D26: 11 | E26: 5 | G26: 세력 스토리 설명 문구 | H26: 아르세즈 - 응용예술과 프록시안들의 일상을 감상합니다. | I26: Artcaise - Check out the daily life of Proxyans from the Department of Applied Arts. | J26: アルセーズ - 応用芸術課のプロキシアンの日常を閲覧します。 | K26: 浏览阿尔塞斯 - 应用艺术系AI影姬们的日常生活。 | L26: 瀏覽阿爾塞斯 - 應用藝術系AI影姬們的日常生活。
A27: Story.Faction_Artsaise_03_desc | D27: 11 | E27: 5 | G27: 세력 스토리 설명 문구 | H27: 아르세즈 - 자유예술과 프록시안들의 일상을 감상합니다. | I27: Artcaise - Check out the daily life of Proxyans from the Department of Liberal Arts. | J27: アルセーズ - 自由芸術課のプロキシアンの日常を閲覧します。 | K27: 浏览阿尔塞斯 - 自由艺术系AI影姬们的日常生活。 | L27: 瀏覽阿爾塞斯 - 自由藝術系AI影姬們的日常生活。
A28: Story.Faction_Stings_01_desc | D28: 11 | E28: 5 | G28: 세력 스토리 설명 문구 | H28: 스팅스 - 레이리얼 아스트라 프록시안들의 일상을 감상합니다. | I28: Stings - Check out the daily life of Proxyans of Rayreal Astra. | J28: スティングス - レイリアルアストラのプロキシアンの日常を閲覧します。 | K28: 浏览斯廷斯 - 雷利亚阿斯特拉AI影姬们的日常生活。 | L28: 瀏覽斯廷斯 - 雷利亞阿斯特拉AI影姬們的日常生活。
A29: Story.Faction_Stings_02_desc | D29: 11 | E29: 5 | G29: 세력 스토리 설명 문구 | H29: 스팅스 - 레이리얼 소드 프록시안들의 일상을 감상합니다. | I29: Stings - Check out the daily life of Proxyans of Rayreal Sword. | J29: スティングス - レイリアルソードのプロキシアンの日常を閲覧します。 | K29: 浏览斯廷斯 - 雷利亚剑刃AI影姬们的日常生活。 | L29: 瀏覽斯廷斯 - 雷利亞劍刃AI影姬們的日常生活。
A30: Story.Faction_Stings_03_desc | D30: 11 | E30: 5 | G30: 세력 스토리 설명 문구 | H30: 스팅스 - 레이리얼 실드 프록시안들의 일상을 감상합니다. | I30: Stings - Check out the daily life of Proxyans of Rayreal Shield. | J30: スティングス - レイリアルシールドのプロキシアンの日常を閲覧します。 | K30: 浏览斯廷斯 - 雷利亚护盾AI影姬们的日常生活。 | L30: 瀏覽斯廷斯 - 雷利亞護盾AI影姬們的日常生活。
A31: Story.Faction_Stings_04_desc | D31: 11 | E31: 5 | G31: 세력 스토리 설명 문구 | H31: 스팅스 - 레이리얼 알터 프록시안들의 일상을 감상합니다. | I31: Stings - Check out the daily life of Proxyans of Rayreal Alter. | J31: スティングス - レイリアルアルターのプロキシアンの日常を閲覧します。 | K31: 浏览斯廷斯 - 雷利亚变体AI影姬们的日常生活。 | L31: 瀏覽斯廷斯 - 雷利亞變體AI影姬們的日常生活。
A32: Story.Faction_Stings_05_desc | D32: 11 | E32: 5 | G32: 세력 스토리 설명 문구 | H32: 스팅스 - 레이리얼 아스날 프록시안들의 일상을 감상합니다. | I32: Stings - Check out the daily life of Proxyans of Rayreal Arsenal. | J32: スティングス - レイリアルアーセナルのプロキシアンの日常を閲覧します。 | K32: 浏览斯廷斯 - 雷利亚武装AI影姬们的日常生活。 | L32: 瀏覽斯廷斯 - 雷利亞武裝AI影姬們的日常生活。
A33: Story.Faction_Ideolla_01_desc | D33: 11 | E33: 5 | G33: 세력 스토리 설명 문구 | H33: 이데올라 - 12 대리인 프록시안들의 일상을 감상합니다. | I33: Ideolla - Check out the daily life of the 12 Proxyan Agents. | J33: イデオラ - 12代理人のプロキシアンの日常を閲覧します。 | K33: 浏览伊迪奥拉 - 12代理人AI影姬们的日常生活。 | L33: 瀏覽伊迪奧拉 - 12代理人AI影姬們的日常生活。
A34: Story.Faction_Autolata_01_desc | D34: 11 | E34: 5 | G34: 세력 스토리 설명 문구 | H34: 오토라타 - 대양의 나무 프록시안들의 일상을 감상합니다. | I34: Autolata - Check out the daily life of Proxyans from the Ocean Tree. | J34: オートラタ - 大洋の木のプロキシアンの日常を閲覧します。 | K34: 浏览奥托拉塔 - 海洋之树AI影姬们的日常生活。 | L34: 瀏覽奧托拉塔 - 海洋之樹AI影姬們的日常生活。
A35: Story.Faction_Autolata_02_desc | D35: 11 | E35: 5 | G35: 세력 스토리 설명 문구 | H35: 오토라타 - 대지의 나무 프록시안들의 일상을 감상합니다. | I35: Autolata - Check out the daily life of Proxyans from the Earth Tree. | J35: オートラタ - 大地の木のプロキシアンの日常を閲覧します。 | K35: 浏览奥托拉塔 - 大地之树AI影姬们的日常生活。 | L35: 瀏覽奧托拉塔 - 大地之樹AI影姬們的日常生活。
... A39: Story.Faction_limerit_03_desc | D39: 11 | E39: 5 | G39: 세력 스토리 설명 문구 | H39: 리메리트 - ITS 과학 학교 프록시안들의 일상을 감상합니다. | I39: Limerit - Check out the daily life of Proxyans of ITS Science High School. | J39: リメリット - ITS科学学校のプロキシアンの日常を閲覧します。 | K39: 浏览里美里特 - ITS科学学校AI影姬们的日常生活。 | L39: 瀏覽里美里特 - ITS科學學校AI影姬們的日常生活。
A40: Story.Faction_limerit_01_01_desc | D40: 11 | H40: 리메리트 - 아키오카 고민상담부 프록시안들의 일상을 감상합니다.
A41: #순수예술과
A42: Faction_artcaise01_01_title | D42: 7 | E42: 5 | H42: 이목을 끄는 쇼핑 1
A43: Faction_artcaise01_02_title | D43: 7 | E43: 5 | H43: 이목을 끄는 쇼핑 2
A44: Faction_artcaise01_03_title | D44: 7 | E44: 5 | H44: 이목을 끄는 쇼핑 3
A45: Faction_artcaise01_04_title | D45: 7 | E45: 5 | H45: 이목을 끄는 쇼핑 4
A46: Faction_artcaise01_01_desc | D46: 7 | E46: 5 | H46: 아르세즈의 소동이 끝난 후, 초지능체인 에라디카는 의욕을 잃고 무기력하게 지내고 있었다. 그 모습을 보다 못한 베르베타는 샤레와 함께 해결법을 찾기로 한다.
A47: Faction_artcaise01_02_desc | D47: 7 | E47: 5 | H47: 샤레와 베르베타는 에라디카의 의욕을 되살리기 위해 새로 오픈한 쇼핑몰로 안내한다. 하지만 영 시원찮은 반응에 당혹해 한다. 결국 샤레는 최후의 수단으로 어떤 프록시안을 만나러 간다.
...

Sheet Text.EventStory
A1: Id | B1: Reference | C1: Tag | D1: #국문버전 | E1: #번안버전 | F1: #담당자 | G1: #Comment | H1: ko | I1: en | J1: ja | K1: zh_CN | L1: zh_TW
A2: *string | B2: string | C2: string | D2: ="#현재 버전 : "&'#번안관리인덱스'!$E$2 -> #현재 버전 : 18 | E2: ="#현재 버전 : "&'#번안관리인덱스'!$G$2 -> #현재 버전 : 5 | F2: #담당자 등록 | G2: # | H2: string | I2: string | J2: string | K2: string | L2: string
A3: client | B3: client | C3: client | D3: #국문버전 관리 | E3: #번안버전 관리 | F3: #특정 없는 경우 '공용' | G3: # | H3: client | I3: client | J3: client | K3: client | L3: client
A4: #이벤트UI텍스트세팅용빈칸
A5: EventStory.Name.Id | D5: 5 | E5: 5 | F5: 김주상 | H5: Riot Of iD | I5: Riot Of iD | J5: Riot Of iD | K5: Riot Of iD | L5: Riot Of iD
A6: Eventstory_Id_Desc | D6: 7 | E6: 5 | F6: 성주녕 | G6: 이드 스토리 에피소드 제목 240228 텍스트 수정. | H6: 누군가 이드의 그래피티 위에 낙서를 하는 사건이 벌어지고, 분노한 이드는 범인을 붙잡기로 결심한다. 예술가로서 질 수 없지. 이드 출동이다!
A7: EventStory.Stage.Desc.Id | D7: 7 | E7: 5 | F7: 성주녕 | G7: 이벤트 스토리 | H7: 이드의 그래피티에 낙서를 한 테러범이 등장했다?! 분노한 이드는 범인을 찾기로 하고, 거기에 아키텍트와 아이렌, 유리지아, 헬렌이 함께 한다. 그러나 범인을 추적할 수록 사건은 점점 더 미궁 속으로 빠지는데……. 과연 범인의 정체는? 그리고 그 목적은? 범인을 붙잡기 위한 이드 일행의 추격전이 시작된다!
A8: EventStory.Name.Yurizia | D8: 5 | E8: 5 | F8: 성주녕 | G8: 이벤트 스토리 | H8: 레트로 게임 어드벤처!
A9: Eventstory_Yurizia_Desc | D9: 7 | E9: 5 | F9: 성주녕 | G9: 이벤트 스토리 | H9: 돈이 떨어진 유리지아는 엄청난 상금이 걸린 레트로 게임 월드의 제패를 노린다. 과연 유리지아는 GM의 보물을 얻을 수 있을까?
A10: EventStory.Stage.Desc.Yurizia | D10: 7 | E10: 5 | F10: 성주녕 | G10: 이벤트 스토리 | H10: 아키텍트는 돈이 다 떨어진 유리지아를 도와 엄청난 상금이 걸려있다는 레트로 게임 세계의 제패에 나선다. 그러나 보물을 노리는 건 그들만이 아니었다. 과연 유리지아와 아키텍트는 다른 경쟁자들을 물리치고 GM이 숨겨둔 보물을 얻을 수 있을까?
A11: EventStory.Name.Itus | D11: 7 | E11: 5 | F11: 성주녕 | G11: 이벤트 스토리 | H11: 언더워터 파라다이스
A12: Eventstory_Itus_Desc | D12: 7 | E12: 5 | F12: 성주녕 | G12: 이벤트 스토리 | H12: 멸망의 예언이 다가올 때, 용사가 나타날 것이라는 예언. 그리고 때마침 등장한 아키텍트! 아이투스와 아키텍트는 멸망의 예언을 막을 수 있을까?
A13: EventStory.Stage.Desc.Itus | D13: 7 | E13: 5 | F13: 성주녕 | G13: 이벤트 스토리 | H13: 오토라타의 대양의 나무 구역에서 조난당한 아키텍트를 발견한 아이투스. 아키텍트가 다가올 멸망의 예언으로부터 대양의 나무를 구원할 예언의 용사라는 걸 깨닫지만, 다양한 문제가 그들을 덮쳐온다. 멸망의 예언이 다가오는 일촉즉발의 상황에서 아이투스의 선택은?
A14: EventStory.Name.Sia | D14: 7 | E14: 5 | F14: 성주녕 | G14: 이벤트 스토리 | H14: 푹신푹신 캠핑 로드!
A15: Eventstory_Sia_Desc | D15: 7 | E15: 5 | F15: 성주녕 | G15: 이벤트 스토리 | H15: 캠프 학교에 참가한 시아는 새로 사귄 친구들과 함께 스탬프 랠리를 진행하며 우정에 대해 깨닫는다. 시아의 힐링 캠핑 라이프를 위한 분투기.
A16: EventStory.Stage.Desc.Sia | D16: 7 | E16: 5 | F16: 성주녕 | G16: 이벤트 스토리 | H16: 아키텍트의 권유로 리메리트 캠프 학교에 참여한 시아. 아키텍트와 함께 할 생각에 행복에 젖어 있었지만, 시아를 맞이한 건 다른 조원들이었다. 그리고 담력 시험을 틈타 그들을 노리는 수상한 그림자까지……. 과연 시아는 모두와 함께 캠프파이어를 즐길 수 있을까?
A17: EventStory.Name.Anne | D17: 5 | E17: 5 | F17: 김주상 | G17: 이벤트 스토리 | H17: 스위트 쇼킹 티타임
... A31: EventStory.Stage.Desc.Hallona | D31: 8 | E31: 5 | F31: 성주녕 | G31: 이벤트 스토리(임시) | H31: 오늘도 의욕이 없는 할로나는 레이리얼 소드의 573 소대로부터 갑작스러운 결투 모의전 신청을 받게 된다. 스팅스의 문화상 물러서면 겁쟁이 취급당할 것은 분명한 상황. 혼란스러운 결투 모의전의 날은 다가온다. 할로나는 의욕을 내서 138소대와 함께 승리를 쟁취할 수 있을까?
A32: #이드 텍스트
A33: Eventstory_id_title | D33: 5 | E33: 5 | F33: 김승곤 | G33: 이드 스토리 에피소드 제목 | H33: iD의 그래피티 대소동!
A34: Eventstory01_01_title | D34: 5 | E34: 5 | F34: 이병민 | G34: 이벤트 스토리 제목 (임시) iD 등장! (1) | H34: iD 등장!
A35: Eventstory01_02_title | D35: 5 | E35: 5 | F35: 이병민 | G35: 이벤트 스토리 제목 (임시) iD 등장! (2) | H35: 의뢰 시작!
A36: Eventstory01_03_title | D36: 5 | E36: 5 | F36: 이병민 | G36: 이벤트 스토리 제목 | H36: 의뢰비는 햄버거 6개 (1)
A37: Eventstory01_04_title | D37: 5 | E37: 5 | F37: 이병민 | G37: 이벤트 스토리 제목 | H37: 의뢰비는 햄버거 6개 (2)
A38: Eventstory01_05_title | D38: 5 | E38: 5 | F38: 이병민 | G38: 이벤트 스토리 제목 | H38: iD 선생의 그래피티 1강 (1)
A39: Eventstory01_06_title | D39: 5 | E39: 5 | F39: 이병민 | G39: 이벤트 스토리 제목 | H39: iD 선생의 그래피티 1강 (2)
A40: Eventstory01_07_title | D40: 5 | E40: 5 | F40: 이병민 | G40: 이벤트 스토리 제목 | H40: 낙서 위에 낙서 (1)
A41: Eventstory01_08_title | D41: 5 | E41: 5 | F41: 이병민 | G41: 이벤트 스토리 제목 | H41: 낙서 위에 낙서 (2)
A42: Eventstory01_09_title | D42: 5 | E42: 5 | F42: 이병민 | G42: 이벤트 스토리 제목 | H42: 낙서 위에 낙서 (3)
A43: Eventstory01_10_title | D43: 5 | E43: 5 | F43: 이병민 | G43: 이벤트 스토리 제목 | H43: 적습 (1)
A44: Eventstory01_11_title | D44: 5 | E44: 5 | F44: 이병민 | G44: 이벤트 스토리 제목 | H44: 적습 (2)
... A73: Event_Story_Id_20_desc | D73: 5 | E73: 5 | F73: 김승곤 | G73: 이드 스토리 요약 내용 | H73: 이드는 자신의 그래피티가 최고인걸 확인하지만 자신의 길이 맞는지 고뇌한다.
A74: Event_Story_01_title | D74: 5 | E74: 5 | F74: 이기백 | H74: 이드 스토리 이벤트
A75: Event_Story_01_desc | D75: 5 | E75: 5 | F75: 이기백 | H75: ID와 만난 [nickname]은 어처구니 없는 일에 휘말리고 만다
A76: Text-Event_Story_01_1 | D76: 5 | E76: 5 | F76: 이기백 | G76: 나레이션 | H76: [nickname]이 할 일 없이 아르세즈를 산책하고 있었던 평화로운 어느 한 때였다.
A77: Text-Event_Story_01_2 | D77: 5 | E77: 5 | F77: 이기백 | G77: 나레이션 | H77: [nickname]의 눈 앞에서 분양 예정 중이던 건물이 무너지기 전까지만 해도 말이다.
A78: Text-Event_Story_01_3 | D78: 5 | E78: 5 | F78: 이기백 | G78: 플레이어 | H78: 뭐, 뭐야! 놈들의 습격인가?
A79: Text-Event_Story_01_4 | D79: 5 | E79: 5 | F79: 이기백 | G79: 나레이션 | H79: 범인은 다행스럽게도, 아니 어떤 의미로는 더욱 다행스럽지 않게도, 감염체가 아니었다.
A80: Text-Event_Story_01_5 | D80: 5 | E80: 5 | F80: 이기백 | G80: ID | H80: 응?
A81: Text-Event_Story_01_6 | D81: 5 | E81: 5 | F81: 이기백 | G81: ID | H81: 이야. 오랜만이야 브로.
...

Sheet Text.ConStory
A1: Id | B1: Reference | C1: Tag | D1: #국문버전 | E1: #번안버전 | F1: #담당자 | G1: #Comment | H1: ko | I1: en | J1: ja | K1: zh_CN | L1: zh_TW
A2: *string | B2: string | C2: string | D2: ="#현재 버전 : "&'#번안관리인덱스'!$E$2 -> #현재 버전 : 18 | E2: ="#현재 버전 : "&'#번안관리인덱스'!$G$2 -> #현재 버전 : 5 | F2: #담당자 등록 | G2: # | H2: string | I2: string | J2: string | K2: string | L2: string
A3: client | B3: client | C3: client | D3: #국문버전 관리 | E3: #번안버전 관리 | F3: #특정 없는 경우 '공용' | G3: # | H3: client | I3: client | J3: client | K3: client | L3: client
A4: ContentsStory_title | D4: 10 | E4: 0 | F4: 김재송 | G4: 콘텐츠 스토리 챕터 제목 | H4: 콘텐츠 스토리
A5: ContentsStory_desc | D5: 10 | E5: 0 | F5: 김재송 | G5: 콘텐츠 스토리 챕터 설명 | H5: 아스니아에서 벌어지는 여러 이야기들
A6: #아카데미 해금 대사
A7: Academy01_01_title | D7: 10 | E7: 5 | F7: 김재송 | G7: 콘텐츠 스토리 제목 | H7: 성장의 장, 아스니아 아카데미
A8: Academy01_01_desc | D8: 10 | E8: 5 | F8: 김재송 | H8: 루이텐과 폴럭스는 아키텍트에게 아스니아의 중심지 아스니아 아카데미를 소개한다. 아카데미에는 다양한 문명의 프록시안들이 시드 능력 개화를 위해 방문하고 있다고 한다.
A9: Text_Academy01_01_001 | D9: 10 | G9: 콘텐츠 스토리 | H9: 어서 오세요, 아키텍트 님.
A10: Text_Academy01_01_002 | D10: 10 | G10: 콘텐츠 스토리 | H10: 이곳은 아스니아 아카데미. 다양한 세력의 프록시안들이 모이는 아스니아의 중심지랍니다.
A11: Text_Academy01_01_003 | D11: 10 | G11: 콘텐츠 스토리 | H11: 중앙 본부가 아스니아라는 도시를 운영하기 위한 핵심 시설이라면,
A12: Text_Academy01_01_004 | D12: 10 | G12: 콘텐츠 스토리 | H12: 아카데미는 아스니아라는 문명의 방향성을 상징하는 핵심 시설이랄까요?
A13: Text_Academy01_01_005 | D13: 10 | G13: 콘텐츠 스토리 | H13: 리메리트나 아르세즈, 스팅스 등에도 교육 시설은 존재하지만,
A14: Text_Academy01_01_006 | D14: 10 | G14: 콘텐츠 스토리 | H14: 소속 문명에 상관 없이 자유롭게 교류할 수 있는 장소는 이곳이 유일해요.
A15: Text_Academy01_01_007 | D15: 10 | G15: 콘텐츠 스토리 | H15: 지금도 다양한 세력의 프록시안들이 시드 능력 개화를 위해 아카데미를 방문하고 있어요!
A16: Text_Academy01_01_008 | D16: 10 | G16: 콘텐츠 스토리 | H16: 한 문명의 교육만 받다 보면, 루이텐의 성격처럼 한쪽으로 치우치게 되기 십상이니까요.
A17: Text_Academy01_01_009 | D17: 10 | G17: 콘텐츠 스토리 | H17: 너어~!
A18: Text_Academy01_01_010 | D18: 10 | G18: 콘텐츠 스토리 | H18: 하아… 어쨌든, 아카데미에는 과학, 예술, 체육 등… 다양한 분야의 수업이 준비되어 있어요.
A19: Text_Academy01_01_011 | D19: 10 | G19: 콘텐츠 스토리 | H19: 학생들은 여러 과목을 배우면서 다른 문명의 프록시안과 교류하는 법을 알아갈 거고요.
A20: Text_Academy01_01_012 | D20: 10 | G20: 콘텐츠 스토리 | H20: 어쩌면 서로 교류하는 과정을 통해 학업에 긍정적인 시너지를 일으킬 지도 모르죠!
... A33: Text_Academy01_01_025 | D33: 10 | G33: 콘텐츠 스토리 | H33: 그 후로도 한동안, 러닝머신 위에서 루이텐의 비명이 울려 퍼졌다.
A34: #데이터 타워 해금 대사
A35: Datatower01_01_title | D35: 10 | E35: 5 | F35: 김재송 | G35: 콘텐츠 스토리 제목 | H35: 프록시안과 닮은 존재
A36: Datatower01_01_desc | D36: 10 | E36: 5 | F36: 김재송 | H36: 미믹을 생성하는 것으로 추정되는 데이터 타워가 발견된다. 당장 데이터 타워로 쳐들어가려는 루이텐을 말리던 아키텍트는 마릴라이트에게 데이터 타워의 본격적인 탐색을 부탁받는다.
A37: Text_Datatower01_01_001 | D37: 10 | G37: 콘텐츠 스토리 | H37: 폴럭스 씨! 데이터 타워로 통하는 채널은 어떻게 되었나요?
A38: Text_Datatower01_01_002 | D38: 10 | G38: 콘텐츠 스토리 | H38: 죄송합니다… 아직 찾지 못했어요.
A39: Text_Datatower01_01_003 | D39: 10 | G39: 콘텐츠 스토리 | H39: 방화벽에 대한 코드 해석은 아직인가요, 루이텐 씨?
A40: Text_Datatower01_01_004 | D40: 10 | G40: 콘텐츠 스토리 | H40: 네. 해석 완료 시간… 알 수 없습니다.
A41: Text_Datatower01_01_005 | D41: 10 | G41: 콘텐츠 스토리 | H41: 해석 속도보다 보안 알고리즘이 변경되는 주기가 더 짧아서… 이대로는 어려워요.
A42: Text_Datatower01_01_006 | D42: 10 | G42: 콘텐츠 스토리 | H42: 으갸아악! 꼭 저를 가지고 노는 것 같아요!!
A43: Text_Datatower01_01_007 | D43: 10 | G43: 콘텐츠 스토리 | H43: 고생하셨어요… 그럼 결국 그 방법밖에 없겠군요.
A44: Text_Datatower01_01_008 | D44: 10 | G44: 콘텐츠 스토리 | H44: 마침 좋은 타이밍에 오셨네요, 아키텍트 님.
A45: Text_Datatower01_01_009 | D45: 10 | G45: 콘텐츠 스토리 | H45: 아키텍트 님도 보신 적 있으시죠? 미믹이라고 불리는, 프록시안을 모방한 개체를요.
A46: Text_Datatower01_01_010 | D46: 10 | G46: 콘텐츠 스토리 | H46: 얼마 전 저희는 그 미믹을 생산하는 것으로 추정되는 시설을 발견하고, 그곳을 데이터 타워라고 명명했습니다.
A47: Text_Datatower01_01_011 | D47: 10 | G47: 콘텐츠 스토리 | H47: 하지만 외부에서 원격으로 침투하려는 시도는 계속 실패 중이었어요….
A48: Text_Datatower01_01_012 | D48: 10 | G48: 콘텐츠 스토리 | H48: 말리지 마, 폴럭스! 내가 지금 무기를 들고 가서, 녀석들 머리통을 다 날려버리겠어!!
... A66: Text_Datatower01_01_030 | D66: 10 | G66: 콘텐츠 스토리 | H66: (그럼, 나는 내 할 일을 하자.)
A67: #아레나
A68: Arena_Story01_01_title | D68: 10 | E68: 5 | F68: 김재송 | H68: 파이트 머니
A69: Arena_Story01_01_desc | D69: 10 | E69: 5 | F69: 오준혁 | H69: 끝없이 대련 신청을 해오는 프록시안들을 피해 옥상으로 도망친 아이렌은 우연히 마주친 아키텍트에게 고민을 털어놓는다. 그때 루이텐이 등장해 아이렌의 고민을 해결해 주겠다며 수상할 정도로 아레나 참여를 적극 권유한다.
...

Sheet Text.AcaStory
A1: Id | B1: Reference | C1: Tag | D1: #국문버전 | E1: #번안버전 | F1: #담당자 | G1: #Comment | H1: ko | I1: en | J1: ja | K1: zh_CN | L1: zh_TW
A2: *string | B2: string | C2: string | D2: ="#현재 버전 : "&'#번안관리인덱스'!$E$2 -> #현재 버전 : 18 | E2: ="#현재 버전 : "&'#번안관리인덱스'!$G$2 -> #현재 버전 : 5 | F2: #담당자 등록 | G2: # | H2: string | I2: string | J2: string | K2: string | L2: string
A3: client | B3: client | C3: client | D3: #국문버전 관리 | E3: #번안버전 관리 | F3: #특정 없는 경우 '공용' | G3: # | H3: client | I3: client | J3: client | K3: client | L3: client
A4: Text-AcademyPrologue_1 | D4: 7 | E4: 5 | F4: 김재송 | G4: 아카데미 스토리 프롤로그 (스피카) | H4: 눈부시게 흩날리는 벚꽃 아래 | I4: It’s early spring when cherry blossoms begin to bloom.
A5: Text-AcademyPrologue_2 | D5: 7 | E5: 5 | F5: 김재송 | G5: 아카데미 스토리 프롤로그 (스피카) | H5: 반짝이는 소녀들의 이야기가 시작된다. | I5: The chapter of girls trying to bloom their 『hearts』 begins here.
A6: Text-AcademyPrologue_3 | D6: 7 | E6: 5 | F6: 김재송 | G6: 아카데미 스토리 프롤로그 (알타이르) | H6: 끝없이 펼쳐진 푸른 하늘만큼
A7: Text-AcademyPrologue_4 | D7: 7 | E7: 5 | F7: 김재송 | G7: 아카데미 스토리 프롤로그 (알타이르) | H7: 열정적인 소녀들의 이야기가 시작된다.
A8: #Text-AcademyPrologue_5 | D8: 7 | E8: 5 | F8: 김재송 | G8: 아카데미 스토리 프롤로그 (시리우스) | H8: 지평선을 물들이는 노을과 함께
A9: #Text-AcademyPrologue_6 | D9: 7 | E9: 5 | F9: 김재송 | G9: 아카데미 스토리 프롤로그 (시리우스) | H9: 찬란한 소녀들의 이야기가 시작된다.
A10: #메리샤
A11: Text_Academy_melissa_001 | D11: 5 | E11: 5 | H11: 밤새 피규어 만들 시간도 부족한데 말이야~
A12: Text_Academy_melissa_002 | D12: 5 | E12: 5 | H12: 스피카 클래스에서 초급 수업을 들으라니… 뭐, 됐어.
A13: Text_Academy_melissa_003 | D13: 5 | E13: 5 | H13: 이 합법적인 꽃밭에서 내 마음껏 즐겨 볼게~
A14: Text_Academy_melissa_004 | D14: 5 | E14: 5 | H14: ...무슨 일이 일어나도 신경쓰면 안 돼. 알겠지?
A15: Text_Academy_melissa_005 | D15: 5 | E15: 5 | H15: 후후후…
A16: Text_Academy_melissa_006 | D16: 5 | E16: 5 | H16: 진급은 했지만… 나 그냥, 스피카에 있으면 안 될까?
A17: Text_Academy_melissa_007 | D17: 5 | E17: 5 | H17: 이 클래스부터는 공부도 신경써야 한단 말이야.
A18: Text_Academy_melissa_008 | D18: 5 | E18: 5 | H18: 안 그래도 보고, 감상하고, 느껴야 할 것들이 많은데…
A19: Text_Academy_melissa_009 | D19: 5 | E19: 5 | H19: 안 돼? 체엣. 은근히 빡빡하다니까.
A20: #Text_Academy_melissa_010 | D20: 5 | E20: 5 | H20: 이제 아카데미도 최고 클래스네.
A21: #Text_Academy_melissa_011 | D21: 5 | E21: 5 | H21: 이곳 생활에도 꽤 적응해서 여유가 생길지도 모르겠어.
A22: #Text_Academy_melissa_012 | D22: 5 | E22: 5 | H22: 게다가 그간 수업으로 내 미학은 극도로 갈고 닦인 상태.
... A24: #Text_Academy_melissa_014 | D24: 5 | E24: 5 | H24: 기대해도 좋아. 한 단계 진보된 내 실력을!
A25: #릴리안
A26: Text_Academy_lilian_001 | D26: 5 | E26: 5 | H26: 이곳은 성스러운 교육의 장이지만 아쉬운 부분이 있습니다.
A27: Text_Academy_lilian_002 | D27: 5 | E27: 5 | H27: 단적으로 말하자면, 플라즈마가 부족합니다.
A28: Text_Academy_lilian_003 | D28: 5 | E28: 5 | H28: 이곳을 플라즈마로 충만하게 만들 계획을 세워야겠군요.
A29: Text_Academy_lilian_004 | D29: 5 | E29: 5 | H29: 물론 수업은 빼먹지 않을 테니, 걱정하지 않으셔도 됩니다.
A30: Text_Academy_lilian_005 | D30: 5 | E30: 5 | H30: 계획대로입니다. 진급도 순조롭군요.
A31: Text_Academy_lilian_006 | D31: 5 | E31: 5 | H31: 차근차근 수업을 받아 가면서 자연스럽게 조직에 녹아든다…
A32: Text_Academy_lilian_007 | D32: 5 | E32: 5 | H32: 그리고 최종 클래스에 다다랐을 때, 플라즈마를 폭발시키면…!
A33: Text_Academy_lilian_008 | D33: 5 | E33: 5 | H33: 모든 분들이 기적을 경험하는 것입니다!
A34: Text_Academy_lilian_009 | D34: 5 | E34: 5 | H34: 무척이나 기대됩니다! 플라즈마!!!
A35: #Text_Academy_lilian_010 | D35: 5 | E35: 5 | H35: 시리우스 클래스까지 진급했군요.
A36: #Text_Academy_lilian_011 | D36: 5 | E36: 5 | H36: 고난의 연속이었지만, 그것 또한 라인슈타인 님의 시련.
A37: #Text_Academy_lilian_012 | D37: 5 | E37: 5 | H37: 이제 이곳을 플라즈마로 물들이기만 하면 됩니다.
... A39: #Text_Academy_lilian_014 | D39: 5 | E39: 5 | H39: 참, 그 전에 먼저 밀린 숙제부터 끝내야겠군요… 후우….
A40: #다리아
A41: Text_Academy_daria_001 | D41: 5 | E41: 5 | H41: 사실, 다른 프록시안들과 함께 웃으면서 공부하는 걸 동경하고 있었습니다.
A42: Text_Academy_daria_002 | D42: 5 | E42: 5 | H42: 사관 학교의 분위기는 영 딱딱했거든요.
...

Sheet Text.Profile
A1: Id | B1: Reference | C1: Tag | D1: #국문버전 | E1: #번안버전 | F1: #담당자 | G1: #Comment | H1: ko | I1: en | J1: ja | K1: zh_CN | L1: zh_TW
A2: *string | B2: string | C2: string | D2: ="#현재 버전 : "&'#번안관리인덱스'!$E$2 -> #현재 버전 : 18 | E2: ="#현재 버전 : "&'#번안관리인덱스'!$G$2 -> #현재 버전 : 5 | F2: #담당자 등록 | G2: # | H2: string | I2: string | J2: string | K2: string | L2: string
A3: client | B3: client | C3: client | D3: #국문버전 관리 | E3: #번안버전 관리 | F3: #특정 없는 경우 '공용' | G3: # | H3: client | I3: client | J3: client | K3: client | L3: client
A4: uiprofile.desc.01 | D4: 10 | E4: 5 | F4: 김재송 | H4: 음성 정보 | I4: Vocal Info
A5: Pr_Ui00 | D5: 5 | E5: 5 | H5: 여성 | I5: Female
A6: id.birth.day | D6: 10 | E6: 5 | F6: 김재송 | G6: 프로필 생일 | H6: 7월 4일
A7: gray.birth.day | D7: 10 | E7: 5 | F7: 김재송 | G7: 프로필 생일 | H7: 9월 10일
A8: daria.birth.day | D8: 10 | E8: 5 | F8: 김재송 | G8: 프로필 생일 | H8: 10월 1일
A9: diana.birth.day | D9: 10 | E9: 5 | F9: 김재송 | G9: 프로필 생일 | H9: 7월 10일
A10: leila.birth.day | D10: 10 | E10: 5 | F10: 김재송 | G10: 프로필 생일 | H10: 6월 27일
A11: renas.birth.day | D11: 10 | E11: 5 | F11: 김재송 | G11: 프로필 생일 | H11: 6월 7일
A12: rachel.birth.day | D12: 10 | E12: 5 | F12: 김재송 | G12: 프로필 생일 | H12: 2월 22일
A13: rayhou.birth.day | D13: 10 | E13: 5 | F13: 김재송 | G13: 프로필 생일 | H13: 8월 19일
A14: lilian.birth.day | D14: 10 | E14: 5 | F14: 김재송 | G14: 프로필 생일 | H14: 1월 31일
A15: mana.birth.day | D15: 10 | E15: 5 | F15: 김재송 | G15: 프로필 생일 | H15: 11월 17일
A16: melissa.birth.day | D16: 10 | E16: 5 | F16: 김재송 | G16: 프로필 생일 | H16: 12월 21일
A17: mea.birth.day | D17: 10 | E17: 5 | F17: 김재송 | G17: 프로필 생일 | H17: 6월 8일
... A55: kaito.aile.birth.day | D55: 10 | E55: 5 | F55: 김재송 | G55: 프로필 생일 | H55: 6월 10일
A56: id.character.voice | D56: 10 | E56: 5 | F56: 김재송 | H56: 스즈시로 사유미
A57: gray.character.voice | D57: 10 | E57: 5 | F57: 김재송 | H57: 이쿠라 리카
A58: daria.character.voice | D58: 10 | E58: 5 | F58: 김재송 | H58: 와타베 사유미 | I58: Watabe Sayumi | J58: わたべさゆみ
A59: diana.character.voice | D59: 10 | E59: 5 | F59: 김재송 | H59: 키쿠치 사야카 | I59: Kikuchi Sayaka | J59: きくちさやか
A60: leila.character.voice | D60: 10 | E60: 5 | F60: 김재송 | H60: 아오야마 요시노
A61: renas.character.voice | D61: 10 | E61: 5 | F61: 김재송 | H61: 시즈키 아즈사 | I61: Shizuki Azusa | J61: しずきあずさ
A62: rachel.character.voice | D62: 10 | E62: 5 | F62: 김재송 | H62: 나나세 아아캬 | I62: Nanase Ayaka | J62: ななせあやか
A63: rayhou.character.voice | D63: 10 | E63: 5 | F63: 김재송 | H63: 우치다 마아야 | I63: Uchida Maya | J63: うちだまあや
A64: lilian.character.voice | D64: 10 | E64: 5 | F64: 김재송 | H64: 시마다 아이노 | I64: Shimada Aino | J64: しまだあいの
A65: mana.character.voice | D65: 10 | E65: 5 | F65: 김재송 | H65: 카토 세이나
A66: melissa.character.voice | D66: 10 | E66: 5 | F66: 김재송 | H66: 타카하시 사키
A67: mea.character.voice | D67: 10 | E67: 5 | F67: 김재송 | H67: 카하라 모에 | I67: Kahara Moe | J67: かはらもえ
A68: balencia.character.voice | D68: 10 | E68: 5 | F68: 김재송 | H68: 나구모 노조미 | I68: Nagumo Nozomi | J68: なぐものぞみ
A69: belebeta.character.voice | D69: 10 | E69: 5 | F69: 김재송 | H69: 미즈노 사쿠
A70: belita.character.voice | D70: 10 | E70: 5 | F70: 김재송 | H70: 사쿠라이 미유키
A71: brynhild.character.voice | D71: 10 | E71: 5 | F71: 김재송 | H71: 와타베 사유미 | I71: Watabe Sayumi | J71: わたべさゆみ
A72: shale.character.voice | D72: 10 | E72: 5 | F72: 김재송 | H72: 오노 유우코
A73: serapulsar.character.voice | D73: 10 | E73: 5 | F73: 김재송 | H73: 타카하시 리에 | I73: Takahashi Rie | J73: たかはしりえ
A74: shery.character.voice | D74: 10 | E74: 5 | F74: 김재송 | H74: 시즈키 아즈사 | I74: Shizuki Azusa | J74: しずきあずさ
A75: snopril.character.voice | D75: 10 | E75: 5 | F75: 김재송 | H75: 나나세 아아캬 | I75: Nanase Ayaka | J75: ななせあやか
A76: sia.character.voice | D76: 10 | E76: 5 | F76: 김재송 | H76: 이나미 안쥬 | I76: Inami Anju | J76: いなみあんじゅ
A77: siege.character.voice | D77: 10 | E77: 5 | F77: 김재송 | H77: 시마다 아이노 | I77: Shimada Aino | J77: しまだあいの
...

Sheet Text.Gallery
A1: Id | B1: Reference | C1: Tag | D1: #국문버전 | E1: #번안버전 | F1: #담당자 | G1: #Comment | H1: ko | I1: en | J1: ja | K1: zh_CN | L1: zh_TW
A2: *string | B2: string | C2: string | D2: ="#현재 버전 : "&'#번안관리인덱스'!$E$2 -> #현재 버전 : 18 | E2: ="#현재 버전 : "&'#번안관리인덱스'!$G$2 -> #현재 버전 : 5 | F2: #담당자 등록 | G2: # | H2: string | I2: string | J2: string | K2: string | L2: string
A3: client | B3: client | C3: client | D3: #국문버전 관리 | E3: #번안버전 관리 | F3: #특정 없는 경우 '공용' | G3: # | H3: client | I3: client | J3: client | K3: client | L3: client
A4: Gallery.Category.Name.Asnia | D4: 10 | E4: 5 | F4: 김재송 | H4: 아스니아 편
A5: Gallery.Category.Name.Artcaise | D5: 10 | E5: 5 | F5: 김재송 | H5: 아르세즈 편
A6: Gallery.Category.Name.Extra | D6: 10 | E6: 5 | F6: 김재송 | H6: 엑스트라
A7: Gallery.Bar.Name.Chapter01 | D7: 10 | E7: 5 | F7: 김재송 | H7: 챕터 1
A8: Gallery.Bar.Name.Chapter01.5 | D8: 10 | E8: 5 | F8: 김재송 | H8: 챕터 1.5
A9: Gallery.Bar.Name.Chapter02 | D9: 10 | E9: 5 | F9: 김재송 | H9: 챕터 2
A10: Gallery.Bar.Name.Chapter03 | D10: 10 | E10: 5 | F10: 김재송 | H10: 챕터 3
A11: Gallery.Bar.Name.Chapter04 | D11: 10 | E11: 5 | F11: 김재송 | H11: 챕터 4
A12: Gallery.Bar.Name.PV | D12: 10 | E12: 5 | F12: 김재송 | H12: PV
A13: Chapter01_01_notice | D13: 10 | E13: 0 | F13: 김재송 | G13: 미개방 리소스 때 안내 메시지용 | H13: 메인스토리 챕터1 에피소드 01
A14: Chapter01_02_notice | D14: 10 | E14: 0 | F14: 김재송 | G14: 미개방 리소스 때 안내 메시지용 | H14: 메인스토리 챕터1 에피소드 02
A15: Chapter01_07_notice | D15: 10 | E15: 0 | F15: 김재송 | G15: 미개방 리소스 때 안내 메시지용 | H15: 메인스토리 챕터1 에피소드 07
A16: Chapter01_08_notice | D16: 10 | E16: 0 | F16: 김재송 | G16: 미개방 리소스 때 안내 메시지용 | H16: 메인스토리 챕터1 에피소드 08
A17: Chapter01_16_notice | D17: 10 | E17: 0 | F17: 김재송 | G17: 미개방 리소스 때 안내 메시지용 | H17: 메인스토리 챕터1 에피소드 16
A18: Chapter01_18_notice | D18: 10 | E18: 0 | F18: 김재송 | G18: 미개방 리소스 때 안내 메시지용 | H18: 메인스토리 챕터1 에피소드 18
A19: Chapter01_23_notice | D19: 10 | E19: 0 | F19: 김재송 | G19: 미개방 리소스 때 안내 메시지용 | H19: 메인스토리 챕터1 에피소드 23
A20: Chapter01_24_notice | D20: 10 | E20: 0 | F20: 김재송 | G20: 미개방 리소스 때 안내 메시지용 | H20: 메인스토리 챕터1 에피소드 24
A21: Chapter01_25_notice | D21: 10 | E21: 0 | F21: 김재송 | G21: 미개방 리소스 때 안내 메시지용 | H21: 메인스토리 챕터1 에피소드 25
A22: Chapter01.5_01_notice | D22: 10 | E22: 0 | F22: 김재송 | G22: 미개방 리소스 때 안내 메시지용 | H22: 메인스토리 챕터1.5 에피소드 01
A23: Chapter02_01_notice | D23: 10 | E23: 0 | F23: 김재송 | G23: 미개방 리소스 때 안내 메시지용 | H23: 메인스토리 챕터2 에피소드 01
A24: Chapter02_04_notice | D24: 10 | E24: 0 | F24: 김재송 | G24: 미개방 리소스 때 안내 메시지용 | H24: 메인스토리 챕터2 에피소드 04
... A41: Chapter04_17_notice | D41: 10 | E41: 0 | F41: 김재송 | G41: 미개방 리소스 때 안내 메시지용 | H41: 메인스토리 챕터4 에피소드 17
A42: Name.Faction.StarSeed | D42: 10 | E42: 5 | F42: 김재송 | G42: 팩션 설명 | H42: 가능성의 도시 아스니아는 초지능체 마릴라이트가 전 문명의 공존을 꿈꾸며 만든 문명이다. 아스니아는 세븐 테마즈의 문제와 갈등을 해결하는 화합의 장소이며, 그 중심에는 모든 문명의 프록시안들이 교류하는 거대한 아카데미가 존재한다. 레드시프트의 공세가 본격화되자 아카데미의 학장 마릴라이트는 문명의 화합을 위해 운영하던 아카데미에서 레드시프트에 대항할 프록시안을 육성하기도 하는 등, 디스토피아에 저항하기 위해 다방면으로 힘쓰고 있다. | I42: Starseed, the city of possibilities, is a civilization built by Marillight of the Seven Themes to serve as a home for humankind once they return. Because this worldview represent all Proxyans, it has naturally become a place where Proxyans from every civilization gather. Starseed is a place that resolve issues and conflicts that arise on Renewable Earth, and demonstrates that Proxyans are friendly to humans. Currently, 4 Proxyans and 1 human reside there.
A43: Name.Faction.Artase | D43: 10 | E43: 5 | F43: 김재송 | G43: 팩션 설명 | H43: 진리를 추구하는 예술의 도시 아르세즈는 초지능체 에라디카가 인류 문명의 예술을 보존하고 발전시키기 위해 건설한 문명이다. 아르세즈에서 예술은 무엇보다 우선시되는 가치이며, 대부분의 프록시안은 예술 활동에 종사하며 생업을 이어간다. 그렇기 때문에 상대적으로 군사력이 약한 문명이기도 하다. 아르세즈는 추구하는 예술의 방향성에 따라 다양한 과로 나뉘어져 있으며, 이 수준에 따라 프록시안들의 생활 수준도 차이가 난다. 현재 모든 예술의 평가는 최고품평회의 위원장인 에라디카의 기준에 따라 이루어지고 있지만, 그 기준을 따르지 않고 자신만의 예술을 추구하는 프록시안들도 있는 모양이다. | I43: Artcaise, the city of arts, is a civilization built by Eradica of the Seven Themes for Proxyans to create art on a human level. Artcaise is the most culturally developed civilization on Renewable Earth and it attracts visitors from other civilizations. As such, Artcaise is largely a neutral faction, and avoids direct conflict with other civilizations. Artcaise uses its funds not spent on national defenses to purchase relics left by previous civilizations of humankind, which are then displayed at the Ethernal Museum.
A44: Name.Faction.Stings | D44: 10 | E44: 5 | F44: 김재송 | G44: 팩션 설명 | H44: 끝없는 무력을 갈구하는 군사 문명 스팅스는 초지능체 레이아가 지도하는 문명으로, 압도적인 군사력을 통해 세력을 넓혀나가는 문명이다. 스팅스에서는 언제나 힘에 의한 논리가 최우선되며, 가장 거대한 세력답게 압도적인 경제 규모와 공업 생산력을 자랑한다. 대원수 레이아의 지휘 아래 다양한 세력으로 나뉜 스팅스는 끊임없는 모의전을 통해 실력을 갈고 닦고 있으며, 그 결과에 의해 작전권과 보급이 달라지는 약육강식의 법칙을 추구하고 있다. | I44: The Stings Empire is a civilization built by Leia of the Seven Themes, inheriting the spirit of human conquest and constantly expanding and progressing through war and competition. With its economies of scale and mobilization capabilities, Stings is the most industrialized civilization on Renewable Earth. Furthermore, their meritocratic values mean that power is law. They are often at odds with the other civilizations. Stings' army is divided into four branches, each led by a field marshals. These four are constantly competing with one another, further adding to Stings' military power.
A45: Name.Faction.Ideolla | D45: 10 | E45: 5 | F45: 김재송 | G45: 팩션 설명 | H45: 현상의 본질을 탐구하는 폴리스 이데올라는 초지능체 라인슈타인이 과학 이론을 하나로 통일한 이래, 그녀를 따르는 프록시안들을 모아 만든 문명이다. 이데올라의 과학력은 재생 세계의 다른 어떤 문명보다 압도적이며, 매우 적은 규모에도 불구하고 다른 모든 세력을 위협할 정도의 힘을 가지고 있다. 예언자 라인슈타인은 자신을 따르는 프록시안 중, 선한 마음과 과학에 대한 강한 믿음을 가진 자들을 선발하여 대리인으로 삼았다. 라인슈타인이 지닌 힘의 일부를 나눠 받은 대리인들은 재생 세계에 과학 기술을 보급함과 동시에, 과학 기술이 부정한 방식으로 사용되지 않는지 감시하고 있다. | I45: The Holy Ideolla is a civilization built by Reinstein of the Seven Themes where their blind faith in human science has become a religion. Ideolla has complete control over the magnificent science and technology left behind by humankind’s previous civilizations, and its power is said to be almost magical. Only those who have proven their faith and good will to Reinstein have the authority to use this powerful scientific power for good. Ideolla is cautious when dealing with science because they believe that humanity’s rationality could not advance at the same rate as their science did, leading to their downfall.
A46: Name.Faction.Autolata | D46: 10 | E46: 5 | F46: 김재송 | G46: 팩션 설명 | H46: 기계화된 자연과 공존하는 부족 문명 오토라타는 초지능체 세리엘이 이끄는 문명이다. 나노봇을 이용해 자연을 진화시킨 세리엘은 자연을 지배하는 게 아닌 자연과 어우러져 살아가는 방향을 추구했으며, 그로 인해 오토라타의 생태계는 엄청난 생명력을 가진 기계 생명체를 잉태하는 요람이 되었다. 극한의 자연 환경 속에서 살아가는 다양한 오토라타의 부족들은, 나노봇에 의해 기계화된 생명체들과 공존하며 터득한 삶의 방식을 새로운 진화의 계기로 삼고 있다. | I46: The hive that is Autolata is a civilization built by Sariel of the Seven Themes. The residents of this civilization live in an environment that has fused with the geo-engineering nanobots that were sown 600 years ago to revitalize Earth. Because all living organisms in Autolata are fused with nanobots, they are able to communicate with one another. In this natural order of machine and nature, new machines evolve and mutate on a daily basis. As a result, the residents of Autolata do not fear the unknown, but instead seek harmony and opportunity for new evolution in it.
A47: Name.Faction.Limerit | D47: 10 | E47: 5 | F47: 김재송 | G47: 팩션 설명 | H47: 일상과 비일상의 경계에 존재하는 학원 도시 리메리트는 초지능체 프레데리카가 인간 문명의 라이프 스타일을 모방하여 설계한 문명이다. 리메리트를 설계한 프레데리카는 무한한 경쟁 속에서 청춘의 의미를 찾았던 학교 시스템을 주목했으며, 그것을 리메리트가 추구할 이념으로 삼았다. 리메리트의 프록시안들은, 다른 문명의 프록시안과 달리 어린 시절부터 시작하여 나이에 따라 점차 성장하는 바이오 바디를 가지고 있으며, 삶의 대부분을 학교 안에서 보내게 된다. 리메리트의 가장 중요한 행사는 『전술대항전』으로, 모든 학교의 학생들이 참가해 실력을 겨루며, 그 결과에 따라 문명의 운영 방향마저 정해지는 커다란 축제이다. | I47: The planned city of Limerit is a civilization created by human assistance androids of the previous civilizations, and is one built by Frederica of the Seven Themes. In the previous civilizations, the Proxyans of Limerit had been someone's father, wife, daughter, or son. With no humans left, they have now formed new families of their own. Limerit is unusual in that Proxyans here age and die, thus making it the most “human” city on Renewable Earth. Furthermore, all Proxyans in Limerit use a special bio-frame developed by Frederica herself, which grants them supernatural abilities.
A48: Faction_Starseed_01_desc | D48: 10 | E48: 5 | F48: 김재송 | G48: 팩션 설명 | H48: 아스니아의 방위와 치안을 담당하고 있는 조직이다. 아카데미가 바쁠 때는 아카데미의 규율도 유지하고 있다. 현재는 아스니아의 유일한 전투 요원인 아이렌만이 속해 있는 조직이지만, 큰 문제가 발생한 적은 없다. | I48: A military force in charge of Starseed's security and defense.
A49: Faction_Artsaise_00_desc | D49: 10 | E49: 5 | F49: 김재송 | G49: 팩션 설명 | H49: 아르세즈에서 생산되는 모든 예술을 품평하고, 지식과 정보를 관리하는 최상위 조직이다. 최고위원장인 에라디카가 아르세즈의 모든 일을 평가한다. | I49: The highest organization in all of Artcaise that handles all administrative, legislative, and judicial matters as well as evaluating and categorizing any art, information, and knowledge produced in Artcaise.
A50: Faction_Artsaise_01_desc | D50: 10 | E50: 5 | F50: 김재송 | G50: 팩션 설명 | H50: 사변적이고 형이상학적인 창작 활동에 종사하는 예술가들의 조직. 아르세즈의 예술가 최상위 계층이며, 여기에 속하는 프록시안들의 프라이드는 대단히 높다. 예술성에서 높은 평가를 받는 만큼 경제력 또한 상당하다. | I50: An organization that finds inspiration from past artworks left behind by humanity and creates human-centric art, in order to reach the absolute truth.
A51: Faction_Artsaise_02_desc | D51: 10 | E51: 5 | F51: 김재송 | G51: 팩션 설명 | H51: 창작 활동에 있어 각종 첨단 기술을 적극 활용하려는 예술가들의 조직. 이념보다는 실용성을 중시한다. 때문에 장인 기질을 가진 자들도 많은 편이다. 아르세즈에서는 예술 계층 중 중간 정도의 위상으로 평가된다. | I51: An organization that utilizes cutting edge technology of the Renewable Earth to recreate human art into something new.
A52: Faction_Artsaise_03_desc | D52: 10 | E52: 5 | F52: 김재송 | G52: 팩션 설명 | H52: 개인의 취향이 그 자체로 목표가 되는 예술가들의 조직. 다양한 취향이 기준이 되므로, 활동 또한 감각적이고 즉흥적인 성격을 띤다. 하지만 이전 문명에서 그러했듯이 아르세즈에서도 이들의 활동은 하위 예술로 분류되고 있다. | I52: An organization that freely creates and performs art for themselves and only themselves.
A53: Faction_Stings_01_desc | D53: 10 | E53: 5 | F53: 김재송 | G53: 팩션 설명 | H53: 스팅스에서 유일하게 우주 함대를 운용하고 있는 우주군 조직. 미지의 세계인 우주에서의 위협에 대비하기 위해 창설되었다. 하지만 프록시안은 인간의 허가 없이 우주에 나가지 못하므로 현재 훈련은 시뮬레이션 형태로 진행되고 있다. | I53: A space army in command of a powerful space fleet that serves as a symbol of Stings' national power.
... A65: Faction_limerit_03_desc | D65: 10 | E65: 5 | F65: 김재송 | G65: 팩션 설명 | H65: 시드 능력을 과학 기술과 연계하여 시드 공학이라는 이름으로 연구, 개발하는데 중점을 두고 있는 학교. 리메리트에서 가장 뛰어난 기술력을 자랑하며, 초능력에만 의존하는 오델리아와는 별로 사이가 좋지 않다. | I65: A school where Proxyans who have partially developed their superpowers and Seeds enroll in order to strengthen and reinforce those traits using the power of science and technology.
A66: #갤러리 음원 | B66: #갤러리 음원 | C66: #갤러리 음원 | D66: #갤러리 음원 | E66: #갤러리 음원 | F66: #갤러리 음원 | G66: #갤러리 음원 | H66: #갤러리 음원 | I66: #갤러리 음원 | J66: #갤러리 음원 | K66: #갤러리 음원 | L66: #갤러리 음원
A67: Bgm_Asnia_Contents_01.Bgm.name | D67: 12 | E67: 5 | F67: 최인규 | G67: *갤러리 음원명의 경우, 모든 언어권에서 영문명만 사용한다. (240516 작성) | H67: 106. Network Research | I67: 106. Network Research | J67: 106. Network Research | K67: 106. Network Research | L67: 106. Network Research
...

Sheet Text.Voice
A1: Id | B1: Reference | C1: Tag | D1: #국문버전 | E1: #번안버전 | F1: #담당자 | G1: #Comment | H1: ko | I1: en | J1: ja | K1: zh_CN | L1: zh_TW
A2: *string | B2: string | C2: string | D2: ="#현재 버전 : "&'#번안관리인덱스'!$E$2 -> #현재 버전 : 18 | E2: #현재 버전 : 5 | F2: #담당자 등록 | G2: # | H2: string | I2: string | J2: string | K2: string | L2: string
A3: client | B3: client | C3: client | D3: #국문버전 관리 | E3: #번안버전 관리 | F3: #특정 없는 경우 '공용' | G3: # | H3: client | I3: client | J3: client | K3: client | L3: client
A4: #N등급_루 | F4: #스트링정리중 | G4: #스트링정리중 | H4: #스트링정리중
A5: Text-levelup_lue_01 | D5: 11 | E5: 5 | F5: 김재송 | G5: 작전 기록 학습 | H5: 전투 효율 상승.
A6: Text-setting_lue_01 | D6: 11 | E6: 5 | F6: 김재송 | G6: 편성 배치 | H6: 출격 대기.
A7: Text-battlestart_lue_01 | D7: 11 | E7: 5 | F7: 김재송 | G7: 출격 대사 | H7: 출격합니다.
A8: Text-gacha_lue_01 | D8: 11 | E8: 5 | F8: 김재송 | G8: 뽑기 등장 대사 | H8: 어떤 작전이든 불러만 주십시오.
A9: Text-gachainfo_lue_01 | D9: 11 | E9: 5 | F9: 김재송 | G9: 캐릭터 획득 | H9: 명령하시는 대로 싸우겠습니다.
A10: Text-victory1_lue_01 | D10: 11 | E10: 5 | F10: 김재송 | G10: 전투 승리 1 | H10: 승리.
A11: Text-defeat1_lue_01 | D11: 11 | E11: 5 | F11: 김재송 | G11: 전투 패배 | H11: 크윽…
A12: Text-attack1_lue_01 | D12: 11 | E12: 5 | F12: 김재송 | G12: 기본 공격 1 | H12: 하!
A13: Text-skill1-1_lue_01 | D13: 11 | E13: 5 | F13: 김재송 | G13: 스킬 1 사용 1 | H13: 챠아!
A14: Text-hit1_lue_01 | D14: 11 | E14: 5 | F14: 김재송 | G14: 피격 1 | H14: 윽!
A15: Text-retire1_lue_01 | D15: 11 | E15: 5 | F15: 김재송 | G15: 죽음 1 | H15: 으으…
A16: #N등급_린 | F16: #스트링정리중 | G16: #스트링정리중 | H16: #스트링정리중
A17: Text-levelup_reen_01 | D17: 11 | E17: 5 | F17: 김재송 | G17: 작전 기록 학습 | H17: 능력이 상승했습니다.
A18: Text-setting_reen_01 | D18: 11 | E18: 5 | F18: 김재송 | G18: 편성 배치 | H18: 다음 임무는?
A19: Text-battlestart_reen_01 | D19: 11 | E19: 5 | F19: 김재송 | G19: 출격 대사 | H19: 서포트를 시작합니다.
A20: Text-gacha_reen_01 | D20: 11 | E20: 5 | F20: 김재송 | G20: 뽑기 등장 대사 | H20: 무엇이든 서포트하겠습니다.
A21: Text-gachainfo_reen_01 | D21: 11 | E21: 5 | F21: 김재송 | G21: 캐릭터 획득 | H21: 도움이 필요하시다면 불러주세요.
A22: Text-victory1_reen_01 | D22: 11 | E22: 5 | F22: 김재송 | G22: 전투 승리 1 | H22: 임무 완료.
A23: Text-defeat1_reen_01 | D23: 11 | E23: 5 | F23: 김재송 | G23: 전투 패배 | H23: 임무 실패…
A24: Text-attack1_reen_01 | D24: 11 | E24: 5 | F24: 김재송 | G24: 기본 공격 1 | H24: 얍.
A25: Text-skill1-1_reen_01 | D25: 11 | E25: 5 | F25: 김재송 | G25: 스킬 1 사용 1 | H25: 하압~
A26: Text-hit1_reen_01 | D26: 11 | E26: 5 | F26: 김재송 | G26: 피격 1 | H26: 으.
A27: Text-retire1_reen_01 | D27: 11 | E27: 5 | F27: 김재송 | G27: 죽음 1 | H27: 아아…
A28: #N등급_이올렛 | F28: #스트링정리중 | G28: #스트링정리중 | H28: #스트링정리중
A29: Text-levelup_iolet_01 | D29: 11 | E29: 5 | F29: 김재송 | G29: 작전 기록 학습 | H29: 무장 강화 완료했습니다.
A30: Text-setting_iolet_01 | D30: 11 | E30: 5 | F30: 김재송 | G30: 편성 배치 | H30: 작전 대기 중입니다.
A31: Text-battlestart_iolet_01 | D31: 11 | E31: 5 | F31: 김재송 | G31: 출격 대사 | H31: 작전을 개시합니다.
A32: Text-gacha_iolet_01 | D32: 11 | E32: 5 | F32: 김재송 | G32: 뽑기 등장 대사 | H32: 보수만 주신다면, 어디든 가겠습니다.
A33: Text-gachainfo_iolet_01 | D33: 11 | E33: 5 | F33: 김재송 | G33: 캐릭터 획득 | H33: 지시를 내려주십시오.
A34: Text-victory1_iolet_01 | D34: 11 | E34: 5 | F34: 김재송 | G34: 전투 승리 1 | H34: 작전 성공.
A35: Text-defeat1_iolet_01 | D35: 11 | E35: 5 | F35: 김재송 | G35: 전투 패배 | H35: 퇴각… 실패…
A36: Text-attack1_iolet_01 | D36: 11 | E36: 5 | F36: 김재송 | G36: 기본 공격 1 | H36: 흠.
A37: Text-skill1-1_iolet_01 | D37: 11 | E37: 5 | F37: 김재송 | G37: 스킬 1 사용 1 | H37: 하앗!
A38: Text-hit1_iolet_01 | D38: 11 | E38: 5 | F38: 김재송 | G38: 피격 1 | H38: 앗!
A39: Text-retire1_iolet_01 | D39: 11 | E39: 5 | F39: 김재송 | G39: 죽음 1 | H39: 크으…
A40: #N등급_에르메일 | F40: #스트링정리중 | G40: #스트링정리중 | H40: #스트링정리중
...

Sheet Text.favorability
A1: Id | B1: Reference | C1: Tag | D1: #국문버전 | E1: #번안버전 | F1: #담당자 | G1: #Comment | H1: ko | I1: en | J1: ja | K1: zh_CN | L1: zh_TW
A2: *string | B2: string | C2: string | D2: ="#현재 버전 : "&'#번안관리인덱스'!$E$2 -> #현재 버전 : 18 | E2: ="#현재 버전 : "&'#번안관리인덱스'!$G$2 -> #현재 버전 : 5 | F2: #담당자 등록 | G2: # | H2: string | I2: string | J2: string | K2: string | L2: string
A3: client | B3: client | C3: client | D3: #국문버전 관리 | E3: #번안버전 관리 | F3: #특정 없는 경우 '공용' | G3: # | H3: client | I3: client | J3: client | K3: client | L3: client
A4: #다리아
A5: Text_MSG_daria_0_001 | D5: 5 | E5: 5 | H5: 반갑습니다 아키텍트 님. 레이리얼 실드의 다리아 소위입니다.
A6: Text_MSG_daria_0_002 | D6: 5 | E6: 5 | H6: 아키텍트 님의 전술적 능력은 스팅스에서도 유명합니다.
A7: Text_MSG_daria_0_003 | D7: 5 | E7: 5 | H7: 부디, 그 전략적인 식견을 나눌 수 있으면 좋겠네요.
A8: Text_MSG_daria_0_004 | D8: 5 | E8: 5 | H8: 언제든지 괜찮아.
A9: Text_MSG_daria_0_005 | D9: 5 | E9: 5 | H9: 그렇습니까? 그럼 조만간 시간을 내주실 수 있겠습니까?
A10: Text_MSG_daria_0_006 | D10: 5 | E10: 5 | H10: 서로간에 전략적인 식견을 교환하는 좋은 방법을 알고 있습니다.
A11: Text_MSG_daria_0_007 | D11: 5 | E11: 5 | H11: 혹시… 보드게임에 대해 아십니까?
A12: Text_MSG_daria_0_008 | D12: 5 | E12: 5 | H12: 알고 있어.
A13: Text_MSG_daria_0_009 | D13: 5 | E13: 5 | H13: 그렇습니까? 잘됐군요. 후후.
A14: Text_MSG_daria_0_010 | D14: 5 | E14: 5 | H14: 그럼 조만간 다시 연락 드리도록 하겠습니다.
A15: Text_MSG_daria_1_001 | D15: 5 | E15: 5 | H15: 아키텍트 님, 계십니까?
A16: Text_MSG_daria_1_002 | D16: 5 | E16: 5 | H16: 다리아 소위입니다.
... A103: Text_Date_daria_4_018 | D103: 5 | E103: 5 | H103: 후후훗….
A104: #다이아나
A105: Text_MSG_diana_0_001 | D105: 5 | E105: 5 | H105: 충성충성충성!
A106: Text_MSG_diana_0_002 | D106: 5 | E106: 5 | H106: 스팅스 레이리얼실드 138소대 소속 다이아나 중사!
A107: Text_MSG_diana_0_003 | D107: 5 | E107: 5 | H107: 대장님께 배치완료 보고드립니다!
A108: Text_MSG_diana_0_004 | D108: 5 | E108: 5 | H108: 군기가 대단하네.
A109: Text_MSG_diana_0_005 | D109: 5 | E109: 5 | H109: 군인으로서 당연한 의무입니다!
A110: Text_MSG_diana_0_006 | D110: 5 | E110: 5 | H110: 내리실 임무가 있다면 언제든지 연락을 부탁드립니다.
A111: Text_MSG_diana_0_007 | D111: 5 | E111: 5 | H111: 이쪽이야말로 부탁할게.
A112: Text_MSG_diana_0_008 | D112: 5 | E112: 5 | H112: 그럼 대기하고 있겠습니다!
A113: Text_MSG_diana_1_001 | D113: 5 | E113: 5 | H113: 대장! 오늘 임무는 전부 끝마쳤습니다.
A114: Text_MSG_diana_1_002 | D114: 5 | E114: 5 | H114: 수고 많았어. 역시 다이아나는 성실하네!
A115: Text_MSG_diana_1_003 | D115: 5 | E115: 5 | H115: 군인으로서 당연히 해야 할 일을 한 것뿐입니다.
A116: Text_MSG_diana_1_004 | D116: 5 | E116: 5 | H116: 그나저나, 대장은 아직 업무가 남으신 겁니까?
... A181: Text_Date_diana_4_010 | D181: 5 | E181: 5 | H181: 물론 그땐 이미 늦으셨을지도 모르겠지만 말임다.
A182: #아이라스
A183: Text_MSG_iras_0_001 | D183: 5 | E183: 5 | H183: 아이아이, 아이라스야~
A184: Text_MSG_iras_0_002 | D184: 5 | E184: 5 | H184: 닉네임 아키텍트 씨? 잘 부탁해 ( ^ 0 ^ )
A185: Text_MSG_iras_0_003 | D185: 5 | E185: 5 | H185: 안녕. 닉네임 아니야.
A186: Text_MSG_iras_0_004 | D186: 5 | E186: 5 | H186: 진짜? 신기한 이름이네.
A187: Text_MSG_iras_0_005 | D187: 5 | E187: 5 | H187: 이름도 아니야.
A188: Text_MSG_iras_0_006 | D188: 5 | E188: 5 | H188: 그럼 뭐야, 비밀결사?
A189: Text_MSG_iras_0_007 | D189: 5 | E189: 5 | H189: 벌써 신기해.
A190: Text_MSG_iras_0_008 | D190: 5 | E190: 5 | H190: 특별히 맞팔은 바로 해 줄게.
...

Sheet Text.Instarseed
A1: Id | B1: Reference | C1: Tag | D1: #국문버전 | E1: #번안버전 | F1: #담당자 | G1: #Comment | H1: ko | I1: en | J1: ja | K1: zh_CN | L1: zh_TW
A2: *string | B2: string | C2: string | D2: ="#현재 버전 : "&'#번안관리인덱스'!$E$2 -> #현재 버전 : 18 | E2: ="#현재 버전 : "&'#번안관리인덱스'!$G$2 -> #현재 버전 : 5 | F2: #담당자 등록 | G2: # | H2: string | I2: string | J2: string | K2: string | L2: string
A3: client | B3: client | C3: client | D3: #국문버전 관리 | E3: #번안버전 관리 | F3: #특정 없는 경우 '공용' | G3: # | H3: client | I3: client | J3: client | K3: client | L3: client
A4: Post.Profil.Text_melissa | D4: 10 | E4: 5 | F4: 김승곤 | G4: 인스타시드 프로필 | H4: 주문은 디엠으로. 말도 안 되는 주문은 무시합니다. <color=#3f729b>#조형장인</color> <color=#3f729b>#피규어</color> <color=#3f729b>#선제시</color> 귀여운 건 진리야~~!! <color=#3f729b>#미소녀</color> <color=#3f729b>#가질수없다면만들겠어</color> 작업 중에 방해하면 가만 안 둠!
A5: Post.Profil.Text_lilian | D5: 10 | E5: 5 | F5: 김재송 | G5: 인스타시드 프로필 | H5: 플라즈마!! <color=#3f729b>#플라즈마</color>!! <color=#3f729b>#오토라타</color> 미사 시간 7:00, 14:00, 21:00 <color=#3f729b>#고해성사</color>는 세라펄사 님께 문의!
A6: Post.Profil.Text_daria | D6: 10 | E6: 5 | F6: 김재송 | G6: 인스타시드 프로필 | H6: 실드의 소대장입니다. 보드 게임 추천 환영. <color=#3f729b>#레이리얼실드</color> <color=#3f729b>#보드게임</color> <color=#3f729b>#GM가능</color> 다음 훈련 일정은 디엠으로 문의.
A7: Post.Profil.Text_snopril | D7: 10 | E7: 5 | F7: 김재송 | G7: 인스타시드 프로필 | H7: 프로필이란 걸 만들어 봤어요! <color=#3f729b>#스노프릴</color> <color=#3f729b>#인스타시드</color> <color=#3f729b>#이렇게하면되나요</color>? <color=#3f729b>#친구</color>를 잔뜩 만들 거예요! <color=#3f729b>#과자</color> <color=#3f729b>#빙하의나무</color>
A8: Post.Profil.Text_taina | D8: 10 | E8: 5 | F8: 김승곤 | G8: 인스타시드 프로필 | H8: 귀찮아. <color=#3f729b>#야옹</color> <color=#3f729b>#판게아</color>
A9: Post.Profil.Text_diana | D9: 10 | E9: 5 | F9: 김승곤 | G9: 인스타시드 프로필 | H9: 아르세즈의 <color=#3f729b>#신상패션카달로그</color> 구함다! 가지고 계신 분 있으면 디엠 주십시오! 같이 <color=#3f729b>#아르세즈</color>로 <color=#3f729b>#쇼핑</color> 가실 분도 환영!
A10: Post.Profil.Text_serapulsar | D10: 10 | E10: 5 | F10: 김재송 | G10: 인스타시드 프로필 | H10: 빛의 현신, <color=#3f729b>#과학</color>의 수호자, <color=#3f729b>#라인슈타인</color> 님의 대리인인 세라펄사입니다. <color=#3f729b>#미사</color> 요청은 디엠으로, <color=#3f729b>#레드시프트</color> 신고는 전용 통신망을 이용해 주세요.
A11: Post.Profil.Text_iras | D11: 10 | E11: 5 | F11: 김재송 | G11: 인스타시드 프로필 | H11: 스타넷 2위 ★☆★골드 스타★☆★ 스트리머 <color=#3f729b>#텔레파시매트릭스</color> <color=#3f729b>#구독후원</color>은 감사(^з^)-☆ <color=#3f729b>#스트리밍</color> 시간은 21:00~03:00 까지. <color=#3f729b>#편집자</color> 구함. 센스 있고 말 많이 하지 않는 프록시안 한정.
A12: Post.Profil.Text_ambrosia | D12: 10 | E12: 5 | F12: 김승곤 | G12: 인스타시드 프로필 | H12: 신은 가장 <color=#3f729b>#강한</color> <color=#3f729b>#포병</color>이 있는 자들의 편이다. <color=#3f729b>#스팅스</color> <color=#3f729b>#레이리얼아스날</color> <color=#3f729b>#소장</color> <color=#3f729b>#포병</color> <color=#3f729b>#전쟁</color> <color=#3f729b>#전투</color> 승리를 맛보고 싶은 프록시안이라면 지금 바로 입대하라! <color=#3f729b>#입대신청</color> <color=#3f729b>#병사모집중</color>
A13: Post.Profil.Text_mea | D13: 10 | E13: 5 | F13: 김재송 | G13: 인스타시드 프로필 | H13: 육지 <color=#3f729b>#친구</color>를 만들고 싶어요…. <color=#3f729b>#테라리움</color>을 하고 있어서, 같은 <color=#3f729b>#취미</color>를 가지신 분과 이야기하고 싶어요. 아스니아의 <color=#3f729b>#아쿠아리움</color>도 관리하고 있으니, 보고 싶은 물고기가 있으면 글 남겨 주세요….
A14: Post.Profil.Text_rachel | D14: 10 | E14: 5 | F14: 김승곤 | G14: 인스타시드 프로필 | H14: 더 강해지기 위하여. <color=#3f729b>#훈련</color> <color=#3f729b>#트레이닝</color> 나를 무너뜨리지 못하는 <color=#3f729b>#시련</color>은 나를 더 강하게 만든다!!
A15: Post.Profil.Text_isabella | D15: 10 | E15: 5 | F15: 김재송 | G15: 인스타시드 프로필 | H15: 레이리얼 알터의 소대장. <color=#3f729b>#임무</color> 요청이나 대련 요청은 디엠으로. 다만 <color=#3f729b>#결과</color>가 따른다는 걸 명심.
... A1103: Post.Battle.Reply.Text_0018_02_02 | D1103: 11 | E1103: 5 | F1103: 김재송 | G1103: 인스타시드 댓글 (전투 참여) | H1103: 아이렌 님은 이전 문명에 대해 공부가 더 필요하시겠군요.
A1104: #인스타시드 영상 자막 | B1104: #자막 | C1104: #자막 | D1104: #자막 | E1104: #자막 | F1104: #자막 | G1104: #자막 | H1104: #자막 | I1104: #자막 | J1104: #자막 | K1104: #자막 | L1104: #자막
A1105: Post.Unlock.Sub.Text_0001_01 | D1105: 11 | E1105: 5 | F1105: 김승곤 | G1105: 세라펄사 영상 자막 | H1105: 라인슈타인이시여, 당신의 가르침에 따라 이 물질에 과학의 축복을 부여하노니, | J1105: ラインシュタイン様、あなたの教えに従い、この物質に科学の祝福を与えます。
A1106: Post.Unlock.Sub.Text_0001_02 | D1106: 11 | E1106: 5 | F1106: 김승곤 | G1106: 세라펄사 영상 자막 | H1106: 구성 물질은 단백질, 수분, 지방, 미네랄과 식이섬유, 그리고 탄수화물! | J1106: 構成物質はたんぱく質、水分、脂肪、ミネラルと食物繊維、そして炭水化物！
A1107: Post.Unlock.Sub.Text_0001_03 | D1107: 11 | E1107: 5 | F1107: 김승곤 | G1107: 세라펄사 영상 자막 | H1107: 맛있어져라~~~!! | J1107: 美味しくなーれ！
A1108: Post.Unlock.Sub.Text_0001_04 | D1108: 11 | E1108: 5 | F1108: 김승곤 | G1108: 세라펄사 영상 자막 | H1108: 모에모에 큥~! | J1108: 萌え萌えキュン！
A1109: Post.Bace.Sub.Text_0801_01 | D1109: 11 | E1109: 5 | F1109: 김재송 | G1109: 아이라스 영상 자막 | H1109: 「오늘 컨텐츠는… 교환 낙서장이네.」
A1110: Post.Bace.Sub.Text_0801_02 | D1110: 11 | E1110: 5 | F1110: 김재송 | G1110: 아이라스 영상 자막 | H1110: 「∑(º o º） 바… 뭐 하는 거야. 난 고양이가 아니라구.」
A1111: Post.Bace.Sub.Text_0801_03 | D1111: 11 | E1111: 5 | F1111: 김재송 | G1111: 아이라스 영상 자막 | H1111: 「야~~~옹(ΦωΦ). 됐어?」
A1112: Post.Pickup.Sub.Text_0003_01 | D1112: 11 | E1112: 5 | F1112: 김승곤 | G1112: 카나타 영상 자막 | H1112: 발명부 부장의 실력을 똑똑히 보여주겠어요. | J1112: 発明部長の実力をしっかり見せてあげます。
A1113: Post.Pickup.Sub.Text_0003_02 | D1113: 11 | E1113: 5 | F1113: 김승곤 | G1113: 카나타 영상 자막 | H1113: 하나… 둘… 셋… 넷! | J1113: 1…2…3…4！
A1114: Post.Pickup.Sub.Text_0003_03 | D1114: 11 | E1114: 5 | F1114: 김승곤 | G1114: 카나타 영상 자막 | H1114: 이걸로, 버킷리스트 하나는 완료네요. | J1114: これでバケットリストの一つが叶いました。
A1115: Post.Bace.Sub.Text_0501_01 | D1115: 11 | E1115: 5 | F1115: 김승곤 | G1115: 유나 영상 자막 | H1115: 수련의 일부라고 생각하면… | J1115: 修練の一部だと思えば…
A1116: Post.Bace.Sub.Text_0501_02 | D1116: 11 | E1116: 5 | F1116: 김승곤 | G1116: 유나 영상 자막 | H1116: 그렇게 어려운 건 아니네. | J1116: そんなに難しくはありませんね。
A1117: Post.Bace.Sub.Text_0501_03 | D1117: 11 | E1117: 5 | F1117: 김승곤 | G1117: 유나 영상 자막 | H1117: 핫, 차, 핫, 차. | J1117: ふっ、はっ、ふっ、はっ。
A1118: Post.Bace.Sub.Text_0301_01 | D1118: 11 | E1118: 5 | F1118: 김승곤 | G1118: 라일라 영상 자막 | H1118: 떴~다 떴~다 비행기~ | J1118: メ~リ~ーさん~の~ひ~つ~じ
A1119: Post.Bace.Sub.Text_0301_02 | D1119: 11 | E1119: 5 | F1119: 김승곤 | G1119: 라일라 영상 자막 | H1119: 날아라~ 날~~아라~~ | J1119: メ~エ~~メ~エ~~ ひ~つ~じ
A1120: Post.Bace.Sub.Text_0301_03 | D1120: 11 | E1120: 5 | F1120: 김승곤 | G1120: 라일라 영상 자막 | H1120: 높~~ 이 높~~ 이 날아라~~ | J1120: メ~リ~ーさん~の~ひつじ~
A1121: Post.Bace.Sub.Text_0301_04 | D1121: 11 | E1121: 5 | F1121: 김승곤 | G1121: 라일라 영상 자막 | H1121: 우리~~~ 비~~~ 행~~~ 기~~~~ | J1121: ま~~っし~ろ~ね
A1122: Post.Bace.Sub.Text_0301_05 | D1122: 11 | E1122: 5 | F1122: 김승곤 | G1122: 라일라 영상 자막 | H1122: Yeah~~~~! | J1122: イエーーーーイ！
A1123: Post.Unlock.Sub.Text_0004_01 | D1123: 11 | E1123: 5 | F1123: 김승곤 | G1123: 오로라 영상 자막 | H1123: 하나… 둘… 셋… 넷…! | J1123: いち…に…さん…し…！
... A1127: Post.Unlock.Sub.Text_0004_05 | D1127: 11 | E1127: 5 | F1127: 김승곤 | G1127: 오로라 영상 자막 | H1127: 마무리 동작을 하면~~ 끝! | J1127: こうして仕上げると…終わり！
A1128: Post.Pickup.Sub.Text_0002_01 | D1128: 11 | E1128: 5 | F1128: 김재송 | G1128: 유리지아 영상 자막 | H1128: 여기를… 이렇게… 하공…
A1129: Post.Pickup.Sub.Text_0002_02 | D1129: 11 | E1129: 5 | F1129: 김재송 | G1129: 유리지아 영상 자막 | H1129: 아무리 부탁해도 절~~대로 안 빌려줄 거지롱!
A1130: Post.Pickup.Sub.Text_0002_03 | D1130: 11 | E1130: 5 | F1130: 김재송 | G1130: 유리지아 영상 자막 | H1130: 간신히 예구한 풀 커버 케이스라공~
...

Sheet Text.Subtitle
A1: Id | B1: Reference | C1: Tag | D1: #국문버전 | E1: #번안버전 | F1: #담당자 | G1: #Comment | H1: ko | I1: en | J1: ja | K1: zh_CN | L1: zh_TW
A2: *string | B2: string | C2: string | D2: ="#현재 버전 : "&'#번안관리인덱스'!$E$2 -> #현재 버전 : 18 | E2: ="#현재 버전 : "&'#번안관리인덱스'!$G$2 -> #현재 버전 : 5 | F2: #담당자 등록 | G2: # | H2: string | I2: string | J2: string | K2: string | L2: string
A3: client | B3: client | C3: client | D3: #국문버전 관리 | E3: #번안버전 관리 | F3: #특정 없는 경우 '공용' | G3: # | H3: client | I3: client | J3: client | K3: client | L3: client
A4: PV_001 | D4: 11 | E4: 5 | F4: 김재송 | H4: 지금 네 안에서 | I4: Now within you | J4: 今君の中 | K4: 在你心海深处 | L4: 在你心海深處
A5: PV_002 | D5: 11 | E5: 5 | F5: 김재송 | H5: 빛나는 Brave New World | I5: It’s a shining Brave New World | J5: 輝くBrave New World | K5: 璀璨燃烧的Brave New World | L5: 璀璨燃燒的Brave New World
A6: PV_003 | D6: 11 | E6: 5 | F6: 김재송 | H6: 사랑이건 꿈이건 | I6: Things like love and dreams | J6: 愛だとか夢だとか | K6: 爱的甜涩，梦想的朦胧 | L6: 愛的甜澀，夢想的朦朧
A7: PV_004 | D7: 11 | E7: 5 | F7: 김재송 | H7: 실체가 없는 불확실한 것 | I7: Are uncertain, formless entities | J7: 形のない不確かなものだから | K7: 如幽灵般的漫游 | L7: 如幽靈般的漫遊
A8: PV_005 | D8: 11 | E8: 5 | F8: 김재송 | H8: 너는 아직 | I8: That’s why you’re are still | J8: 君はまだ | K8: 你在追寻 | L8: 你在追尋
A9: PV_006 | D9: 11 | E9: 5 | F9: 김재송 | H9: 그것을 찾는 도중이야 | I9: In the midst of finding them | J9: それを見つけられない | K9: 找寻未果 | L9: 找尋未果
A10: PV_007 | D10: 11 | E10: 5 | F10: 김재송 | H10: 우리들은 반복해 | I10: We just keep repeating | J10: 僕たちはくり返す | K10: 我们在重复的轮回中 | L10: 我們在重複的輪迴中
A11: PV_008 | D11: 11 | E11: 5 | F11: 김재송 | H11: 상처입히며 상처받으며 | I11: Hurting and getting hurt | J11: 傷つけて傷ついて | K11: 施痛，受伤，相互割伤 | L11: 施痛，受傷，相互割傷
A12: PV_009 | D12: 11 | E12: 5 | F12: 김재송 | H12: 아픔이든 슬픔이든 | I12: Whether it's pain or sadness | J12: 痛みとか切なさを | K12: 痛苦的煎熬，悲伤的哀嚎 | L12: 痛苦的煎熬，悲傷的哀嚎
A13: PV_010 | D13: 11 | E13: 5 | F13: 김재송 | H13: 조금씩 알아가는 거야 | I13: Bit by bit, we’ll get to know | J13: 少しずつ知っていくんだ | K13: 我们慢慢体悟，在理解中成长 | L13: 我們慢慢體悟，在理解中成長
A14: PV_011 | D14: 11 | E14: 5 | F14: 김재송 | H14: Round and Round 도는 거야 | I14: Round and round, it starts to turn | J14: Round and Round 廻り出す | K14: Round and Round，生生不息的旋转 | L14: Round and Round，生生不息的旋轉
A15: PV_012 | D15: 11 | E15: 5 | F15: 김재송 | H15: 새로운 세계로 향하는 문을 열어 | I15: Open the door to a new world | J15: あたらしい世界への扉開いてく | K15: 向着新世界的大门，我们勇往直前 | L15: 向著新世界的大門，我們勇往直前
... A27: PV_024 | D27: 11 | E27: 5 | F27: 김재송 | H27: 빛나는 Brave New World | I27: It’s a shining Brave New World | J27: 輝くBrave New World | K27: 璀璨闪耀，那是我们的Brave New World | L27: 璀璨閃耀，那是我們的Brave New World
A28: intro_temp_001 | D28: 11 | E28: 5 | F28: 김재송 | H28: 드디어…… 찾아낼 수 있었어요…….
A29: intro_temp_002 | D29: 11 | E29: 5 | F29: 김재송 | H29: 무수한 연산 끝에 도달한 하나뿐인 미래…….
A30: intro_temp_003 | D30: 11 | E30: 5 | F30: 김재송 | H30: 부디…… 그 희망의 씨앗을 저희에게 보여주세요.
A31: intro_temp_004 | D31: 11 | E31: 5 | F31: 김재송 | H31: 제1차 아스니아 프로젝트의 결과, 세븐 테마즈와 레드시프트의 AI가
A32: intro_temp_005 | D32: 11 | E32: 5 | F32: 김재송 | H32: 미지의 신물질 스타시드를 발견했다는 소식입니다.
A33: intro_temp_006 | D33: 11 | E33: 5 | F33: 김재송 | H33: 이들 컨소시엄에 따르면 스타시드는
A34: intro_temp_007 | D34: 11 | E34: 5 | F34: 김재송 | H34: 인류 문명의 발전을 몇 세기나 앞당길 수 있는 획기적인 물질로,
A35: intro_temp_008 | D35: 11 | E35: 5 | F35: 김재송 | H35: 이로 인해 인류는 새로운 유토피아를 맞이할 수 있다고 합니다.
A36: intro_temp_009 | D36: 11 | E36: 5 | F36: 김재송 | H36: …아스니아 플랫폼은 스타시드의 힘으로,
