Workbook

Sheet MissionCategory
A1: Id | B1: Type | C1: Condition | D1: OnlyOnReset | E1: Reset | F1: DateRangeCondition | G1: TabType | H1: NotReceivedMail | I1: Name | J1: Icon | K1: RewardCondition | L1: UnlockCondition | M1: VisibleCondition | N1: ExpItem | O1: Resource | P1: ShowPointReward | Q1: BannerImage | R1: BannerTitle | S1: BannerSubtitle
A2: *long | B2: MissionCategoryType | C2: dsl | D2: bool? | E2: $Reset? | F2: dsl? | G2: MissionTabType? | H2: string | I2: $Text | J2: string | K2: [dsl] | L2: [dsl] | M2: [dsl] | N2: $ItemCase? | O2: string? | P2: bool? | Q2: string? | R2: string? | S2: string?
A3: common | B3: common | C3: common | D3: common | E3: common | F3: common | G3: client | H3: common | I3: client | J3: client | K3: common | L3: common | M3: common | N3: client | O3: client | P3: client | Q3: client | R3: client | S3: client
A4: 2200000000000 | B4: Daily | C4: LevelRange(1,200) | E4: SYSTEM_DAILY_RESET | G4: Mission | I4: Mission.Group.Name.Daily | J4: tab_mission_daily | N4: 1040701911 | P4: TRUE
A5: 2200000000001 | B5: DailyPoint | C5: LevelRange(1,200) | E5: SYSTEM_DAILY_RESET | G5: MissionPoint | I5: Mission.Group.Name.DailyPoint | J5: tab_mission_daily
A6: 2200000000002 | B6: Weekly | C6: LevelRange(1,200) | E6: SYSTEM_WEEKLY_RESET | G6: Mission | I6: Mission.Group.Name.Weekly | J6: tab_mission_weekly | N6: 1040701912 | P6: TRUE
A7: 2200000000003 | B7: WeeklyPoint | C7: LevelRange(1,200) | E7: SYSTEM_WEEKLY_RESET | G7: MissionPoint | I7: Mission.Group.Name.WeeklyPoint | J7: tab_mission_daily
A8: 2200000000004 | B8: Achievement | C8: LevelRange(1,200) | I8: Mission.Group.Name.Achievement | J8: tab_mission_daily
A9: 2200000000005 | B9: MainScenario | C9: LevelRange(1,200) | G9: Mission | I9: Mission.Group.Name.Main | J9: tab_mission_main
A10: 2200000000009 | B10: Guide | C10: LevelRange(1,200) | G10: Guide | I10: Mission.Group.Name.Guide | J10: tab_mission_daily
A11: 2200000000010 | B11: Special | C11: LevelRange(1,200) | G11: Special | I11: Mission.Group.Name.Event.Popup.1 | J11: tab_mission_daily
A12: 2200000000013 | B12: StarRecord | C12: LevelRange(1,200) | G12: StarRecord | I12: Record.01 | J12: tab_mission_daily | P12: TRUE
A13: 2200000000014 | B13: StarRecord | C13: StarRecord(3040200001) | G13: StarRecord | I13: Record.03 | J13: tab_mission_daily | P13: TRUE
A14: 2200000000015 | B14: Event7Days | C14: LevelRange(1,200) | F14: StaticDateRange(2021-12-01 ~ 2077-12-31) | G14: Event7Days | I14: Mission.Group.Name.7Days | J14: tab_mission_daily | O14: event_newuser
A15: 2200000000016 | B15: Event7Days | C15: LevelRange(1,200) | F15: StaticDateRange(2021-12-01 ~ 2077-12-31) | G15: Event7Days | I15: Mission.Group.Name.7Days | J15: tab_mission_daily | K15: MissionElapsed(2200000000015, 1, Const:Server:DefaultResetTime)
A16: 2200000000017 | B16: Event7Days | C16: LevelRange(1,200) | F16: StaticDateRange(2021-12-01 ~ 2077-12-31) | G16: Event7Days | I16: Mission.Group.Name.7Days | J16: tab_mission_daily | K16: MissionElapsed(2200000000015, 2, Const:Server:DefaultResetTime)
A17: 2200000000018 | B17: Event7Days | C17: LevelRange(1,200) | F17: StaticDateRange(2021-12-01 ~ 2077-12-31) | G17: Event7Days | I17: Mission.Group.Name.7Days | J17: tab_mission_daily | K17: MissionElapsed(2200000000015, 3, Const:Server:DefaultResetTime)
A18: 2200000000019 | B18: Event7Days | C18: LevelRange(1,200) | F18: StaticDateRange(2021-12-01 ~ 2077-12-31) | G18: Event7Days | I18: Mission.Group.Name.7Days | J18: tab_mission_daily | K18: MissionElapsed(2200000000015, 4, Const:Server:DefaultResetTime)
A19: 2200000000020 | B19: Event7Days | C19: LevelRange(1,200) | F19: StaticDateRange(2021-12-01 ~ 2077-12-31) | G19: Event7Days | I19: Mission.Group.Name.7Days | J19: tab_mission_daily | K19: MissionElapsed(2200000000015, 5, Const:Server:DefaultResetTime)
A20: 2200000000021 | B20: Event7Days | C20: LevelRange(1,200) | F20: StaticDateRange(2021-12-01 ~ 2077-12-31) | G20: Event7Days | I20: Mission.Group.Name.7Days | J20: tab_mission_daily | K20: MissionElapsed(2200000000015, 6, Const:Server:DefaultResetTime)
A21: 2200000000022 | B21: Event7Days | C21: LevelRange(1,200) | F21: StaticDateRange(2021-12-01 ~ 2077-12-31) | G21: MissionPoint | I21: Mission.Group.Name.7Days | J21: tab_mission_daily
A22: 2200000000023 | B22: Event7Days | C22: LevelRange(1,200) | F22: StaticDateRange(2021-12-01 ~ 2077-12-31) | G22: MissionPoint | I22: Mission.Group.Name.7Days | J22: tab_mission_daily | K22: MissionElapsed(2200000000015, 1, Const:Server:DefaultResetTime)
A23: 2200000000024 | B23: Event7Days | C23: LevelRange(1,200) | F23: StaticDateRange(2021-12-01 ~ 2077-12-31) | G23: MissionPoint | I23: Mission.Group.Name.7Days | J23: tab_mission_daily | K23: MissionElapsed(2200000000015, 2, Const:Server:DefaultResetTime)
A24: 2200000000025 | B24: Event7Days | C24: LevelRange(1,200) | F24: StaticDateRange(2021-12-01 ~ 2077-12-31) | G24: MissionPoint | I24: Mission.Group.Name.7Days | J24: tab_mission_daily | K24: MissionElapsed(2200000000015, 3, Const:Server:DefaultResetTime)
A25: 2200000000026 | B25: Event7Days | C25: LevelRange(1,200) | F25: StaticDateRange(2021-12-01 ~ 2077-12-31) | G25: MissionPoint | I25: Mission.Group.Name.7Days | J25: tab_mission_daily | K25: MissionElapsed(2200000000015, 4, Const:Server:DefaultResetTime)
A26: 2200000000027 | B26: Event7Days | C26: LevelRange(1,200) | F26: StaticDateRange(2021-12-01 ~ 2077-12-31) | G26: MissionPoint | I26: Mission.Group.Name.7Days | J26: tab_mission_daily | K26: MissionElapsed(2200000000015, 5, Const:Server:DefaultResetTime)
A27: 2200000000028 | B27: Event7Days | C27: LevelRange(1,200) | F27: StaticDateRange(2021-12-01 ~ 2077-12-31) | G27: MissionPoint | I27: Mission.Group.Name.7Days | J27: tab_mission_daily | K27: MissionElapsed(2200000000015, 6, Const:Server:DefaultResetTime)
A28: 2200000000029 | B28: StarRecord | C28: LevelRange(1,200) | E28: SYSTEM_MONTHLY_RESET | G28: StarRecord | I28: Record.02 | J28: tab_mission_daily | P28: TRUE
A29: 2200000000037 | B29: Recommend | C29: LevelRange(1,200) | G29: Recommend | I29: Mission.Group.Name.Recommend | J29: tab_mission_daily | K29: StageClear(스테이지16) | L29: StageClear(스테이지16) | O29: NPC.Marillight
A30: 2200000000038 | B30: Recommend | C30: LevelRange(1,200) | G30: Recommend | I30: Mission.Group.Name.Recommend | J30: tab_mission_daily | K30: StageClear(스테이지92) | L30: StageClear(스테이지92) | O30: NPC.Marillight
A31: 2200000000039 | B31: Recommend | C31: LevelRange(1,200) | G31: Recommend | I31: Mission.Group.Name.Recommend | J31: tab_mission_daily | K31: StageClear(스테이지212) | L31: StageClear(스테이지212) | O31: NPC.Marillight
A32: 2200000000040 | B32: Recommend | C32: LevelRange(1,200) | G32: Recommend | I32: Mission.Group.Name.Recommend | J32: tab_mission_daily | K32: StageClear(스테이지317) | L32: StageClear(스테이지317) | O32: NPC.Marillight
A33: 2200000000041 | B33: Recommend | C33: LevelRange(1,200) | G33: MissionPoint | I33: Mission.Group.Name.Recommend.S1 | J33: tab_mission_daily | K33: StageClear(스테이지16) | L33: StageClear(스테이지16) | O33: NPC.Marillight
A34: 2200000000042 | B34: Recommend | C34: LevelRange(1,200) | G34: MissionPoint | I34: Mission.Group.Name.Recommend.S2 | J34: tab_mission_daily | K34: StageClear(스테이지36) | L34: StageClear(스테이지36) | O34: NPC.Marillight
A35: 2200000000043 | B35: Recommend | C35: LevelRange(1,200) | G35: MissionPoint | I35: Mission.Group.Name.Recommend.S3 | J35: tab_mission_daily | K35: StageClear(스테이지61) | L35: StageClear(스테이지61) | O35: NPC.Marillight
A36: 2200000000044 | B36: Recommend | C36: LevelRange(1,200) | G36: MissionPoint | I36: Mission.Group.Name.Recommend.S4 | J36: tab_mission_daily | K36: StageClear(스테이지91) | L36: StageClear(스테이지91) | O36: NPC.Marillight
A37: 2200000000045 | B37: Purchase | C37: LevelRange(1,200) | E37: SYSTEM_DAILY_RESET | G37: Event | I37: Mission.Group.Purchase | J37: tab_mission_daily
A38: 2200000000046 | B38: StarRecord | C38: ContentsUnlock(EventStory) | F38: ManagedDateRange(EventSchedule.Id.Reward) | G38: StarRecord | I38: Record.Event | J38: tab_mission_daily | P38: TRUE
A39: 2200000000047 | B39: StarRecord | C39: StarRecord(3040200002) | G39: StarRecord | I39: Record.03 | J39: tab_mission_daily | P39: TRUE
A40: 2200000000048 | B40: StarRecord | C40: StarRecord(3040200003) | G40: StarRecord | I40: Record.03 | J40: tab_mission_daily | P40: TRUE
...

Sheet Statistics
A1: #ID | B1: #타입 이름 | C1: #체크 타입 | D1: #업데이트 타입 | E1: #GoalTarget용법 주석 | F1: #QuickMove 주석
A2: Id | B2: Type | C2: RecordType | D2: UpdateType | E2: # | F2: #
A3: string | B3: *StatisticsType | C3: StatisticsRecordType | D3: StatisticsUpdateType | E3: # | F3: #
A4: common | B4: common | C4: common | D4: common | E4: # | F4: #
A5: 가챠진행 | B5: TryGacha | C5: Always | D5: Increasement
A6: 가한피해량 | B6: InflictedDamage | C6: Always | D6: Increasement
A7: 검색 - 프록시안 시도 | B7: TrySelectiveGacha | C7: Always | D7: Increasement
A8: 검색 - 프록시안 확정 | B8: ConfirmSelectiveGacha | C8: Always | D8: Increasement
A9: 계정레벨 | B9: AcountLv | C9: Always | D9: Max
A10: 교류 대성공 | B10: CommunicationCritical | C10: Always | D10: Increasement
A11: 교류 완료 | B11: CommunicationComplete | C11: Always | D11: Increasement
A12: 길드가입 | B12: GuildJoin | C12: Always | D12: Increasement | F12: QuickMove0260
A13: 길드개인기여도 | B13: GuildPlayerExp | C13: Always | D13: Increasement | F13: QuickMove0260
A14: 길드기부 | B14: GuildDonation | C14: Always | D14: Increasement | F14: QuickMove.GuildSupport
A15: 길드소식지 | B15: GuildNewsCount | C15: Always | D15: Increasement | F15: QuickMove0260
A16: 길드출석체크 | B16: GuildAttendance | C16: Always | D16: Increasement | F16: QuickMove0260
A17: 누적길드레벨업 | B17: GuildLevelUpCount | C17: Always | D17: Increasement | F17: QuickMove0260
A18: 누적로그인 | B18: Login | C18: DailyOnce | D18: Increasement
A19: 대표캐릭터변경 | B19: ProfileCharacterChange | C19: Always | D19: Increasement
A20: 도미니언 레벨 그룹 완료 | B20: DominionLevelGroupClear | C20: Always | D20: Increasement | F20: QuickMove.Dominion
A21: 도미니언 에어리어 오픈 | B21: DominionAreaOpen | C21: Always | D21: Max | F21: QuickMove.Dominion
A22: 동시길드소식지 | B22: GuildNewsTriple | C22: Always | D22: Increasement | F22: QuickMove0260
A23: 레더 점수 달성 | B23: LadderScore | C23: Always | D23: Max | E23: LadderId : (ID) Proxyan | F23: QuickMove0680
A24: 미션포인트 | B24: MissionPoint | C24: Always | D24: Increasement | E24: MissionPointType : (미션 포인트 ID)
A25: 빠른작전보상획득 | B25: IdleBattleFastReward | C25: Always | D25: Increasement
A26: 상점구매 | B26: ShopPurchase | C26: Always | D26: Increasement | E26: ShopCategory : (상점 ID) [2600000000000:기본] | F26: QuickMove.Starbeat.Shop
A27: 상품 구매 포인트 | B27: BuyPoint | C27: Always | D27: Increasement
A28: 스킬개방 | B28: OpenSkill | C28: Always | D28: Increasement
A29: 스킬레벨업 | B29: SkillLvUp | C29: Always | D29: Increasement | F29: QuickMove0420
A30: 스타시드 건물에 캐릭터 배치 | B30: ArrangeStarseedChar | C30: Always | D30: Increasement
A31: 스타시드 시설 강화 완료 | B31: CompleteFacilityUpgrade | C31: Always | D31: Increasement
A32: 스테이지클리어 | B32: StageClear | C32: Always | D32: Increasement | E32: StageId : 스테이지(숫자) | F32: QuickMove0010
A33: 스테이지플레이 | B33: StagePlay | C33: Always | D33: Increasement | E33: ContentsType : GuildOperation | F33: QuickMove.GuildOperation
A34: 스토리열람 | B34: ReadStory | C34: Always | D34: Increasement
A35: 시드연구 | B35: ResearchSeed | C35: Always | D35: Increasement | F35: QuickMove0480
A36: 시민 의뢰 | B36: AsniaRequestComplete | C36: Always | D36: Increasement
A37: 시민 의뢰(교환) | B37: AsniaRequestExchange | C37: Always | D37: Increasement
A38: 시민 의뢰(선물) | B38: AsniaRequestGift | C38: Always | D38: Increasement
A39: 아레나승리 | B39: ArenaVictory | C39: Always | D39: Increasement | F39: QuickMove.Arena
A40: 아레나플레이 | B40: ArenaPlay | C40: Always | D40: Increasement | F40: QuickMove.Arena
...

Sheet MissionCategory.Newbie
A1: Id | B1: Type | C1: Condition | D1: OnlyOnReset | E1: Reset | F1: DateRangeCondition | G1: TabType | H1: NotReceivedMail | I1: Name | J1: Icon | K1: RewardCondition | L1: UnlockCondition | M1: VisibleCondition | N1: ExpItem | O1: Resource | P1: ShowPointReward | Q1: BannerImage | R1: BannerTitle | S1: BannerSubtitle
A2: *long | B2: MissionCategoryType | C2: dsl | D2: bool? | E2: $Reset? | F2: dsl? | G2: MissionTabType? | H2: string | I2: $Text | J2: string | K2: [dsl] | L2: [dsl] | M2: [dsl] | N2: $ItemCase? | O2: string? | P2: bool? | Q2: string? | R2: string? | S2: string?
A3: common | B3: common | C3: common | D3: common | E3: common | F3: common | G3: client | H3: common | I3: client | J3: client | K3: common | L3: common | M3: common | N3: client | O3: client | P3: client | Q3: client | R3: client | S3: client
A4: 2291000000001 | B4: Event | C4: FirstLoginAfter(2024-05-09) | F4: DynamicDateRange(14 00:00:00) | G4: Mission | I4: Mission.Group.Name.Event.Newbie | J4: tab_event_newbie | M4: FirstLoginAfter(2024-04-19) | Q4: bg_shop_stepgrowth_proxian.png | R4: Mission.Growth.Topbanner.Title | S4: Mission.Growth.Topbanner.Subtitle

Sheet MissionCase.Newbie
A1: Group | B1: #주석 | C1: Category | D1: NoticeProgress | E1: NoticeComplete | F1: Condition | G1: Ignore | H1: Step | I1: Name | J1: Desc | K1: Continuous | L1: MissionGoal | M1: GoalTarget | N1: GoalCount | O1: Reward | P1: QuickMove
A2: *long | B2: # | C2: $MissionCategory | D2: [dsl] | E2: bool | F2: [dsl] | G2: bool? | H2: int | I2: $Text | J2: $Text | K2: MissionChainingType | L2: StatisticsType | M2: {MissionGoalTargetType : string} | N2: int | O2: [dsl] | P2: $QuickMove?
A3: common | B3: # | C3: common | D3: server | E3: client | F3: common | G3: common | H3: common | I3: client | J3: client | K3: common | L3: common | M3: common | N3: common | O3: common | P3: client
A4: 2901000000001 | B4: 2섹터 클리어 | C4: 2291000000001 | D4: Always() | E4: TRUE
H5: 1 | I5: MSG.Mission.Name.Newbie.Sector2 | J5: MSG.Mission.Desc.Newbie.Sector2 | K5: Always | L5: StageClear | M5: ContentsType : Scenario | N5: 36 | O5: Item(1040603084, 1) | P5: QuickMove.MainBattle
A6: 2901000000002 | B6: 프록시안 SSR1 등급 달성 | C6: 2291000000001 | D6: Always() | E6: TRUE
H7: 1 | I7: MSG.Mission.Name.Promotion.SSR1 | J7: MSG.Mission.Desc.Promotion.SSR1 | K7: Always | L7: CharacterGradeReached | M7: Grade : SSR1 | N7: 1 | O7: Item(1040501001, 5) | P7: QuickMove.Gacha
A8: 2901000000003 | B8: 프록시안 UR 등급 달성 | C8: 2291000000001 | D8: Always() | E8: TRUE
H9: 1 | I9: MSG.Mission.Name.Promotion.UR | J9: MSG.Mission.Desc.Promotion.UR | K9: Always | L9: CharacterGradeReached | M9: Grade : UR | N9: 1 | O9: Item(1040501001, 10) | P9: QuickMove.Gacha
A10: 2901000000004 | B10: 프록시안 UR1 등급 달성 | C10: 2291000000001 | D10: Always() | E10: TRUE
H11: 1 | I11: MSG.Mission.Name.Promotion.UR1 | J11: MSG.Mission.Desc.Promotion.UR1 | K11: Always | L11: CharacterGradeReached | M11: Grade : UR1 | N11: 1 | O11: Item(1040603019, 1) | P11: QuickMove.Gacha
A12: 2901000000005 | B12: 프록시안 MR 등급 달성 | C12: 2291000000001 | D12: Always() | E12: TRUE
H13: 1 | I13: MSG.Mission.Name.Promotion.MR | J13: MSG.Mission.Desc.Promotion.MR | K13: Always | L13: CharacterGradeReached | M13: Grade : MR | N13: 1 | O13: Item(1040501001, 20) | P13: QuickMove.Gacha
A14: 2901000000006 | B14: 프록시안 MR1 등급 달성 | C14: 2291000000001 | D14: Always() | E14: TRUE
H15: 1 | I15: MSG.Mission.Name.Promotion.MR1 | J15: MSG.Mission.Desc.Promotion.MR1 | K15: Always | L15: CharacterGradeReached | M15: Grade : MR1 | N15: 1 | O15: Item(1040501001, 30) | P15: QuickMove.Gacha
A16: 2901000000007 | B16: 프록시안 LR 등급 달성 | C16: 2291000000001 | D16: Always() | E16: TRUE
H17: 1 | I17: MSG.Mission.Name.Promotion.LR | J17: MSG.Mission.Desc.Promotion.LR | K17: Always | L17: CharacterGradeReached | M17: Grade : LR | N17: 1 | O17: Item(1040102001, 5000) | P17: QuickMove.Gacha

Sheet #Mission.Set
A1: 가챠진행 | B1: TryGacha
A2: 검색 - 프록시안 | B2: TryGacha | C2: GachaGroup : Character | D2: QuickMove.Gacha.Character
A3: 검색 - 플러그인 | B3: TryGacha | C3: GachaGroup : Plugin | D3: QuickMove.Gacha
A4: 가한피해량 | B4: InflictedDamage
A5: 검색 - 프록시안 시도 | B5: TrySelectiveGacha
A6: 검색 - 프록시안 확정 | B6: ConfirmSelectiveGacha
A7: 계정레벨 | B7: AcountLv
A8: 교류 대성공 | B8: CommunicationCritical
A9: 교류 완료 | B9: CommunicationComplete
A10: 길드가입 | B10: GuildJoin | D10: QuickMove0260
A11: 길드개인기여도 | B11: GuildPlayerExp | D11: QuickMove0260
A12: 길드기부 | B12: GuildDonation | D12: QuickMove.GuildSupport
A13: 길드소식지 | B13: GuildNewsCount | D13: QuickMove0260
A14: 길드출석체크 | B14: GuildAttendance | D14: QuickMove0260
A15: 누적길드레벨업 | B15: GuildLevelUpCount | D15: QuickMove0260
A16: 누적로그인 | B16: Login
A17: 대표캐릭터변경 | B17: ProfileCharacterChange
A18: 도미니언 레벨 그룹 완료 | B18: DominionLevelGroupClear | D18: QuickMove.Dominion
A19: 도미니언 에어리어 오픈 | B19: DominionAreaOpen | D19: QuickMove.Dominion
A20: 동시길드소식지 | B20: GuildNewsTriple | D20: QuickMove0260
A21: 레더 점수 달성 | B21: LadderScore | D21: QuickMove0680
A22: 미션포인트 | B22: MissionPoint
A23: 미션포인트 - 일일미션 | B23: MissionPoint | C23: MissionPointType : Daily | D23: QuickMove.DailyMission
A24: 미션포인트 - 주간미션 | B24: MissionPoint | C24: MissionPointType : Weekly | D24: QuickMove.WeeklyMission
A25: 빠른작전보상획득 | B25: IdleBattleFastReward
A26: 상점구매 | B26: ShopPurchase
A27: 상품 구매 포인트 | B27: BuyPoint
A28: 스킬개방 | B28: OpenSkill
A29: 스킬레벨업 | B29: SkillLvUp | D29: QuickMove0420
A30: 스타시드 건물에 캐릭터 배치 | B30: ArrangeStarseedChar
A31: 스타시드 시설 강화 완료 | B31: CompleteFacilityUpgrade
A32: 스테이지클리어 | B32: StageClear
A33: 스테이지클리어 - 물자탐색 | B33: StageClear | C33: ContentsType : Raid | D33: QuickMove.Raid
A34: 스테이지클리어 - 길드 작전 | B34: StageClear | C34: ContentsType : GuildOperation | D34: QuickMove.GuildOperation
A35: 스테이지클리어 - 도미니언 | B35: StageClear | C35: ContentsType : Dominion | D35: QuickMove.Dominion
A36: 스테이지클리어 - 월드 레이드 | B36: StageClear | C36: ContentsType : WorldRaid | D36: QuickMove.WorldRaid
A37: 스테이지클리어 - 통합작전 | B37: StageClear | C37: ContentsType : Raid | D37: QuickMove.Raid
A38: 스테이지클리어 - 데이터타워 | B38: StageClear | C38: ContentsType : DataTower | D38: QuickMove.DataTower
A39: 스테이지클리어 - 아레나 챌린지 | B39: StageClear | C39: ContentsType : ArenaChallenge | D39: QuickMove0510
A40: 스테이지클리어 - 아스니아 전투 의뢰 | B40: StageClear | C40: ContentsType : AsniaQuest
...

Sheet MissionCase.Daily
A1: Group | B1: #주석 | C1: Category | D1: NoticeProgress | E1: NoticeComplete | F1: Condition | G1: Ignore | H1: Step | I1: Name | J1: Desc | K1: Continuous | L1: MissionGoal | M1: GoalTarget | N1: GoalCount | O1: Reward | P1: QuickMove
A2: *long | B2: # | C2: $MissionCategory | D2: [dsl] | E2: bool | F2: [dsl] | G2: bool? | H2: int | I2: $Text | J2: $Text | K2: MissionChainingType | L2: StatisticsType | M2: {MissionGoalTargetType : string} | N2: int | O2: [dsl] | P2: $QuickMove?
A3: common | B3: # | C3: common | D3: server | E3: client | F3: common | G3: common | H3: common | I3: client | J3: client | K3: common | L3: common | M3: common | N3: common | O3: common | P3: client
A4: 2101000000000 | C4: 2200000000000 | D4: Always() | E4: TRUE
H5: 1 | I5: Daily.Mission.10 | J5: Daily.Mission.10 | K5: Equal | L5: StagePlay | M5: ContentsType : Scenario | N5: 1 | O5: MissionPoint(Daily, 20) | P5: QuickMove.MainBattle
A6: 2101000000001 | C6: 2200000000000 | D6: Always() | E6: TRUE
H7: 1 | I7: Daily.Mission.20 | J7: Daily.Mission.20 | K7: Equal | L7: StagePlay | M7: ContentsType : DataTower | N7: 1 | O7: MissionPoint(Daily, 10) | P7: QuickMove0380
A8: 2101000000002 | C8: 2200000000000 | D8: Always() | E8: TRUE
H9: 1 | I9: Daily.Mission.40 | J9: Daily.Mission.40 | K9: Equal | L9: IdleBattleReward | N9: 2 | O9: MissionPoint(Daily, 20) | P9: QuickMove.IdleBattlePopup
A10: 2101000000004 | C10: 2200000000000 | D10: Always() | E10: TRUE
H11: 1 | I11: Daily.Mission.60 | J11: Daily.Mission.60 | K11: Equal | L11: StagePlay | M11: ContentsType : Raid | N11: 1 | O11: MissionPoint(Daily, 10) | P11: QuickMove0160
A12: 2101000000005 | C12: 2200000000000 | D12: Always() | E12: TRUE
H13: 1 | I13: Daily.Mission.70 | J13: Daily.Mission.70 | K13: Equal | L13: ArenaPlay | M13: ArenaType : Normal | N13: 1 | O13: MissionPoint(Daily, 10) | P13: QuickMove0180
A14: 2101000000006 | C14: 2200000000000 | D14: Always() | E14: TRUE
H15: 1 | I15: Daily.Mission.90 | J15: Daily.Mission.90 | K15: Equal | L15: StagePlay | M15: ContentsType : GuildOperation | N15: 1 | O15: MissionPoint(Daily, 10) | P15: QuickMove0400
A16: 2101000000007 | C16: 2200000000000 | D16: Always() | E16: TRUE
H17: 1 | I17: Daily.Mission.100 | J17: Daily.Mission.100 | K17: Equal | L17: RewardCurrency | M17: ItemId:1040201001 | N17: 10 | O17: MissionPoint(Daily, 10) | P17: QuickMove0310
A18: 2101000000008 | C18: 2200000000000 | D18: Always() | E18: TRUE
H19: 1 | I19: Daily.Mission.120 | J19: Daily.Mission.120 | K19: Equal | L19: CharacterLvUp | N19: 1 | O19: MissionPoint(Daily, 10) | P19: QuickMove0250
A20: 2101000000009 | C20: 2200000000000 | D20: Always() | E20: TRUE
H21: 1 | I21: Daily.Mission.130 | J21: Daily.Mission.130 | K21: Equal | L21: TryEquipmentEnhance | N21: 1 | O21: MissionPoint(Daily, 10) | P21: QuickMove0170
A22: 2101000000010 | C22: 2200000000000 | D22: Always() | E22: TRUE
H23: 1 | I23: Daily.Mission.140 | J23: Daily.Mission.140 | K23: Equal | L23: PluginLvUp | N23: 1 | O23: MissionPoint(Daily, 10) | P23: QuickMove.Plugin
A24: 2101000000011 | C24: 2200000000000 | D24: Always() | E24: TRUE
H25: 1 | I25: Daily.Mission.150 | J25: Daily.Mission.150 | K25: Equal | L25: TryGacha | N25: 1 | O25: MissionPoint(Daily, 20) | P25: QuickMove.Gacha
A26: 2101000000012 | C26: 2200000000000 | D26: Always() | E26: TRUE
H27: 1 | I27: Daily.Mission.160 | J27: Daily.Mission.160 | K27: Equal | L27: ShopPurchase | M27: ShopCategory : 2600000000000 | N27: 1 | O27: MissionPoint(Daily, 10) | P27: QuickMove.Starbeat.Shop
A28: 2101000000101 | C28: 2200000000001 | D28: Always() | E28: FALSE
H29: 1 | I29: Mission.DailyMissionPoint.Point | J29: Mission.DailyMissionPoint.Point | K29: Equal | L29: MissionPoint | M29: MissionPointType : Daily | N29: 20 | O29: Item(1040605011, 1)
H30: 2 | I30: Mission.DailyMissionPoint.Point | J30: Mission.DailyMissionPoint.Point | K30: Equal | L30: MissionPoint | M30: MissionPointType : Daily | N30: 40 | O30: Item(1040605111, 1)
H31: 3 | I31: Mission.DailyMissionPoint.Point | J31: Mission.DailyMissionPoint.Point | K31: Equal | L31: MissionPoint | M31: MissionPointType : Daily | N31: 60 | O31: Item(1040605201, 1) Item(1040503171, 3)
H32: 4 | I32: Mission.DailyMissionPoint.Point | J32: Mission.DailyMissionPoint.Point | K32: Equal | L32: MissionPoint | M32: MissionPointType : Daily | N32: 80 | O32: Item(1040604001, 5) Item(1040504011, 2)
H33: 5 | I33: Mission.DailyMissionPoint.Point | J33: Mission.DailyMissionPoint.Point | K33: Equal | L33: MissionPoint | M33: MissionPointType : Daily | N33: 100 | O33: Item(1040102001, 40) Item(1040501001, 2)

Sheet MissionCase.Weekly
A1: Group | B1: #주석 | C1: Category | D1: NoticeProgress | E1: NoticeComplete | F1: Condition | G1: Ignore | H1: Step | I1: Name | J1: Desc | K1: Continuous | L1: MissionGoal | M1: GoalTarget | N1: GoalCount | O1: Reward | P1: QuickMove
A2: *long | B2: # | C2: $MissionCategory | D2: [dsl] | E2: bool | F2: [dsl] | G2: bool? | H2: int | I2: $Text | J2: $Text | K2: MissionChainingType | L2: StatisticsType | M2: {MissionGoalTargetType : string} | N2: int | O2: [dsl] | P2: $QuickMove?
A3: common | B3: # | C3: common | D3: server | E3: client | F3: common | G3: common | H3: common | I3: client | J3: client | K3: common | L3: common | M3: common | N3: common | O3: common | P3: client
A4: 2100000000000 | C4: 2200000000002 | D4: Always() | E4: TRUE
H5: 1 | I5: Weekly.Mission.10 | J5: Weekly.Mission.Desc.10 | K5: Equal | L5: TryGacha | M5: GachaGroup : Character | N5: 5 | O5: MissionPoint(Weekly, 20) | P5: QuickMove.Gacha.Character
A6: 2100000000001 | C6: 2200000000002 | D6: Always() | E6: TRUE
H7: 1 | I7: Weekly.Mission.20 | J7: Weekly.Mission.Desc.20 | K7: Equal | L7: TryGacha | M7: GachaGroup : Plugin | N7: 5 | O7: MissionPoint(Weekly, 20) | P7: QuickMove.Gacha
A8: 2100000000002 | C8: 2200000000002 | D8: Always() | E8: TRUE
H9: 1 | I9: Weekly.Mission.30 | J9: Weekly.Mission.Desc.30 | K9: Equal | L9: CharacterGradeUp | N9: 1 | O9: MissionPoint(Weekly, 20) | P9: QuickMove0660
A10: 2100000000003 | C10: 2200000000002 | D10: Always() | E10: TRUE
H11: 1 | I11: Weekly.Mission.160 | J11: Weekly.Mission.Desc.160 | K11: Equal | L11: MissionPoint | M11: MissionPointType : AMH | N11: 5 | O11: MissionPoint(Weekly, 20) | P11: QuickMove0300
A12: 2100000000004 | C12: 2200000000002 | D12: Always() | E12: TRUE
H13: 1 | I13: Weekly.Mission.40 | J13: Weekly.Mission.Desc.40 | K13: Equal | L13: ShopPurchase | M13: ShopCategory : 2600000000000 | N13: 3 | O13: MissionPoint(Weekly, 10) | P13: QuickMove.Starbeat.Shop
A14: 2100000000005 | C14: 2200000000002 | D14: Always() | E14: TRUE
H15: 1 | I15: Weekly.Mission.50 | J15: Weekly.Mission.Desc.50 | K15: Equal | L15: ShopPurchase | M15: ShopCategory : 2600000000004 | N15: 3 | O15: MissionPoint(Weekly, 10) | P15: QuickMove.Guild.Shop
A16: 2100000000006 | C16: 2200000000002 | D16: Always() | E16: TRUE
H17: 1 | I17: Weekly.Mission.60 | J17: Weekly.Mission.Desc.60 | K17: Equal | L17: ArenaVictory | M17: ArenaType : Normal | N17: 8 | O17: MissionPoint(Weekly, 10) | P17: QuickMove.Arena
A18: 2100000000007 | C18: 2200000000002 | D18: Always() | E18: TRUE
H19: 1 | I19: Weekly.Mission.70 | J19: Weekly.Mission.Desc.70 | K19: Equal | L19: GuildDonation | N19: 20 | O19: MissionPoint(Weekly, 10) | P19: QuickMove.GuildSupport
A20: 2100000000008 | C20: 2200000000002 | D20: Always() | E20: TRUE
H21: 1 | I21: Weekly.Mission.110 | J21: Weekly.Mission.Desc.110 | K21: Equal | L21: GiveGift | N21: 5 | O21: MissionPoint(Weekly, 10) | P21: QuickMove.Favorability
A22: 2100000000009 | C22: 2200000000002 | D22: Always() | E22: TRUE
H23: 1 | I23: Weekly.Mission.150 | J23: Weekly.Mission.Desc.150 | K23: Equal | L23: PluginPromote | N23: 1 | O23: MissionPoint(Weekly, 10) | P23: QuickMove.Plugin
A24: 2100000000101 | C24: 2200000000003 | D24: Always() | E24: TRUE
H25: 1 | I25: Mission.WeeklyMissionPoint.Point | J25: Mission.WeeklyMissionPoint.Point | K25: Equal | L25: MissionPoint | M25: MissionPointType : Weekly | N25: 20 | O25: Item(1040605031, 1) Item(1040604002, 5)
H26: 2 | I26: Mission.WeeklyMissionPoint.Point | J26: Mission.WeeklyMissionPoint.Point | K26: Equal | L26: MissionPoint | M26: MissionPointType : Weekly | N26: 40 | O26: Item(1040605131, 1) Item(1040604001, 50)
H27: 3 | I27: Mission.WeeklyMissionPoint.Point | J27: Mission.WeeklyMissionPoint.Point | K27: Equal | L27: MissionPoint | M27: MissionPointType : Weekly | N27: 60 | O27: Item(1040605211, 1) Item(1040503171, 9)
H28: 4 | I28: Mission.WeeklyMissionPoint.Point | J28: Mission.WeeklyMissionPoint.Point | K28: Equal | L28: MissionPoint | M28: MissionPointType : Weekly | N28: 80 | O28: Item(1040501101, 4) Item(1040504011, 15)
H29: 5 | I29: Mission.WeeklyMissionPoint.Point | J29: Mission.WeeklyMissionPoint.Point | K29: Equal | L29: MissionPoint | M29: MissionPointType : Weekly | N29: 100 | O29: Item(1040102001, 300) Item(1040501001, 4)

Sheet MissionCase.Main
A1: Group | B1: #주석 | C1: Category | D1: NoticeProgress | E1: NoticeComplete | F1: Condition | G1: Ignore | H1: Step | I1: Name | J1: Desc | K1: Continuous | L1: MissionGoal | M1: GoalTarget | N1: GoalCount | O1: Reward | P1: QuickMove
A2: *long | B2: # | C2: $MissionCategory | D2: [dsl] | E2: bool | F2: [dsl] | G2: bool? | H2: int | I2: $Text | J2: $Text | K2: MissionChainingType | L2: StatisticsType | M2: {MissionGoalTargetType : string} | N2: int | O2: [dsl] | P2: $QuickMove?
A3: common | B3: # | C3: common | D3: server | E3: client | F3: common | G3: common | H3: common | I3: client | J3: client | K3: common | L3: common | M3: common | N3: common | O3: common | P3: client
A5: 2101999999999 | C5: 2200000000005 | D5: Always() | E5: TRUE
H6: 1 | I6: Main.Mission.09.01 | J6: Main.Mission.Desc.09.1 | K6: Always | L6: TryGacha | M6: GachaPickUp: True | N6: 10 | O6: Item(1040501002, 5) | P6: QuickMove.Gacha
H7: 2 | I7: Main.Mission.09.02 | J7: Main.Mission.Desc.09.2 | K7: Always | L7: TryGacha | M7: GachaPickUp: True | N7: 20 | O7: Item(1040501002, 5) | P7: QuickMove.Gacha
H8: 3 | I8: Main.Mission.09.03 | J8: Main.Mission.Desc.09.3 | K8: Always | L8: TryGacha | M8: GachaPickUp: True | N8: 30 | O8: Item(1040501002, 5) | P8: QuickMove.Gacha
H9: 4 | I9: Main.Mission.09.04 | J9: Main.Mission.Desc.09.4 | K9: Always | L9: TryGacha | M9: GachaPickUp: True | N9: 40 | O9: Item(1040501002, 5) | P9: QuickMove.Gacha
H10: 5 | I10: Main.Mission.09.05 | J10: Main.Mission.Desc.09.5 | K10: Always | L10: TryGacha | M10: GachaPickUp: True | N10: 50 | O10: Item(1040501002, 5) | P10: QuickMove.Gacha
H11: 6 | I11: Main.Mission.09.06 | J11: Main.Mission.Desc.09.6 | K11: Always | L11: TryGacha | M11: GachaPickUp: True | N11: 60 | O11: Item(1040501002, 5) | P11: QuickMove.Gacha
H12: 7 | I12: Main.Mission.09.07 | J12: Main.Mission.Desc.09.7 | K12: Always | L12: TryGacha | M12: GachaPickUp: True | N12: 70 | O12: Item(1040501002, 5) | P12: QuickMove.Gacha
H13: 8 | I13: Main.Mission.09.08 | J13: Main.Mission.Desc.09.8 | K13: Always | L13: TryGacha | M13: GachaPickUp: True | N13: 80 | O13: Item(1040501002, 5) | P13: QuickMove.Gacha
H14: 9 | I14: Main.Mission.09.09 | J14: Main.Mission.Desc.09.9 | K14: Always | L14: TryGacha | M14: GachaPickUp: True | N14: 90 | O14: Item(1040501002, 5) | P14: QuickMove.Gacha
H15: 10 | I15: Main.Mission.09.10 | J15: Main.Mission.Desc.09.10 | K15: Always | L15: TryGacha | M15: GachaPickUp: True | N15: 100 | O15: Item(1040501002, 5) | P15: QuickMove.Gacha
H16: 11 | I16: Main.Mission.09.11 | J16: Main.Mission.Desc.09.11 | K16: Always | L16: TryGacha | M16: GachaPickUp: True | N16: 110 | O16: Item(1040501002, 5) | P16: QuickMove.Gacha
H17: 12 | I17: Main.Mission.09.12 | J17: Main.Mission.Desc.09.12 | K17: Always | L17: TryGacha | M17: GachaPickUp: True | N17: 120 | O17: Item(1040501002, 5) | P17: QuickMove.Gacha
... H25: 20 | I25: Main.Mission.09.20 | J25: Main.Mission.Desc.09.20 | K25: Always | L25: TryGacha | M25: GachaPickUp: True | N25: 200 | O25: Item(1040501002, 5) | P25: QuickMove.Gacha
A26: 2102000000000 | C26: 2200000000005 | D26: Always() | E26: TRUE
H27: 1 | I27: Main.Mission.10 | J27: Main.Mission.Desc.10.1 | K27: Equal | L27: AcountLv | N27: 2 | O27: Item(1040102001, 50)
H28: 2 | I28: Main.Mission.10 | J28: Main.Mission.Desc.10.2 | K28: Equal | L28: AcountLv | N28: 5 | O28: Item(1040102001, 50)
H29: 3 | I29: Main.Mission.10 | J29: Main.Mission.Desc.10.3 | K29: Equal | L29: AcountLv | N29: 9 | O29: Item(1040102001, 100)
H30: 4 | I30: Main.Mission.10 | J30: Main.Mission.Desc.10.4 | K30: Equal | L30: AcountLv | N30: 15 | O30: Item(1040102001, 100)
H31: 5 | I31: Main.Mission.10 | J31: Main.Mission.Desc.10.5 | K31: Equal | L31: AcountLv | N31: 22 | O31: Item(1040102001, 150)
H32: 6 | I32: Main.Mission.10 | J32: Main.Mission.Desc.10.6 | K32: Equal | L32: AcountLv | N32: 29 | O32: Item(1040102001, 150)
H33: 7 | I33: Main.Mission.10 | J33: Main.Mission.Desc.10.7 | K33: Equal | L33: AcountLv | N33: 38 | O33: Item(1040102001, 150)
H34: 8 | I34: Main.Mission.10 | J34: Main.Mission.Desc.10.8 | K34: Equal | L34: AcountLv | N34: 47 | O34: Item(1040102001, 150)
H35: 9 | I35: Main.Mission.10 | J35: Main.Mission.Desc.10.9 | K35: Equal | L35: AcountLv | N35: 57 | O35: Item(1040102001, 150)
H36: 10 | I36: Main.Mission.10 | J36: Main.Mission.Desc.10.10 | K36: Equal | L36: AcountLv | N36: 67 | O36: Item(1040102001, 150)
H37: 11 | I37: Main.Mission.10 | J37: Main.Mission.Desc.10.11 | K37: Equal | L37: AcountLv | N37: 78 | O37: Item(1040102001, 150)
H38: 12 | I38: Main.Mission.10 | J38: Main.Mission.Desc.10.12 | K38: Equal | L38: AcountLv | N38: 90 | O38: Item(1040102001, 150)
... H46: 20 | I46: Main.Mission.10 | J46: Main.Mission.Desc.10.20 | K46: Equal | L46: AcountLv | N46: 200 | O46: Item(1040102001, 200)
A48: 2102000000001 | C48: 2200000000005 | D48: Always() | E48: TRUE
H49: 1 | I49: Main.Mission.20.6 | J49: Main.Mission.Desc.20.6.1 | K49: Equal | L49: StageClear | M49: ContentsType : Scenario | N49: 25 | O49: Item(1040102001, 50) | P49: QuickMove.MainBattle
H50: 2 | I50: Main.Mission.20.6 | J50: Main.Mission.Desc.20.6.2 | K50: Equal | L50: StageClear | M50: ContentsType : Scenario | N50: 50 | O50: Item(1040102001, 50) | P50: QuickMove.MainBattle
H51: 3 | I51: Main.Mission.20.6 | J51: Main.Mission.Desc.20.6.3 | K51: Equal | L51: StageClear | M51: ContentsType : Scenario | N51: 80 | O51: Item(1040102001, 100) | P51: QuickMove.MainBattle
H52: 4 | I52: Main.Mission.20.6 | J52: Main.Mission.Desc.20.6.4 | K52: Equal | L52: StageClear | M52: ContentsType : Scenario | N52: 100 | O52: Item(1040102001, 100) | P52: QuickMove.MainBattle
H53: 5 | I53: Main.Mission.20.6 | J53: Main.Mission.Desc.20.6.5 | K53: Equal | L53: StageClear | M53: ContentsType : Scenario | N53: 140 | O53: Item(1040102001, 150) | P53: QuickMove.MainBattle
H54: 6 | I54: Main.Mission.20.6 | J54: Main.Mission.Desc.20.6.6 | K54: Equal | L54: StageClear | M54: ContentsType : Scenario | N54: 180 | O54: Item(1040102001, 150) | P54: QuickMove.MainBattle
H55: 7 | I55: Main.Mission.20.6 | J55: Main.Mission.Desc.20.6.7 | K55: Equal | L55: StageClear | M55: ContentsType : Scenario | N55: 220 | O55: Item(1040102001, 150) | P55: QuickMove.MainBattle
H56: 8 | I56: Main.Mission.20.6 | J56: Main.Mission.Desc.20.6.8 | K56: Equal | L56: StageClear | M56: ContentsType : Scenario | N56: 270 | O56: Item(1040102001, 150) | P56: QuickMove.MainBattle
...

Sheet MissionCase.Unlock
A1: Group | B1: #주석 | C1: Category | D1: NoticeProgress | E1: NoticeComplete | F1: Condition | G1: Ignore | H1: Step | I1: Name | J1: Desc | K1: Continuous | L1: MissionGoal | M1: GoalTarget | N1: GoalCount | O1: Reward | P1: QuickMove
A2: *long | B2: # | C2: $MissionCategory | D2: [dsl] | E2: bool | F2: [dsl] | G2: bool? | H2: int | I2: $Text | J2: $Text | K2: MissionChainingType | L2: StatisticsType | M2: {MissionGoalTargetType : string} | N2: int | O2: [dsl] | P2: $QuickMove?
A3: common | B3: # | C3: common | D3: server | E3: client | F3: common | G3: common | H3: common | I3: client | J3: client | K3: common | L3: common | M3: common | N3: common | O3: common | P3: client
A4: 2103000000000 | C4: 2200000000004 | D4: Never() | E4: FALSE
H5: 1 | I5: MSG.Mission.Name.Get.Plugin | J5: MSG.Mission.Desc.Get.Plugin | K5: Equal | L5: GetPlugin | M5: PluginId : 1030710001 | N5: 1 | P5: QuickMove0110
A6: 2103000000001 | C6: 2200000000004 | D6: Never() | E6: FALSE
H7: 1 | I7: MSG.Mission.Name.Get.Plugin | J7: MSG.Mission.Desc.Get.Plugin | K7: Equal | L7: GetPlugin | M7: PluginId : 1030710002 | N7: 1 | P7: QuickMove0110
A8: 2103000000002 | C8: 2200000000004 | D8: Never() | E8: FALSE
H9: 1 | I9: MSG.Mission.Name.Get.Plugin | J9: MSG.Mission.Desc.Get.Plugin | K9: Equal | L9: GetPlugin | M9: PluginId : 1030710003 | N9: 1 | P9: QuickMove0110
A10: 2103000000003 | C10: 2200000000004 | D10: Never() | E10: FALSE
H11: 1 | I11: MSG.Mission.Name.Get.Plugin | J11: MSG.Mission.Desc.Get.Plugin | K11: Equal | L11: GetPlugin | M11: PluginId : 1030510001 | N11: 1 | P11: QuickMove0110
A12: 2103000000004 | C12: 2200000000004 | D12: Never() | E12: FALSE
H13: 1 | I13: MSG.Mission.Name.Get.Plugin | J13: MSG.Mission.Desc.Get.Plugin | K13: Equal | L13: GetPlugin | M13: PluginId : 1030510002 | N13: 1 | P13: QuickMove0110
A14: 2103000000005 | C14: 2200000000004 | D14: Never() | E14: FALSE
H15: 1 | I15: MSG.Mission.Name.Get.Plugin | J15: MSG.Mission.Desc.Get.Plugin | K15: Equal | L15: GetPlugin | M15: PluginId : 1030920002 | N15: 1 | P15: QuickMove0110
A16: 2103000000006 | C16: 2200000000004 | D16: Never() | E16: FALSE
H17: 1 | I17: MSG.Mission.Name.Get.Plugin | J17: MSG.Mission.Desc.Get.Plugin | K17: Equal | L17: GetPlugin | M17: PluginId : 1030920003 | N17: 1 | P17: QuickMove0110
A18: 2103000000007 | C18: 2200000000004 | D18: Never() | E18: FALSE
H19: 1 | I19: MSG.Mission.Name.Get.Plugin | J19: MSG.Mission.Desc.Get.Plugin | K19: Equal | L19: GetPlugin | M19: PluginId : 1030920004 | N19: 1 | P19: QuickMove0110
A20: 2103000000008 | C20: 2200000000004 | D20: Never() | E20: FALSE
H21: 1 | I21: MSG.Mission.Name.Get.Plugin | J21: MSG.Mission.Desc.Get.Plugin | K21: Equal | L21: GetPlugin | M21: PluginId : 1030920005 | N21: 1 | P21: QuickMove0110
A22: 2103000000009 | C22: 2200000000004 | D22: Never() | E22: FALSE
H23: 1 | I23: MSG.Mission.Name.Get.Plugin | J23: MSG.Mission.Desc.Get.Plugin | K23: Equal | L23: GetPlugin | M23: PluginId : 1030720001 | N23: 1 | P23: QuickMove0110
A24: 2103000000010 | C24: 2200000000004 | D24: Never() | E24: FALSE
H25: 1 | I25: MSG.Mission.Name.Get.Plugin | J25: MSG.Mission.Desc.Get.Plugin | K25: Equal | L25: GetPlugin | M25: PluginId : 1030720002 | N25: 1 | P25: QuickMove0110
A26: 2103000000011 | C26: 2200000000004 | D26: Never() | E26: FALSE
H27: 1 | I27: MSG.Mission.Name.Get.Plugin | J27: MSG.Mission.Desc.Get.Plugin | K27: Equal | L27: GetPlugin | M27: PluginId : 1030720003 | N27: 1 | P27: QuickMove0110
A28: 2103000000012 | C28: 2200000000004 | D28: Never() | E28: FALSE
H29: 1 | I29: MSG.Mission.Name.Get.Plugin | J29: MSG.Mission.Desc.Get.Plugin | K29: Equal | L29: GetPlugin | M29: PluginId : 1030720004 | N29: 1 | P29: QuickMove0110
A30: 2103000000013 | C30: 2200000000004 | D30: Never() | E30: FALSE
H31: 1 | I31: MSG.Mission.Name.Get.Plugin | J31: MSG.Mission.Desc.Get.Plugin | K31: Equal | L31: GetPlugin | M31: PluginId : 1030720005 | N31: 1 | P31: QuickMove0110
A32: 2103000000014 | C32: 2200000000004 | D32: Never() | E32: FALSE
H33: 1 | I33: MSG.Mission.Name.Get.Plugin | J33: MSG.Mission.Desc.Get.Plugin | K33: Equal | L33: GetPlugin | M33: PluginId : 1030720006 | N33: 1 | P33: QuickMove0110
A34: 2103000000015 | C34: 2200000000004 | D34: Never() | E34: FALSE
H35: 1 | I35: MSG.Mission.Name.Get.Plugin | J35: MSG.Mission.Desc.Get.Plugin | K35: Equal | L35: GetPlugin | M35: PluginId : 1030720007 | N35: 1 | P35: QuickMove0110
A36: 2103000000016 | C36: 2200000000004 | D36: Never() | E36: FALSE
H37: 1 | I37: MSG.Mission.Name.Get.Plugin | J37: MSG.Mission.Desc.Get.Plugin | K37: Equal | L37: GetPlugin | M37: PluginId : 1030520001 | N37: 1 | P37: QuickMove0110
A38: 2103000000017 | C38: 2200000000004 | D38: Never() | E38: FALSE
H39: 1 | I39: MSG.Mission.Name.Get.Plugin | J39: MSG.Mission.Desc.Get.Plugin | K39: Equal | L39: GetPlugin | M39: PluginId : 1030520003 | N39: 1 | P39: QuickMove0110
A40: 2103000000018 | C40: 2200000000004 | D40: Never() | E40: FALSE
...

Sheet MissionCase.Special
A1: Group | B1: #주석 | C1: Category | D1: NoticeProgress | E1: NoticeComplete | F1: Condition | G1: Ignore | H1: Step | I1: Name | J1: Desc | K1: Continuous | L1: MissionGoal | M1: GoalTarget | N1: GoalCount | O1: Reward | P1: QuickMove
A2: *long | B2: # | C2: $MissionCategory | D2: [dsl] | E2: bool | F2: [dsl] | G2: bool? | H2: int | I2: $Text | J2: $Text | K2: MissionChainingType | L2: StatisticsType | M2: {MissionGoalTargetType : string} | N2: int | O2: [dsl] | P2: $QuickMove?
A3: common | B3: # | C3: common | D3: server | E3: client | F3: common | G3: common | H3: common | I3: client | J3: client | K3: common | L3: common | M3: common | N3: common | O3: common | P3: client
A4: 2104000000017 | B4: 선별뽑기 완료 패키지 | C4: 2200000000010 | D4: Always() | E4: FALSE
H5: 1 | I5: MSG.Mission.Name.Get.Plugin | J5: MSG.Mission.Desc.Get.Plugin | K5: Always | L5: ConfirmSelectiveGacha | N5: 1 | O5: ShopSlot(2701000000065) | P5: QuickMove0010
A6: 2104000000034 | B6: 릴리안 호감도 3 달성 패키지 | C6: 2200000000010 | D6: Always() | E6: FALSE
H7: 1 | I7: MSG.Mission.Name.Get.Plugin | J7: MSG.Mission.Desc.Get.Plugin | K7: Always | L7: FavorLevelUp | M7: CharacterId : 1010710001 | N7: 2 | O7: ShopSlot(2771000000082) | P7: QuickMove0010
A8: 2104000000035 | B8: 릴리안 호감도 6 달성 패키지 | C8: 2200000000010 | D8: Always() | E8: FALSE
H9: 1 | I9: MSG.Mission.Name.Get.Plugin | J9: MSG.Mission.Desc.Get.Plugin | K9: Always | L9: FavorLevelUp | M9: CharacterId : 1010710001 | N9: 5 | O9: ShopSlot(2771000000083) | P9: QuickMove0010
A10: 2104000000036 | B10: 릴리안 호감도 MAX 달성 패키지 | C10: 2200000000010 | D10: Always() | E10: FALSE
H11: 1 | I11: MSG.Mission.Name.Get.Plugin | J11: MSG.Mission.Desc.Get.Plugin | K11: Always | L11: FavorLevelUp | M11: CharacterId : 1010710001 | N11: 7 | O11: ShopSlot(2771000000084) | P11: QuickMove0010
A12: 2104000000037 | B12: 다리아 호감도 3 달성 패키지 | C12: 2200000000010 | D12: Always() | E12: FALSE
H13: 1 | I13: MSG.Mission.Name.Get.Plugin | J13: MSG.Mission.Desc.Get.Plugin | K13: Always | L13: FavorLevelUp | M13: CharacterId : 1010710002 | N13: 2 | O13: ShopSlot(2771000000085) | P13: QuickMove0010
A14: 2104000000038 | B14: 다리아 호감도 6 달성 패키지 | C14: 2200000000010 | D14: Always() | E14: FALSE
H15: 1 | I15: MSG.Mission.Name.Get.Plugin | J15: MSG.Mission.Desc.Get.Plugin | K15: Always | L15: FavorLevelUp | M15: CharacterId : 1010710002 | N15: 5 | O15: ShopSlot(2771000000086) | P15: QuickMove0010
A16: 2104000000039 | B16: 다리아 호감도 MAX 달성 패키지 | C16: 2200000000010 | D16: Always() | E16: FALSE
H17: 1 | I17: MSG.Mission.Name.Get.Plugin | J17: MSG.Mission.Desc.Get.Plugin | K17: Always | L17: FavorLevelUp | M17: CharacterId : 1010710002 | N17: 7 | O17: ShopSlot(2771000000087) | P17: QuickMove0010
A18: 2104000000040 | B18: 스노프릴 호감도 3 달성 패키지 | C18: 2200000000010 | D18: Always() | E18: FALSE
H19: 1 | I19: MSG.Mission.Name.Get.Plugin | J19: MSG.Mission.Desc.Get.Plugin | K19: Always | L19: FavorLevelUp | M19: CharacterId : 1010710003 | N19: 2 | O19: ShopSlot(2771000000088) | P19: QuickMove0010
A20: 2104000000041 | B20: 스노프릴 호감도 6 달성 패키지 | C20: 2200000000010 | D20: Always() | E20: FALSE
H21: 1 | I21: MSG.Mission.Name.Get.Plugin | J21: MSG.Mission.Desc.Get.Plugin | K21: Always | L21: FavorLevelUp | M21: CharacterId : 1010710003 | N21: 5 | O21: ShopSlot(2771000000089) | P21: QuickMove0010
A22: 2104000000042 | B22: 스노프릴 호감도 MAX 달성 패키지 | C22: 2200000000010 | D22: Always() | E22: FALSE
H23: 1 | I23: MSG.Mission.Name.Get.Plugin | J23: MSG.Mission.Desc.Get.Plugin | K23: Always | L23: FavorLevelUp | M23: CharacterId : 1010710003 | N23: 7 | O23: ShopSlot(2771000000090) | P23: QuickMove0010
A24: 2104000000046 | B24: 타이나 호감도 3 달성 패키지 | C24: 2200000000010 | D24: Always() | E24: FALSE
H25: 1 | I25: MSG.Mission.Name.Get.Plugin | J25: MSG.Mission.Desc.Get.Plugin | K25: Always | L25: FavorLevelUp | M25: CharacterId : 1010510002 | N25: 2 | O25: ShopSlot(2771000000094) | P25: QuickMove0010
A26: 2104000000047 | B26: 타이나 호감도 6 달성 패키지 | C26: 2200000000010 | D26: Always() | E26: FALSE
H27: 1 | I27: MSG.Mission.Name.Get.Plugin | J27: MSG.Mission.Desc.Get.Plugin | K27: Always | L27: FavorLevelUp | M27: CharacterId : 1010510002 | N27: 5 | O27: ShopSlot(2771000000095) | P27: QuickMove0010
A28: 2104000000048 | B28: 타이나 호감도 MAX 달성 패키지 | C28: 2200000000010 | D28: Always() | E28: FALSE
H29: 1 | I29: MSG.Mission.Name.Get.Plugin | J29: MSG.Mission.Desc.Get.Plugin | K29: Always | L29: FavorLevelUp | M29: CharacterId : 1010510002 | N29: 7 | O29: ShopSlot(2771000000096) | P29: QuickMove0010
A30: 2104000000049 | B30: 세라펄사 호감도 3 달성 패키지 | C30: 2200000000010 | D30: Always() | E30: FALSE
H31: 1 | I31: MSG.Mission.Name.Get.Plugin | J31: MSG.Mission.Desc.Get.Plugin | K31: Always | L31: FavorLevelUp | M31: CharacterId : 1010920002 | N31: 2 | O31: ShopSlot(2771000000097) | P31: QuickMove0010
A32: 2104000000050 | B32: 세라펄사 호감도 6 달성 패키지 | C32: 2200000000010 | D32: Always() | E32: FALSE
H33: 1 | I33: MSG.Mission.Name.Get.Plugin | J33: MSG.Mission.Desc.Get.Plugin | K33: Always | L33: FavorLevelUp | M33: CharacterId : 1010920002 | N33: 5 | O33: ShopSlot(2771000000098) | P33: QuickMove0010
A34: 2104000000051 | B34: 세라펄사 호감도 MAX 달성 패키지 | C34: 2200000000010 | D34: Always() | E34: FALSE
H35: 1 | I35: MSG.Mission.Name.Get.Plugin | J35: MSG.Mission.Desc.Get.Plugin | K35: Always | L35: FavorLevelUp | M35: CharacterId : 1010920002 | N35: 7 | O35: ShopSlot(2771000000099) | P35: QuickMove0010
A36: 2104000000052 | B36: 아이라스 호감도 3 달성 패키지 | C36: 2200000000010 | D36: Always() | E36: FALSE
H37: 1 | I37: MSG.Mission.Name.Get.Plugin | J37: MSG.Mission.Desc.Get.Plugin | K37: Always | L37: FavorLevelUp | M37: CharacterId : 1010920003 | N37: 2 | O37: ShopSlot(2771000000100) | P37: QuickMove0010
A38: 2104000000053 | B38: 아이라스 호감도 6 달성 패키지 | C38: 2200000000010 | D38: Always() | E38: FALSE
H39: 1 | I39: MSG.Mission.Name.Get.Plugin | J39: MSG.Mission.Desc.Get.Plugin | K39: Always | L39: FavorLevelUp | M39: CharacterId : 1010920003 | N39: 5 | O39: ShopSlot(2771000000101) | P39: QuickMove0010
A40: 2104000000054 | B40: 아이라스 호감도 MAX 달성 패키지 | C40: 2200000000010 | D40: Always() | E40: FALSE
...

Sheet MissionCase.Guide
A1: Group | B1: #주석 | C1: Category | D1: NoticeProgress | E1: NoticeComplete | F1: Condition | G1: Ignore | H1: Step | I1: Name | J1: Desc | K1: Continuous | L1: MissionGoal | M1: GoalTarget | N1: GoalCount | O1: Reward | P1: # | Q1: QuickMove
A2: *long | B2: # | C2: $MissionCategory | D2: [dsl] | E2: bool | F2: [dsl] | G2: bool? | H2: int | I2: $Text | J2: $Text | K2: MissionChainingType | L2: StatisticsType | M2: {MissionGoalTargetType : string} | N2: int | O2: [dsl] | P2: # | Q2: $QuickMove?
A3: common | B3: # | C3: common | D3: server | E3: client | F3: common | G3: common | H3: common | I3: client | J3: client | K3: common | L3: common | M3: common | N3: common | O3: common | P3: # | Q3: client
A4: 2105000000001 | B4: 아스니아 도착(1-4승리) | C4: 2200000000009 | D4: Always() | E4: TRUE
H5: 1 | I5: Mission.Guide.001 | J5: Mission.Guide.001 | K5: Equal | L5: StageClear | M5: StageId : 스테이지4 | N5: 1 | O5: Item(1040102001, 25) | P5: =IF(VLOOKUP(L5,Statistics!B:F,5,FALSE)=0,"",VLOOKUP(L5,Statistics!B:F,5,FALSE)) -> QuickMove0010 | Q5: QuickMove0010
A6: 2105000000002 | B6: 앰브로시아 영입 | C6: 2200000000009 | D6: Always() | E6: TRUE
H7: 1 | I7: Mission.Guide.002 | J7: Mission.Guide.002 | K7: Equal | L7: CharacterPossess | M7: CharacterId:1010920004 | N7: 1 | O7: Item(1040302001, 500) | P7: =IF(VLOOKUP(L7,Statistics!B:F,5,FALSE)=0,"",VLOOKUP(L7,Statistics!B:F,5,FALSE)) -> QuickMove0110 | Q7: QuickMove0110
A8: 2105000000003 | B8: 캐릭터 레벨업 | C8: 2200000000009 | D8: Always() | E8: TRUE
H9: 1 | I9: Mission.Guide.003 | J9: Mission.Guide.003 | K9: Equal | L9: CharacterLvUp | N9: 1 | O9: Item(1040101001, 1000) | P9: =IF(VLOOKUP(L9,Statistics!B:F,5,FALSE)=0,"",VLOOKUP(L9,Statistics!B:F,5,FALSE)) -> QuickMove0250 | Q9: QuickMove0250
A10: 2105000000004 | B10: 시즈 획득 | C10: 2200000000009 | D10: Always() | E10: TRUE
H11: 1 | I11: Mission.Guide.004 | J11: Mission.Guide.004 | K11: Equal | L11: CharacterPossess | M11: CharacterId:1010340001 | N11: 1 | O11: Item(1040302001, 500) | P11: =IF(VLOOKUP(L11,Statistics!B:F,5,FALSE)=0,"",VLOOKUP(L11,Statistics!B:F,5,FALSE)) -> QuickMove0110 | Q11: QuickMove0010
A12: 2105000000005 | B12: 1-6 승리 | C12: 2200000000009 | D12: Always() | E12: TRUE
H13: 1 | I13: Mission.Guide.005 | J13: Mission.Guide.005 | K13: Equal | L13: StageClear | M13: StageId : 스테이지6 | N13: 1 | O13: Item(1040102001, 50) | P13: QuickMove0010 | Q13: QuickMove0010
A14: 2105000000006 | B14: 일일 미션 완료 | C14: 2200000000009 | D14: Always() | E14: TRUE
H15: 1 | I15: Mission.Guide.006 | J15: Mission.Guide.006 | K15: Equal | L15: MissionPoint | M15: MissionPointType : Daily | N15: 1 | O15: Item(1040302001, 1000) | P15: =IF(VLOOKUP(L15,Statistics!B:F,5,FALSE)=0,"",VLOOKUP(L15,Statistics!B:F,5,FALSE)) | Q15: QuickMove0350
A16: 2105000000007 | B16: 링크 달성하기 | C16: 2200000000009 | D16: Always() | E16: TRUE
H17: 1 | I17: Mission.Guide.007 | J17: Mission.Guide.007 | K17: Equal | L17: CharacterLink | N17: 1 | O17: Item(1040101001, 1000) | P17: =IF(VLOOKUP(L17,Statistics!B:F,5,FALSE)=0,"",VLOOKUP(L17,Statistics!B:F,5,FALSE)) | Q17: QuickMove0580
A18: 2105000000008 | B18: 프록시안 1명 5레벨 달성 | C18: 2200000000009 | D18: Always() | E18: TRUE
H19: 1 | I19: Mission.Guide.008 | J19: Mission.Guide.008 | K19: Equal | L19: CharacterLevelReached | M19: Level : 5 | N19: 1 | O19: Item(1040408041, 10) | P19: =IF(VLOOKUP(L19,Statistics!B:F,5,FALSE)=0,"",VLOOKUP(L19,Statistics!B:F,5,FALSE)) -> QuickMove0250 | Q19: QuickMove0250
A20: 2105000000009 | B20: 스킬 레벨업 1회 | C20: 2200000000009 | D20: Always() | E20: TRUE
H21: 1 | I21: Mission.Guide.009 | J21: Mission.Guide.009 | K21: Equal | L21: SkillLvUp | N21: 1 | O21: Item(1040302001, 1000) | P21: =IF(VLOOKUP(L21,Statistics!B:F,5,FALSE)=0,"",VLOOKUP(L21,Statistics!B:F,5,FALSE)) -> QuickMove0420 | Q21: QuickMove0420
A22: 2105000000010 | B22: 1-7 승리 | C22: 2200000000009 | D22: Always() | E22: TRUE
H23: 1 | I23: Mission.Guide.010 | J23: Mission.Guide.010 | K23: Equal | L23: StageClear | M23: StageId : 스테이지7 | N23: 1 | O23: Item(1040102001, 100) | P23: QuickMove0010 | Q23: QuickMove0010
A24: 2105000000011 | B24: 1-8 승리 | C24: 2200000000009 | D24: Always() | E24: TRUE
H25: 1 | I25: Mission.Guide.011 | J25: Mission.Guide.011 | K25: Equal | L25: StageClear | M25: StageId : 스테이지8 | N25: 1 | O25: Item(1040302001, 2000) | P25: QuickMove0010 | Q25: QuickMove0010
A26: 2105000000012 | B26: 선물 1회 주기 | C26: 2200000000009 | D26: Always() | E26: TRUE
H27: 1 | I27: Mission.Guide.012 | J27: Mission.Guide.012 | K27: Equal | L27: GiveGift | N27: 1 | O27: Item(1040101001, 1000) | Q27: QuickMove0630
A28: 2105000000013 | B28: 세라펄사 | C28: 2200000000009 | D28: Always() | E28: TRUE
H29: 1 | I29: Mission.Guide.013 | J29: Mission.Guide.013 | K29: Equal | L29: CharacterPossess | M29: CharacterId:1010920002 | N29: 1 | O29: Item(1040302001, 2000) | P29: =IF(VLOOKUP(L29,Statistics!B:F,5,FALSE)=0,"",VLOOKUP(L29,Statistics!B:F,5,FALSE)) -> QuickMove0110 | Q29: QuickMove0010
A30: 2105000000014 | B30: N등급 이상 장비 착용하기 | C30: 2200000000009 | D30: Always() | E30: TRUE
H31: 1 | I31: Mission.Guide.014 | J31: Mission.Guide.014 | K31: Equal | L31: EquipOverGrade | M31: Grade:N | N31: 1 | O31: Item(1040603005, 1) | Q31: QuickMove0170
A32: 2105000000015 | B32: 작전 보상 획득 | C32: 2200000000009 | D32: Always() | E32: TRUE
H33: 1 | I33: Mission.Guide.015 | J33: Mission.Guide.015 | K33: Equal | L33: IdleBattleReward | N33: 1 | O33: Item(1040102001, 150) | P33: =IF(VLOOKUP(L33,Statistics!B:F,5,FALSE)=0,"",VLOOKUP(L33,Statistics!B:F,5,FALSE)) -> QuickMove.IdleBattlePopup | Q33: QuickMove0010
A34: 2105000000016 | B34: 1-13 승리 | C34: 2200000000009 | D34: Always() | E34: TRUE
H35: 1 | I35: Mission.Guide.016 | J35: Mission.Guide.016 | K35: Equal | L35: StageClear | M35: StageId : 스테이지13 | N35: 1 | O35: Item(1040302001, 8000) | P35: =IF(VLOOKUP(L35,Statistics!B:F,5,FALSE)=0,"",VLOOKUP(L35,Statistics!B:F,5,FALSE)) -> QuickMove0010 | Q35: QuickMove0010
A36: 2105000000017 | B36: 캐릭터 3명 5레벨 강화 | C36: 2200000000009 | D36: Always() | E36: TRUE
H37: 1 | I37: Mission.Guide.017 | J37: Mission.Guide.017 | K37: Equal | L37: CharacterLevelReached | M37: Level : 5 | N37: 3 | O37: Item(1040408041, 20) | P37: =IF(VLOOKUP(L37,Statistics!B:F,5,FALSE)=0,"",VLOOKUP(L37,Statistics!B:F,5,FALSE)) -> QuickMove0250 | Q37: QuickMove0250
A38: 2105000000018 | B38: 스킬 레벨업 3회 | C38: 2200000000009 | D38: Always() | E38: TRUE
H39: 1 | I39: Mission.Guide.018 | J39: Mission.Guide.018 | K39: Equal | L39: SkillLvUp | N39: 3 | O39: Item(1040605301, 1) | P39: =IF(VLOOKUP(L39,Statistics!B:F,5,FALSE)=0,"",VLOOKUP(L39,Statistics!B:F,5,FALSE)) -> QuickMove0420 | Q39: QuickMove0420
A40: 2105000000019 | B40: 캐릭터 해산 하기 | C40: 2200000000009 | D40: Always() | E40: TRUE
...

Sheet #MissionCase.Guide
A1: Group | B1: #주석 | C1: Category | D1: NoticeProgress | E1: NoticeComplete | F1: Condition | G1: Ignore | H1: Step | I1: Name | J1: Desc | K1: Continuous | L1: MissionGoal | M1: GoalTarget | N1: GoalCount | O1: Reward | P1: # | Q1: QuickMove
A2: *long | B2: # | C2: $MissionCategory | D2: [dsl] | E2: bool | F2: [dsl] | G2: bool? | H2: int | I2: $Text | J2: $Text | K2: MissionChainingType | L2: StatisticsType | M2: {MissionGoalTargetType : string} | N2: int | O2: [dsl] | P2: # | Q2: $QuickMove?
A3: common | B3: # | C3: common | D3: server | E3: client | F3: common | G3: common | H3: common | I3: client | J3: client | K3: common | L3: common | M3: common | N3: common | O3: common | P3: # | Q3: client
A4: 2105000000001 | B4: 1-4 전투 승리 | C4: 2200000000009 | D4: Always() | E4: TRUE
H5: 1 | I5: Mission.Guide.Title.001 | J5: Mission.Guide.Desc.001 | K5: Equal | L5: StageClear | M5: StageId : 스테이지4 | N5: 1 | O5: Item(1040302001, 500) | P5: =IF(VLOOKUP(L5,Statistics!B:F,5,FALSE)=0,"",VLOOKUP(L5,Statistics!B:F,5,FALSE)) -> QuickMove0010 | Q5: QuickMove0010
A6: 2105000000002 | B6: 1명 캐릭터 3 레벨 업 | C6: 2200000000009 | D6: Always() | E6: TRUE
H7: 1 | I7: Mission.Guide.Title.002 | J7: Mission.Guide.Desc.002 | K7: Equal | L7: CharacterLevelReached | M7: Level : 3 | N7: 1 | O7: Item(1040101001, 1000) | P7: =IF(VLOOKUP(L7,Statistics!B:F,5,FALSE)=0,"",VLOOKUP(L7,Statistics!B:F,5,FALSE)) -> QuickMove0250 | Q7: QuickMove0250
A8: 2105000000003 | B8: 일일 과제 | C8: 2200000000009 | D8: Always() | E8: TRUE
H9: 1 | I9: Mission.Guide.Title.003 | J9: Mission.Guide.Desc.003 | K9: Equal | L9: MissionPoint | M9: MissionPointType : Daily | N9: 10 | O9: Item(1040501001, 1) | P9: =IF(VLOOKUP(L9,Statistics!B:F,5,FALSE)=0,"",VLOOKUP(L9,Statistics!B:F,5,FALSE)) | Q9: QuickMove0350
A10: 2105000000004 | B10: 1-5전투 승리 | C10: 2200000000009 | D10: Always() | E10: TRUE
B11: (5->4) | H11: 1 | I11: Mission.Guide.Title.004 | J11: Mission.Guide.Desc.004 | K11: Equal | L11: StageClear | M11: StageId : 스테이지5 | N11: 1 | O11: Item(1040101001, 2000) | P11: =IF(VLOOKUP(L11,Statistics!B:F,5,FALSE)=0,"",VLOOKUP(L11,Statistics!B:F,5,FALSE)) -> QuickMove0010 | Q11: QuickMove0010
A12: 2105000000005 | B12: 앰브로시아 영입 | C12: 2200000000009 | D12: Always() | E12: TRUE
B13: (6->5) | H13: 1 | I13: Mission.Guide.Title.005 | J13: Mission.Guide.Desc.005 | K13: Equal | L13: CharacterPossess | M13: CharacterId:1010920004 | N13: 1 | O13: Item(1040102001, 30) | P13: =IF(VLOOKUP(L13,Statistics!B:F,5,FALSE)=0,"",VLOOKUP(L13,Statistics!B:F,5,FALSE)) -> QuickMove0110 | Q13: QuickMove0110
A14: 2105000000006 | B14: 1-7전투 승리 | C14: 2200000000009 | D14: Always() | E14: TRUE
B15: (7->6) | H15: 1 | I15: Mission.Guide.Title.006 | J15: Mission.Guide.Desc.006 | K15: Equal | L15: StageClear | M15: StageId : 스테이지7 | N15: 1 | O15: Item(1040501001, 1) | P15: =IF(VLOOKUP(L15,Statistics!B:F,5,FALSE)=0,"",VLOOKUP(L15,Statistics!B:F,5,FALSE)) -> QuickMove0010 | Q15: QuickMove0010
A16: 2105000000007 | B16: 캐릭터 5명 3레벨 강화 | C16: 2200000000009 | D16: Always() | E16: TRUE
B17: (신규) | H17: 1 | I17: Mission.Guide.Title.007 | J17: Mission.Guide.Desc.007 | K17: Equal | L17: CharacterLevelReached | M17: Level : 3 | N17: 5 | O17: Item(1040302001, 2000) | P17: =IF(VLOOKUP(L17,Statistics!B:F,5,FALSE)=0,"",VLOOKUP(L17,Statistics!B:F,5,FALSE)) -> QuickMove0250 | Q17: QuickMove0250
A18: 2105000000008 | B18: 작전 보상 획득 | C18: 2200000000009 | D18: Always() | E18: TRUE
B19: (10->8) | H19: 1 | I19: Mission.Guide.Title.008 | J19: Mission.Guide.Desc.008 | K19: Equal | L19: IdleBattleReward | N19: 1 | O19: Item(1040102001, 30) | P19: =IF(VLOOKUP(L19,Statistics!B:F,5,FALSE)=0,"",VLOOKUP(L19,Statistics!B:F,5,FALSE)) -> QuickMove.IdleBattlePopup | Q19: QuickMove.IdleBattlePopup
A20: 2105000000009 | B20: 동기화 시키기 | C20: 2200000000009 | D20: Always() | E20: TRUE
B21: (20->9) | H21: 1 | I21: Mission.Guide.Title.009 | J21: Mission.Guide.Desc.009 | K21: Equal | L21: TutorialClear | M21: TutorialId:3100000033 | N21: 1 | O21: Item(1040605001, 1) | P21: =IF(VLOOKUP(L21,Statistics!B:F,5,FALSE)=0,"",VLOOKUP(L21,Statistics!B:F,5,FALSE)) -> #N/A | Q21: QuickMove0570
A22: 2105000000010 | B22: 캐릭터 1명 5레벨 강화 | C22: 2200000000009 | D22: Always() | E22: TRUE
B23: (8->10) | H23: 1 | I23: Mission.Guide.Title.010 | J23: Mission.Guide.Desc.010 | K23: Equal | L23: CharacterLevelReached | M23: Level : 5 | N23: 1 | O23: Item(1040501001, 1) | P23: =IF(VLOOKUP(L23,Statistics!B:F,5,FALSE)=0,"",VLOOKUP(L23,Statistics!B:F,5,FALSE)) -> QuickMove0250 | Q23: QuickMove0250
A24: 2105000000011 | B24: 스킬 레벨업 | C24: 2200000000009 | D24: Always() | E24: TRUE
B25: (9->11) | H25: 1 | I25: Mission.Guide.Title.011 | J25: Mission.Guide.Desc.011 | K25: Equal | L25: SkillLvUp | N25: 1 | O25: Item(1040102001, 30) | P25: =IF(VLOOKUP(L25,Statistics!B:F,5,FALSE)=0,"",VLOOKUP(L25,Statistics!B:F,5,FALSE)) -> QuickMove0420 | Q25: QuickMove0420
A26: 2105000000012 | B26: 1-11 전투 승리 | C26: 2200000000009 | D26: Always() | E26: TRUE
B27: (11->12) | H27: 1 | I27: Mission.Guide.Title.012 | J27: Mission.Guide.Desc.012 | K27: Equal | L27: StageClear | M27: StageId : 스테이지11 | N27: 1 | O27: Equipment(1020101002) | P27: =IF(VLOOKUP(L27,Statistics!B:F,5,FALSE)=0,"",VLOOKUP(L27,Statistics!B:F,5,FALSE)) -> QuickMove0010 | Q27: QuickMove0010
A28: 2105000000013 | B28: 장비 착용하기 | C28: 2200000000009 | D28: Always() | E28: TRUE
B29: (12->13) | H29: 1 | I29: Mission.Guide.Title.013 | J29: Mission.Guide.Desc.013 | K29: Equal | L29: ItemEquip | N29: 1 | O29: Item(1040102001, 30) | P29: =IF(VLOOKUP(L29,Statistics!B:F,5,FALSE)=0,"",VLOOKUP(L29,Statistics!B:F,5,FALSE)) -> QuickMove0170 | Q29: QuickMove0170
A30: 2105000000014 | B30: 1-14 전투 승리 | C30: 2200000000009 | D30: Always() | E30: TRUE
B31: (13->14) | H31: 1 | I31: Mission.Guide.Title.014 | J31: Mission.Guide.Desc.014 | K31: Equal | L31: StageClear | M31: StageId : 스테이지14 | N31: 1 | O31: Item(1040501001, 2) | P31: =IF(VLOOKUP(L31,Statistics!B:F,5,FALSE)=0,"",VLOOKUP(L31,Statistics!B:F,5,FALSE)) -> QuickMove0010 | Q31: QuickMove0010
A32: 2105000000015 | B32: 캐릭터 5명 5레벨 강화 | C32: 2200000000009 | D32: Always() | E32: TRUE
B33: (14->15) | H33: 1 | I33: Mission.Guide.Title.015 | J33: Mission.Guide.Desc.015 | K33: Equal | L33: CharacterLevelReached | M33: Level : 5 | N33: 5 | O33: Item(1040102001, 100) | P33: =IF(VLOOKUP(L33,Statistics!B:F,5,FALSE)=0,"",VLOOKUP(L33,Statistics!B:F,5,FALSE)) -> QuickMove0250 | Q33: QuickMove0250
A34: 2105000000016 | B34: 스킬 레벨업 3회 | C34: 2200000000009 | D34: Always() | E34: TRUE
B35: (15->16) | H35: 1 | I35: Mission.Guide.Title.016 | J35: Mission.Guide.Desc.016 | K35: Equal | L35: SkillLvUp | N35: 3 | O35: Item(1040605201, 1) | P35: =IF(VLOOKUP(L35,Statistics!B:F,5,FALSE)=0,"",VLOOKUP(L35,Statistics!B:F,5,FALSE)) -> QuickMove0420 | Q35: QuickMove0420
A36: 2105000000017 | B36: 1-16 전투 승리 | C36: 2200000000009 | D36: Always() | E36: TRUE
B37: (16->17) | H37: 1 | I37: Mission.Guide.Title.017 | J37: Mission.Guide.Desc.017 | K37: Equal | L37: StageClear | M37: StageId : 스테이지16 | N37: 1 | O37: Item(1040302001, 4000) | P37: =IF(VLOOKUP(L37,Statistics!B:F,5,FALSE)=0,"",VLOOKUP(L37,Statistics!B:F,5,FALSE)) -> QuickMove0010 | Q37: QuickMove0010
A38: 2105000000018 | B38: 세라펄사 | C38: 2200000000009 | D38: Always() | E38: TRUE
B39: (17->18) | H39: 1 | I39: Mission.Guide.Title.018 | J39: Mission.Guide.Desc.018 | K39: Equal | L39: CharacterPossess | M39: CharacterId:1010920002 | N39: 1 | O39: Item(1040102001, 30) | P39: =IF(VLOOKUP(L39,Statistics!B:F,5,FALSE)=0,"",VLOOKUP(L39,Statistics!B:F,5,FALSE)) -> QuickMove0110 | Q39: QuickMove0560
A40: 2105000000019 | B40: 캐릭터 3명 7레벨 강화 | C40: 2200000000009 | D40: Always() | E40: TRUE
...

Sheet MissionCase.7Days
A1: Group | B1: #주석 | C1: Category | D1: NoticeProgress | E1: NoticeComplete | F1: Condition | G1: Ignore | H1: Step | I1: Name | J1: Desc | K1: Continuous | L1: MissionGoal | M1: GoalTarget | N1: GoalCount | O1: Reward | P1: QuickMove
A2: *long | B2: # | C2: $MissionCategory | D2: [dsl] | E2: bool | F2: [dsl] | G2: bool? | H2: int | I2: $Text | J2: $Text | K2: MissionChainingType | L2: StatisticsType | M2: {MissionGoalTargetType : string} | N2: int | O2: [dsl] | P2: $QuickMove?
A3: common | B3: # | C3: common | D3: server | E3: client | F3: common | G3: common | H3: common | I3: client | J3: client | K3: common | L3: common | M3: common | N3: common | O3: common | P3: client
A4: #1일차
A5: 2106000000000 | C5: 2200000000015 | D5: Always() | E5: TRUE
H6: 1 | I6: Mission.Name.Login.Normal | J6: 7Days.Mission.Deec.Dummy | K6: Equal | L6: Login | N6: 1 | O6: Item(1040102001,50) & MissionPoint(Event7Days1, 1)
A7: 2106000000001 | C7: 2200000000015 | D7: Always() | E7: TRUE
H8: 1 | I8: Mission.Name.CharacterLevelReached.15 | J8: 7Days.Mission.Deec.Dummy | K8: Equal | L8: CharacterLevelReached | M8: Level : 15 | N8: 5 | O8: Item(1040102001,50) & MissionPoint(Event7Days1, 1) | P8: QuickMove0250
