Workbook

Sheet Monster
A1: Id | B1: #기획 | C1: #기획 | D1: Name | E1: Type | F1: FactionGroudId | G1: Attackable | H1: Boss | I1: UseHpSlice | J1: Radius | K1: MoveValue | L1: NormalSkill1 | M1: NormalSkill2 | N1: NormalSkill3 | O1: Skill1 | P1: Skill2 | Q1: Skill3 | R1: Skill4 | S1: Skill5 | T1: UltimateSkill | U1: UltimateExSkill | V1: Left | W1: PrefabBattle | X1: PrefabSpine | Y1: Icon | Z1: UltimateTimeline | AA1: VictoryTimeline | AB1: DieSound | AC1: Scale | AD1: CriticalEffect | AE1: StartTimeline | AF1: EndTimeline | AG1: Attribute
A2: *long | B2: # | C2: # | D2: string | E2: ClassType | F2: $FactionGroup? | G2: bool | H2: bool | I2: bool | J2: int | K2: int | L2: $SkillGroup? | M2: $SkillGroup? | N2: $SkillGroup? | O2: $SkillGroup? | P2: $SkillGroup? | Q2: $SkillGroup? | R2: $SkillGroup? | S2: $SkillGroup? | T2: $SkillGroup? | U2: $SkillGroup? | V2: bool | W2: string | X2: string | Y2: string | Z2: string | AA2: string | AB2: string | AC2: float | AD2: string | AE2: string | AF2: string | AG2: AttributeType
A3: common | B3: #사용처 | C3: #리소스명 | D3: client | E3: common | F3: common | G3: common | H3: common | I3: client | J3: common | K3: common | L3: common | M3: common | N3: common | O3: common | P3: common | Q3: common | R3: common | S3: common | T3: common | U3: common | V3: client | W3: client | X3: client | Y3: client | Z3: client | AA3: client | AB3: client | AC3: client | AD3: client | AE3: common | AF3: common | AG3: common
A4: 1110201101 | B4: Sector01 | C4: 솔리드메카mk1 | D4: ="Monster.Name."&VLOOKUP($C4,'#Data'!$B$2:$J$344,2,FALSE) -> Monster.Name.solid_turretmk1_1 | E4: Attacker | F4: Fac_nul_ind | G4: TRUE | H4: =IF(OR(VLOOKUP($C4,'#Data'!$B$2:$J$344,4,FALSE)="보스",VLOOKUP($C4,'#Data'!$B$2:$J$344,4,FALSE)="중간"),TRUE,FALSE) -> FALSE | I4: =IF(OR(VLOOKUP($C4,'#Data'!$B$2:$J$344,4,FALSE)="보스",VLOOKUP($C4,'#Data'!$B$2:$J$344,4,FALSE)="중간"),TRUE,FALSE) -> FALSE | J4: 10 | K4: =VLOOKUP($A4,쿼리1[[ID]:[열1]],3,FALSE) -> 10 | L4: =$B4&"."&VLOOKUP($C4,'#Data'!$B$2:$J$344,2,FALSE)&".attack0"&RIGHT(L$1,1) -> Sector01.solid_turretmk1_1.attack01 | O4: Sector01.solid_turretmk1_1.skill01 | V4: FALSE | W4: ="Character/Prefabs/"&VLOOKUP($C4,'#Data'!$B$3:$I$344,8,FALSE) -> Character/Prefabs/m_s_attacker_solid_turretmk1_1 | Y4: =VLOOKUP($C4,'#Data'!$B$3:$I$344,8,FALSE) -> m_s_attacker_solid_turretmk1_1 | AC4: 0.7 | AG4: AttributeNone
A5: 1110201102 | B5: Sector01 | C5: 터렛프로토 | D5: ="Monster.Name."&VLOOKUP($C5,'#Data'!$B$2:$J$344,2,FALSE) -> Monster.Name.spider_turret_prototype_1 | E5: Ranger | F5: Fac_nul_ind | G5: TRUE | H5: =IF(OR(VLOOKUP($C5,'#Data'!$B$2:$J$344,4,FALSE)="보스",VLOOKUP($C5,'#Data'!$B$2:$J$344,4,FALSE)="중간"),TRUE,FALSE) -> FALSE | I5: =IF(OR(VLOOKUP($C5,'#Data'!$B$2:$J$344,4,FALSE)="보스",VLOOKUP($C5,'#Data'!$B$2:$J$344,4,FALSE)="중간"),TRUE,FALSE) -> FALSE | J5: 10 | K5: =VLOOKUP($A5,쿼리1[[ID]:[열1]],3,FALSE) -> 30 | L5: =$B5&"."&VLOOKUP($C5,'#Data'!$B$2:$J$344,2,FALSE)&".attack0"&RIGHT(L$1,1) -> Sector01.spider_turret_prototype_1.attack01 | O5: Sector01.spider_turret_prototype_1.skill01 | V5: FALSE | W5: ="Character/Prefabs/"&VLOOKUP($C5,'#Data'!$B$3:$I$344,8,FALSE) -> Character/Prefabs/m_s_ranger_spider_turret_prototype_1 | Y5: =VLOOKUP($C5,'#Data'!$B$3:$I$344,8,FALSE) -> m_s_ranger_spider_turret_prototype_1 | AC5: 0.6 | AG5: AttributeNone
A6: 1110201103 | B6: Sector01 | C6: 일렉트릭드론 | D6: ="Monster.Name."&VLOOKUP($C6,'#Data'!$B$2:$J$344,2,FALSE) -> Monster.Name.electric_drone_1 | E6: Attacker | F6: Fac_nul_ind | G6: TRUE | H6: =IF(OR(VLOOKUP($C6,'#Data'!$B$2:$J$344,4,FALSE)="보스",VLOOKUP($C6,'#Data'!$B$2:$J$344,4,FALSE)="중간"),TRUE,FALSE) -> FALSE | I6: =IF(OR(VLOOKUP($C6,'#Data'!$B$2:$J$344,4,FALSE)="보스",VLOOKUP($C6,'#Data'!$B$2:$J$344,4,FALSE)="중간"),TRUE,FALSE) -> FALSE | J6: 10 | K6: =VLOOKUP($A6,쿼리1[[ID]:[열1]],3,FALSE) -> 10 | L6: =$B6&"."&VLOOKUP($C6,'#Data'!$B$2:$J$344,2,FALSE)&".attack0"&RIGHT(L$1,1) -> Sector01.electric_drone_1.attack01 | O6: Sector01.electric_drone_1.skill01 | V6: FALSE | W6: ="Character/Prefabs/"&VLOOKUP($C6,'#Data'!$B$3:$I$344,8,FALSE) -> Character/Prefabs/m_s_attacker_electric_drone_1 | Y6: =VLOOKUP($C6,'#Data'!$B$3:$I$344,8,FALSE) -> m_s_attacker_electric_drone_1 | AC6: 0.7 | AG6: AttributeNone
A7: 1110201104 | B7: Sector01 | C7: 재밍드론 | D7: ="Monster.Name."&VLOOKUP($C7,'#Data'!$B$2:$J$344,2,FALSE) -> Monster.Name.jamming_drone_1 | E7: Ranger | F7: Fac_nul_ind | G7: TRUE | H7: =IF(OR(VLOOKUP($C7,'#Data'!$B$2:$J$344,4,FALSE)="보스",VLOOKUP($C7,'#Data'!$B$2:$J$344,4,FALSE)="중간"),TRUE,FALSE) -> FALSE | I7: =IF(OR(VLOOKUP($C7,'#Data'!$B$2:$J$344,4,FALSE)="보스",VLOOKUP($C7,'#Data'!$B$2:$J$344,4,FALSE)="중간"),TRUE,FALSE) -> FALSE | J7: 10 | K7: =VLOOKUP($A7,쿼리1[[ID]:[열1]],3,FALSE) -> 10 | L7: =$B7&"."&VLOOKUP($C7,'#Data'!$B$2:$J$344,2,FALSE)&".attack0"&RIGHT(L$1,1) -> Sector01.jamming_drone_1.attack01 | O7: Sector01.jamming_drone_1.skill01 | V7: FALSE | W7: ="Character/Prefabs/"&VLOOKUP($C7,'#Data'!$B$3:$I$344,8,FALSE) -> Character/Prefabs/m_s_ranger_jamming_drone_1 | Y7: =VLOOKUP($C7,'#Data'!$B$3:$I$344,8,FALSE) -> m_s_ranger_jamming_drone_1 | AC7: 0.6 | AG7: AttributeNone
A8: 1110201105 | B8: Sector01 | C8: 트루퍼라이플 | D8: ="Monster.Name."&VLOOKUP($C8,'#Data'!$B$2:$J$344,2,FALSE) -> Monster.Name.trooper_sniper_1 | E8: Ranger | F8: Fac_nul_ind | G8: TRUE | H8: =IF(OR(VLOOKUP($C8,'#Data'!$B$2:$J$344,4,FALSE)="보스",VLOOKUP($C8,'#Data'!$B$2:$J$344,4,FALSE)="중간"),TRUE,FALSE) -> FALSE | I8: =IF(OR(VLOOKUP($C8,'#Data'!$B$2:$J$344,4,FALSE)="보스",VLOOKUP($C8,'#Data'!$B$2:$J$344,4,FALSE)="중간"),TRUE,FALSE) -> FALSE | J8: 10 | K8: =VLOOKUP($A8,쿼리1[[ID]:[열1]],3,FALSE) -> 10 | L8: =$B8&"."&VLOOKUP($C8,'#Data'!$B$2:$J$344,2,FALSE)&".attack0"&RIGHT(L$1,1) -> Sector01.trooper_sniper_1.attack01 | O8: =$B8&"."&VLOOKUP($C8,'#Data'!$B$2:$J$344,2,FALSE)&".skill0"&RIGHT(O$1,1) -> Sector01.trooper_sniper_1.skill01 | P8: Sector01.trooper_sniper_1.skill02 | V8: FALSE | W8: ="Character/Prefabs/"&VLOOKUP($C8,'#Data'!$B$3:$I$344,8,FALSE) -> Character/Prefabs/m_m_ranger_trooper_sniper_1 | Y8: =VLOOKUP($C8,'#Data'!$B$3:$I$344,8,FALSE) -> m_m_ranger_trooper_sniper_1 | AC8: 0.8 | AG8: AttributeNone
A9: 1110201106 | B9: Sector01 | C9: 트루퍼쉴드 | D9: ="Monster.Name."&VLOOKUP($C9,'#Data'!$B$2:$J$344,2,FALSE) -> Monster.Name.trooper_guard_1 | E9: Tanker | F9: Fac_nul_ind | G9: TRUE | H9: =IF(OR(VLOOKUP($C9,'#Data'!$B$2:$J$344,4,FALSE)="보스",VLOOKUP($C9,'#Data'!$B$2:$J$344,4,FALSE)="중간"),TRUE,FALSE) -> FALSE | I9: =IF(OR(VLOOKUP($C9,'#Data'!$B$2:$J$344,4,FALSE)="보스",VLOOKUP($C9,'#Data'!$B$2:$J$344,4,FALSE)="중간"),TRUE,FALSE) -> FALSE | J9: 10 | K9: =VLOOKUP($A9,쿼리1[[ID]:[열1]],3,FALSE) -> 10 | L9: =$B9&"."&VLOOKUP($C9,'#Data'!$B$2:$J$344,2,FALSE)&".attack0"&RIGHT(L$1,1) -> Sector01.trooper_guard_1.attack01 | O9: =$B9&"."&VLOOKUP($C9,'#Data'!$B$2:$J$344,2,FALSE)&".skill0"&RIGHT(O$1,1) -> Sector01.trooper_guard_1.skill01 | P9: Sector01.trooper_guard_1.skill02 | V9: FALSE | W9: ="Character/Prefabs/"&VLOOKUP($C9,'#Data'!$B$3:$I$344,8,FALSE) -> Character/Prefabs/m_m_tanker_trooper_guard_1 | Y9: =VLOOKUP($C9,'#Data'!$B$3:$I$344,8,FALSE) -> m_m_tanker_trooper_guard_1 | AC9: 0.8 | AG9: AttributeNone
A10: 1110201107 | B10: Sector01 | C10: 트루퍼건틀릿 | D10: ="Monster.Name."&VLOOKUP($C10,'#Data'!$B$2:$J$344,2,FALSE) -> Monster.Name.trooper_champion_1 | E10: Attacker | F10: Fac_nul_ind | G10: TRUE | H10: =IF(OR(VLOOKUP($C10,'#Data'!$B$2:$J$344,4,FALSE)="보스",VLOOKUP($C10,'#Data'!$B$2:$J$344,4,FALSE)="중간"),TRUE,FALSE) -> FALSE | I10: =IF(OR(VLOOKUP($C10,'#Data'!$B$2:$J$344,4,FALSE)="보스",VLOOKUP($C10,'#Data'!$B$2:$J$344,4,FALSE)="중간"),TRUE,FALSE) -> FALSE | J10: 10 | K10: =VLOOKUP($A10,쿼리1[[ID]:[열1]],3,FALSE) -> 10 | L10: =$B10&"."&VLOOKUP($C10,'#Data'!$B$2:$J$344,2,FALSE)&".attack0"&RIGHT(L$1,1) -> Sector01.trooper_champion_1.attack01 | O10: =$B10&"."&VLOOKUP($C10,'#Data'!$B$2:$J$344,2,FALSE)&".skill0"&RIGHT(O$1,1) -> Sector01.trooper_champion_1.skill01 | P10: Sector01.trooper_champion_1.skill02 | V10: FALSE | W10: ="Character/Prefabs/"&VLOOKUP($C10,'#Data'!$B$3:$I$344,8,FALSE) -> Character/Prefabs/m_m_attacker_trooper_champion_1 | Y10: =VLOOKUP($C10,'#Data'!$B$3:$I$344,8,FALSE) -> m_m_attacker_trooper_champion_1 | AC10: 0.8 | AG10: AttributeNone
A11: 1110201108 | B11: Sector01 | C11: 트루퍼런처 | D11: ="Monster.Name."&VLOOKUP($C11,'#Data'!$B$2:$J$344,2,FALSE) -> Monster.Name.trooper_demolisher_1 | E11: Ranger | F11: Fac_nul_ind | G11: TRUE | H11: =IF(OR(VLOOKUP($C11,'#Data'!$B$2:$J$344,4,FALSE)="보스",VLOOKUP($C11,'#Data'!$B$2:$J$344,4,FALSE)="중간"),TRUE,FALSE) -> FALSE | I11: =IF(OR(VLOOKUP($C11,'#Data'!$B$2:$J$344,4,FALSE)="보스",VLOOKUP($C11,'#Data'!$B$2:$J$344,4,FALSE)="중간"),TRUE,FALSE) -> FALSE | J11: 10 | K11: =VLOOKUP($A11,쿼리1[[ID]:[열1]],3,FALSE) -> 10 | L11: =$B11&"."&VLOOKUP($C11,'#Data'!$B$2:$J$344,2,FALSE)&".attack0"&RIGHT(L$1,1) -> Sector01.trooper_demolisher_1.attack01 | O11: =$B11&"."&VLOOKUP($C11,'#Data'!$B$2:$J$344,2,FALSE)&".skill0"&RIGHT(O$1,1) -> Sector01.trooper_demolisher_1.skill01 | P11: Sector01.trooper_demolisher_1.skill02 | V11: FALSE | W11: ="Character/Prefabs/"&VLOOKUP($C11,'#Data'!$B$3:$I$344,8,FALSE) -> Character/Prefabs/m_m_ranger_trooper_demolisher_1 | Y11: =VLOOKUP($C11,'#Data'!$B$3:$I$344,8,FALSE) -> m_m_ranger_trooper_demolisher_1 | AC11: 0.8 | AG11: AttributeNone
A12: 1110201109 | B12: Sector01 | C12: 트루퍼플레임 | D12: ="Monster.Name."&VLOOKUP($C12,'#Data'!$B$2:$J$344,2,FALSE) -> Monster.Name.trooper_inferno_1 | E12: Attacker | F12: Fac_nul_ind | G12: TRUE | H12: =IF(OR(VLOOKUP($C12,'#Data'!$B$2:$J$344,4,FALSE)="보스",VLOOKUP($C12,'#Data'!$B$2:$J$344,4,FALSE)="중간"),TRUE,FALSE) -> FALSE | I12: =IF(OR(VLOOKUP($C12,'#Data'!$B$2:$J$344,4,FALSE)="보스",VLOOKUP($C12,'#Data'!$B$2:$J$344,4,FALSE)="중간"),TRUE,FALSE) -> FALSE | J12: 10 | K12: =VLOOKUP($A12,쿼리1[[ID]:[열1]],3,FALSE) -> 10 | L12: =$B12&"."&VLOOKUP($C12,'#Data'!$B$2:$J$344,2,FALSE)&".attack0"&RIGHT(L$1,1) -> Sector01.trooper_inferno_1.attack01 | O12: =$B12&"."&VLOOKUP($C12,'#Data'!$B$2:$J$344,2,FALSE)&".skill0"&RIGHT(O$1,1) -> Sector01.trooper_inferno_1.skill01 | P12: Sector01.trooper_inferno_1.skill02 | V12: FALSE | W12: ="Character/Prefabs/"&VLOOKUP($C12,'#Data'!$B$3:$I$344,8,FALSE) -> Character/Prefabs/m_m_attacker_trooper_inferno_1 | Y12: =VLOOKUP($C12,'#Data'!$B$3:$I$344,8,FALSE) -> m_m_attacker_trooper_inferno_1 | AC12: 0.8 | AG12: AttributeNone
A13: 1110201110 | B13: Sector01 | C13: 솔리드메카mk1베리 | D13: ="Monster.Name."&VLOOKUP($C13,'#Data'!$B$2:$J$344,2,FALSE) -> Monster.Name.solid_turretmk1_2 | E13: Attacker | F13: Fac_nul_ind | G13: TRUE | H13: =IF(OR(VLOOKUP($C13,'#Data'!$B$2:$J$344,4,FALSE)="보스",VLOOKUP($C13,'#Data'!$B$2:$J$344,4,FALSE)="중간"),TRUE,FALSE) -> FALSE | I13: =IF(OR(VLOOKUP($C13,'#Data'!$B$2:$J$344,4,FALSE)="보스",VLOOKUP($C13,'#Data'!$B$2:$J$344,4,FALSE)="중간"),TRUE,FALSE) -> FALSE | J13: 10 | K13: =VLOOKUP($A13,쿼리1[[ID]:[열1]],3,FALSE) -> 10 | L13: Sector01.solid_turretmk1_1.attack01 | O13: Sector01.solid_turretmk1_1.skill01 | V13: FALSE | W13: ="Character/Prefabs/"&VLOOKUP($C13,'#Data'!$B$3:$I$344,8,FALSE) -> Character/Prefabs/m_s_attacker_solid_turretmk1_2 | Y13: =VLOOKUP($C13,'#Data'!$B$3:$I$344,8,FALSE) -> m_s_attacker_solid_turretmk1_2 | AC13: 0.7 | AG13: AttributeNone
A14: 1110201111 | B14: Sector01 | C14: 터렛프로토베리 | D14: ="Monster.Name."&VLOOKUP($C14,'#Data'!$B$2:$J$344,2,FALSE) -> Monster.Name.spider_turret_prototype_2 | E14: Ranger | F14: Fac_nul_ind | G14: TRUE | H14: =IF(OR(VLOOKUP($C14,'#Data'!$B$2:$J$344,4,FALSE)="보스",VLOOKUP($C14,'#Data'!$B$2:$J$344,4,FALSE)="중간"),TRUE,FALSE) -> FALSE | I14: =IF(OR(VLOOKUP($C14,'#Data'!$B$2:$J$344,4,FALSE)="보스",VLOOKUP($C14,'#Data'!$B$2:$J$344,4,FALSE)="중간"),TRUE,FALSE) -> FALSE | J14: 10 | K14: =VLOOKUP($A14,쿼리1[[ID]:[열1]],3,FALSE) -> 30 | L14: Sector01.spider_turret_prototype_1.attack01 | O14: Sector01.spider_turret_prototype_1.skill01 | V14: FALSE | W14: ="Character/Prefabs/"&VLOOKUP($C14,'#Data'!$B$3:$I$344,8,FALSE) -> Character/Prefabs/m_s_ranger_spider_turret_prototype_2 | Y14: =VLOOKUP($C14,'#Data'!$B$3:$I$344,8,FALSE) -> m_s_ranger_spider_turret_prototype_2 | AC14: 0.6 | AG14: AttributeNone
A15: 1110201112 | B15: Sector01 | C15: 일렉트릭드론베리 | D15: ="Monster.Name."&VLOOKUP($C15,'#Data'!$B$2:$J$344,2,FALSE) -> Monster.Name.electric_drone_2 | E15: Attacker | F15: Fac_nul_ind | G15: TRUE | H15: =IF(OR(VLOOKUP($C15,'#Data'!$B$2:$J$344,4,FALSE)="보스",VLOOKUP($C15,'#Data'!$B$2:$J$344,4,FALSE)="중간"),TRUE,FALSE) -> FALSE | I15: =IF(OR(VLOOKUP($C15,'#Data'!$B$2:$J$344,4,FALSE)="보스",VLOOKUP($C15,'#Data'!$B$2:$J$344,4,FALSE)="중간"),TRUE,FALSE) -> FALSE | J15: 10 | K15: =VLOOKUP($A15,쿼리1[[ID]:[열1]],3,FALSE) -> 10 | L15: Sector01.electric_drone_1.attack01 | O15: Sector01.electric_drone_1.skill01 | V15: FALSE | W15: Character/Prefabs/m_s_attacker_electric_drone_5 | Y15: m_s_attacker_electric_drone_5 | AC15: 0.7 | AG15: AttributeNone
A16: 1110201113 | B16: Sector01 | C16: 재밍드론베리 | D16: ="Monster.Name."&VLOOKUP($C16,'#Data'!$B$2:$J$344,2,FALSE) -> Monster.Name.jamming_drone_2 | E16: Ranger | F16: Fac_nul_ind | G16: TRUE | H16: =IF(OR(VLOOKUP($C16,'#Data'!$B$2:$J$344,4,FALSE)="보스",VLOOKUP($C16,'#Data'!$B$2:$J$344,4,FALSE)="중간"),TRUE,FALSE) -> FALSE | I16: =IF(OR(VLOOKUP($C16,'#Data'!$B$2:$J$344,4,FALSE)="보스",VLOOKUP($C16,'#Data'!$B$2:$J$344,4,FALSE)="중간"),TRUE,FALSE) -> FALSE | J16: 10 | K16: =VLOOKUP($A16,쿼리1[[ID]:[열1]],3,FALSE) -> 10 | L16: Sector01.jamming_drone_1.attack01 | O16: Sector01.jamming_drone_1.skill01 | V16: FALSE | W16: Character/Prefabs/m_s_ranger_jamming_drone_4 | Y16: m_s_ranger_jamming_drone_4 | AC16: 0.6 | AG16: AttributeNone
A17: 1110201114 | B17: Sector01 | C17: 트루퍼라이플베리 | D17: ="Monster.Name."&VLOOKUP($C17,'#Data'!$B$2:$J$344,2,FALSE) -> Monster.Name.trooper_sniper_2 | E17: Ranger | F17: Fac_nul_ind | G17: TRUE | H17: =IF(OR(VLOOKUP($C17,'#Data'!$B$2:$J$344,4,FALSE)="보스",VLOOKUP($C17,'#Data'!$B$2:$J$344,4,FALSE)="중간"),TRUE,FALSE) -> FALSE | I17: =IF(OR(VLOOKUP($C17,'#Data'!$B$2:$J$344,4,FALSE)="보스",VLOOKUP($C17,'#Data'!$B$2:$J$344,4,FALSE)="중간"),TRUE,FALSE) -> FALSE | J17: 10 | K17: =VLOOKUP($A17,쿼리1[[ID]:[열1]],3,FALSE) -> 10 | L17: Sector01.trooper_sniper_1.attack01 | O17: Sector01.trooper_sniper_1.skill01 | P17: Sector01.trooper_sniper_1.skill02 | V17: FALSE | W17: ="Character/Prefabs/"&VLOOKUP($C17,'#Data'!$B$3:$I$344,8,FALSE) -> Character/Prefabs/m_m_ranger_trooper_sniper_2 | Y17: =VLOOKUP($C17,'#Data'!$B$3:$I$344,8,FALSE) -> m_m_ranger_trooper_sniper_2 | AC17: 0.8 | AG17: AttributeNone
A18: 1110201115 | B18: Sector01 | C18: 트루퍼쉴드베리 | D18: ="Monster.Name."&VLOOKUP($C18,'#Data'!$B$2:$J$344,2,FALSE) -> Monster.Name.trooper_guard_2 | E18: Tanker | F18: Fac_nul_ind | G18: TRUE | H18: =IF(OR(VLOOKUP($C18,'#Data'!$B$2:$J$344,4,FALSE)="보스",VLOOKUP($C18,'#Data'!$B$2:$J$344,4,FALSE)="중간"),TRUE,FALSE) -> FALSE | I18: =IF(OR(VLOOKUP($C18,'#Data'!$B$2:$J$344,4,FALSE)="보스",VLOOKUP($C18,'#Data'!$B$2:$J$344,4,FALSE)="중간"),TRUE,FALSE) -> FALSE | J18: 10 | K18: =VLOOKUP($A18,쿼리1[[ID]:[열1]],3,FALSE) -> 10 | L18: Sector01.trooper_guard_1.attack01 | O18: Sector01.trooper_guard_1.skill01 | P18: Sector01.trooper_guard_1.skill02 | V18: FALSE | W18: ="Character/Prefabs/"&VLOOKUP($C18,'#Data'!$B$3:$I$344,8,FALSE) -> Character/Prefabs/m_m_tanker_trooper_guard_2 | Y18: =VLOOKUP($C18,'#Data'!$B$3:$I$344,8,FALSE) -> m_m_tanker_trooper_guard_2 | AC18: 0.8 | AG18: AttributeNone
A19: 1110201116 | B19: Sector01 | C19: 트루퍼건틀릿베리 | D19: ="Monster.Name."&VLOOKUP($C19,'#Data'!$B$2:$J$344,2,FALSE) -> Monster.Name.trooper_champion_2 | E19: Attacker | F19: Fac_nul_ind | G19: TRUE | H19: =IF(OR(VLOOKUP($C19,'#Data'!$B$2:$J$344,4,FALSE)="보스",VLOOKUP($C19,'#Data'!$B$2:$J$344,4,FALSE)="중간"),TRUE,FALSE) -> FALSE | I19: =IF(OR(VLOOKUP($C19,'#Data'!$B$2:$J$344,4,FALSE)="보스",VLOOKUP($C19,'#Data'!$B$2:$J$344,4,FALSE)="중간"),TRUE,FALSE) -> FALSE | J19: 10 | K19: =VLOOKUP($A19,쿼리1[[ID]:[열1]],3,FALSE) -> 10 | L19: Sector01.trooper_champion_1.attack01 | O19: Sector01.trooper_champion_1.skill01 | P19: Sector01.trooper_champion_1.skill02 | V19: FALSE | W19: ="Character/Prefabs/"&VLOOKUP($C19,'#Data'!$B$3:$I$344,8,FALSE) -> Character/Prefabs/m_m_attacker_trooper_champion_2 | Y19: =VLOOKUP($C19,'#Data'!$B$3:$I$344,8,FALSE) -> m_m_attacker_trooper_champion_2 | AC19: 0.8 | AG19: AttributeNone
A20: 1110201117 | B20: Sector01 | C20: 트루퍼런처베리 | D20: ="Monster.Name."&VLOOKUP($C20,'#Data'!$B$2:$J$344,2,FALSE) -> Monster.Name.trooper_demolisher_2 | E20: Ranger | F20: Fac_nul_ind | G20: TRUE | H20: =IF(OR(VLOOKUP($C20,'#Data'!$B$2:$J$344,4,FALSE)="보스",VLOOKUP($C20,'#Data'!$B$2:$J$344,4,FALSE)="중간"),TRUE,FALSE) -> FALSE | I20: =IF(OR(VLOOKUP($C20,'#Data'!$B$2:$J$344,4,FALSE)="보스",VLOOKUP($C20,'#Data'!$B$2:$J$344,4,FALSE)="중간"),TRUE,FALSE) -> FALSE | J20: 10 | K20: =VLOOKUP($A20,쿼리1[[ID]:[열1]],3,FALSE) -> 10 | L20: Sector01.trooper_demolisher_1.attack01 | O20: Sector01.trooper_demolisher_1.skill01 | P20: Sector01.trooper_demolisher_1.skill02 | V20: FALSE | W20: ="Character/Prefabs/"&VLOOKUP($C20,'#Data'!$B$3:$I$344,8,FALSE) -> Character/Prefabs/m_m_ranger_trooper_demolisher_2 | Y20: =VLOOKUP($C20,'#Data'!$B$3:$I$344,8,FALSE) -> m_m_ranger_trooper_demolisher_2 | AC20: 0.8 | AG20: AttributeNone
A21: 1110201118 | B21: Sector01 | C21: 트루퍼플레임베리 | D21: ="Monster.Name."&VLOOKUP($C21,'#Data'!$B$2:$J$344,2,FALSE) -> Monster.Name.trooper_inferno_2 | E21: Attacker | F21: Fac_nul_ind | G21: TRUE | H21: =IF(OR(VLOOKUP($C21,'#Data'!$B$2:$J$344,4,FALSE)="보스",VLOOKUP($C21,'#Data'!$B$2:$J$344,4,FALSE)="중간"),TRUE,FALSE) -> FALSE | I21: =IF(OR(VLOOKUP($C21,'#Data'!$B$2:$J$344,4,FALSE)="보스",VLOOKUP($C21,'#Data'!$B$2:$J$344,4,FALSE)="중간"),TRUE,FALSE) -> FALSE | J21: 10 | K21: =VLOOKUP($A21,쿼리1[[ID]:[열1]],3,FALSE) -> 10 | L21: Sector01.trooper_inferno_1.attack01 | O21: Sector01.trooper_inferno_1.skill01 | P21: Sector01.trooper_inferno_1.skill02 | V21: FALSE | W21: ="Character/Prefabs/"&VLOOKUP($C21,'#Data'!$B$3:$I$344,8,FALSE) -> Character/Prefabs/m_m_attacker_trooper_inferno_2 | Y21: =VLOOKUP($C21,'#Data'!$B$3:$I$344,8,FALSE) -> m_m_attacker_trooper_inferno_2 | AC21: 0.8 | AG21: AttributeNone
A22: 1110201201 | B22: Sector01 | C22: 엑시큐서너베타 | D22: ="Monster.Name."&VLOOKUP($C22,'#Data'!$B$2:$J$344,2,FALSE) -> Monster.Name.labmecha_launcher_1 | E22: Ranger | F22: Fac_nul_ind | G22: TRUE | H22: =IF(OR(VLOOKUP($C22,'#Data'!$B$2:$J$344,4,FALSE)="보스",VLOOKUP($C22,'#Data'!$B$2:$J$344,4,FALSE)="중간"),TRUE,FALSE) -> TRUE | I22: =IF(OR(VLOOKUP($C22,'#Data'!$B$2:$J$344,4,FALSE)="보스",VLOOKUP($C22,'#Data'!$B$2:$J$344,4,FALSE)="중간"),TRUE,FALSE) -> TRUE | J22: 10 | K22: =VLOOKUP($A22,쿼리1[[ID]:[열1]],3,FALSE) -> 10 | L22: =$B22&"."&VLOOKUP($C22,'#Data'!$B$2:$J$344,2,FALSE)&".attack0"&RIGHT(L$1,1) -> Sector01.labmecha_launcher_1.attack01 | O22: =$B22&"."&VLOOKUP($C22,'#Data'!$B$2:$J$344,2,FALSE)&".skill0"&RIGHT(O$1,1) -> Sector01.labmecha_launcher_1.skill01 | P22: =$B22&"."&VLOOKUP($C22,'#Data'!$B$2:$J$344,2,FALSE)&".skill0"&RIGHT(P$1,1) -> Sector01.labmecha_launcher_1.skill02 | S22: Mid.Boss.Immun.orange | V22: FALSE | W22: ="Character/Prefabs/"&VLOOKUP($C22,'#Data'!$B$3:$I$344,8,FALSE) -> Character/Prefabs/m_m_ranger_labmecha_launcher_1 | Y22: =VLOOKUP($C22,'#Data'!$B$3:$I$344,8,FALSE) -> m_m_ranger_labmecha_launcher_1 | AC22: 0.7 | AG22: AttributeNone
A23: 1110201202 | B23: Sector01 | C23: 엑시큐서너알파 | D23: ="Monster.Name."&VLOOKUP($C23,'#Data'!$B$2:$J$344,2,FALSE) -> Monster.Name.harbor_crab_1 | E23: Tanker | F23: Fac_nul_ind | G23: TRUE | H23: =IF(OR(VLOOKUP($C23,'#Data'!$B$2:$J$344,4,FALSE)="보스",VLOOKUP($C23,'#Data'!$B$2:$J$344,4,FALSE)="중간"),TRUE,FALSE) -> TRUE | I23: =IF(OR(VLOOKUP($C23,'#Data'!$B$2:$J$344,4,FALSE)="보스",VLOOKUP($C23,'#Data'!$B$2:$J$344,4,FALSE)="중간"),TRUE,FALSE) -> TRUE | J23: 20 | K23: =VLOOKUP($A23,쿼리1[[ID]:[열1]],3,FALSE) -> 10 | L23: =$B23&"."&VLOOKUP($C23,'#Data'!$B$2:$J$344,2,FALSE)&".attack0"&RIGHT(L$1,1) -> Sector01.harbor_crab_1.attack01 | O23: =$B23&"."&VLOOKUP($C23,'#Data'!$B$2:$J$344,2,FALSE)&".skill0"&RIGHT(O$1,1) -> Sector01.harbor_crab_1.skill01 | P23: =$B23&"."&VLOOKUP($C23,'#Data'!$B$2:$J$344,2,FALSE)&".skill0"&RIGHT(P$1,1) -> Sector01.harbor_crab_1.skill02 | Q23: Sector01.harbor_crab_1.passive01 | S23: Mid.Boss.Immun.orange | V23: FALSE | W23: ="Character/Prefabs/"&VLOOKUP($C23,'#Data'!$B$3:$I$344,8,FALSE) -> Character/Prefabs/m_l_attacker_harbor_crab_1 | Y23: =VLOOKUP($C23,'#Data'!$B$3:$I$344,8,FALSE) -> m_l_attacker_harbor_crab_1 | AC23: 1 | AG23: AttributeNone
A24: 1110201203 | B24: Sector01 | C24: 엑시큐서너감마 | D24: ="Monster.Name."&VLOOKUP($C24,'#Data'!$B$2:$J$344,2,FALSE) -> Monster.Name.harbor_punch_1 | E24: Tanker | F24: Fac_nul_ind | G24: TRUE | H24: =IF(OR(VLOOKUP($C24,'#Data'!$B$2:$J$344,4,FALSE)="보스",VLOOKUP($C24,'#Data'!$B$2:$J$344,4,FALSE)="중간"),TRUE,FALSE) -> TRUE | I24: =IF(OR(VLOOKUP($C24,'#Data'!$B$2:$J$344,4,FALSE)="보스",VLOOKUP($C24,'#Data'!$B$2:$J$344,4,FALSE)="중간"),TRUE,FALSE) -> TRUE | J24: 20 | K24: =VLOOKUP($A24,쿼리1[[ID]:[열1]],3,FALSE) -> 10 | L24: =$B24&"."&VLOOKUP($C24,'#Data'!$B$2:$J$344,2,FALSE)&".attack0"&RIGHT(L$1,1) -> Sector01.harbor_punch_1.attack01 | O24: =$B24&"."&VLOOKUP($C24,'#Data'!$B$2:$J$344,2,FALSE)&".skill0"&RIGHT(O$1,1) -> Sector01.harbor_punch_1.skill01 | P24: =$B24&"."&VLOOKUP($C24,'#Data'!$B$2:$J$344,2,FALSE)&".skill0"&RIGHT(P$1,1) -> Sector01.harbor_punch_1.skill02 | S24: Mid.Boss.Immun.orange | V24: FALSE | W24: ="Character/Prefabs/"&VLOOKUP($C24,'#Data'!$B$3:$I$344,8,FALSE) -> Character/Prefabs/m_l_tanker_harbor_punch_1 | Y24: =VLOOKUP($C24,'#Data'!$B$3:$I$344,8,FALSE) -> m_l_tanker_harbor_punch_1 | AC24: 1 | AG24: AttributeNone
A25: 1110201301 | B25: Sector02 | C25: 카산드라 | D25: ="Monster.Name."&VLOOKUP($C25,'#Data'!$B$2:$J$344,2,FALSE) -> Monster.Name.cassandra_1 | E25: None | F25: Fac_nul_ind | G25: TRUE | H25: =IF(OR(VLOOKUP($C25,'#Data'!$B$2:$J$344,4,FALSE)="보스",VLOOKUP($C25,'#Data'!$B$2:$J$344,4,FALSE)="중간"),TRUE,FALSE) -> TRUE | I25: TRUE | J25: 30 | K25: =VLOOKUP($A25,쿼리1[[ID]:[열1]],3,FALSE) -> 10 | L25: =$B25&"."&VLOOKUP($C25,'#Data'!$B$2:$J$344,2,FALSE)&".attack0"&RIGHT(L$1,1) -> Sector02.cassandra_1.attack01 | O25: =$B25&"."&VLOOKUP($C25,'#Data'!$B$2:$J$344,2,FALSE)&".skill0"&RIGHT(O$1,1) -> Sector02.cassandra_1.skill01 | P25: =$B25&"."&VLOOKUP($C25,'#Data'!$B$2:$J$344,2,FALSE)&".skill0"&RIGHT(P$1,1) -> Sector02.cassandra_1.skill02 | Q25: Sector02.cassandra_1.passive01 | S25: Boss.Common.Immun | V25: FALSE | W25: ="Character/Prefabs/"&VLOOKUP($C25,'#Data'!$B$3:$I$344,8,FALSE) -> Character/Prefabs/m_boss_ranger_cassandra_1 | Y25: =VLOOKUP($C25,'#Data'!$B$3:$I$344,8,FALSE) -> m_boss_ranger_cassandra_1 | AC25: 0.9 | AE25: Character/Timeline/02_MON/cassandra/appearance | AF25: Character/Timeline/02_MON/cassandra/die | AG25: AttributeNone
A26: 1110201302 | B26: Sector02 | C26: 강화카산드라 | D26: ="Monster.Name."&VLOOKUP($C26,'#Data'!$B$2:$J$344,2,FALSE) -> Monster.Name.cassandra_2 | E26: None | F26: Fac_nul_ind | G26: TRUE | H26: =IF(OR(VLOOKUP($C26,'#Data'!$B$2:$J$344,4,FALSE)="보스",VLOOKUP($C26,'#Data'!$B$2:$J$344,4,FALSE)="중간"),TRUE,FALSE) -> TRUE | I26: TRUE | J26: 30 | K26: =VLOOKUP($A26,쿼리1[[ID]:[열1]],3,FALSE) -> 10 | L26: =$B26&"."&VLOOKUP($C26,'#Data'!$B$2:$J$344,2,FALSE)&".attack0"&RIGHT(L$1,1) -> Sector02.cassandra_2.attack01 | O26: =$B26&"."&VLOOKUP($C26,'#Data'!$B$2:$J$344,2,FALSE)&".skill0"&RIGHT(O$1,1) -> Sector02.cassandra_2.skill01 | P26: =$B26&"."&VLOOKUP($C26,'#Data'!$B$2:$J$344,2,FALSE)&".skill0"&RIGHT(P$1,1) -> Sector02.cassandra_2.skill02 | Q26: =$B26&"."&VLOOKUP($C26,'#Data'!$B$2:$J$344,2,FALSE)&".skill0"&RIGHT(Q$1,1) -> Sector02.cassandra_2.skill03 | R26: Sector02.cassandra_2.passive01 | S26: Boss.Common.Immun | V26: FALSE | W26: ="Character/Prefabs/"&VLOOKUP($C26,'#Data'!$B$3:$I$344,8,FALSE) -> Character/Prefabs/m_boss_ranger_cassandra_2 | Y26: =VLOOKUP($C26,'#Data'!$B$3:$I$344,8,FALSE) -> m_boss_ranger_cassandra_2 | AC26: 0.9 | AE26: Character/Timeline/02_MON/cassandra/appearance2 | AF26: Character/Timeline/02_MON/cassandra/die2 | AG26: AttributeNone
A27: 1110202101 | B27: Sector02 | C27: 터틀메카mk3 | D27: ="Monster.Name."&VLOOKUP($C27,'#Data'!$B$2:$J$344,2,FALSE) -> Monster.Name.turtle_mechamk3_3 | E27: Attacker | F27: Fac_nul_ind | G27: TRUE | H27: =IF(OR(VLOOKUP($C27,'#Data'!$B$2:$J$344,4,FALSE)="보스",VLOOKUP($C27,'#Data'!$B$2:$J$344,4,FALSE)="중간"),TRUE,FALSE) -> FALSE | I27: =IF(OR(VLOOKUP($C27,'#Data'!$B$2:$J$344,4,FALSE)="보스",VLOOKUP($C27,'#Data'!$B$2:$J$344,4,FALSE)="중간"),TRUE,FALSE) -> FALSE | J27: 10 | K27: =VLOOKUP($A27,쿼리1[[ID]:[열1]],3,FALSE) -> 10 | L27: =$B27&"."&VLOOKUP($C27,'#Data'!$B$2:$J$344,2,FALSE)&".attack0"&RIGHT(L$1,1) -> Sector02.turtle_mechamk3_3.attack01 | O27: Sector02.turtle_mechamk3_3.skill01 | V27: FALSE | W27: ="Character/Prefabs/"&VLOOKUP($C27,'#Data'!$B$3:$I$344,8,FALSE) -> Character/Prefabs/m_s_attacker_turtle_mechamk3_3 | Y27: =VLOOKUP($C27,'#Data'!$B$3:$I$344,8,FALSE) -> m_s_attacker_turtle_mechamk3_3 | AC27: 0.7 | AG27: AttributeNone
A28: 1110202102 | B28: Sector02 | C28: 스콜피온터렛mk2 | D28: ="Monster.Name."&VLOOKUP($C28,'#Data'!$B$2:$J$344,2,FALSE) -> Monster.Name.scorpion_turretmk2_3 | E28: Ranger | F28: Fac_nul_ind | G28: TRUE | H28: =IF(OR(VLOOKUP($C28,'#Data'!$B$2:$J$344,4,FALSE)="보스",VLOOKUP($C28,'#Data'!$B$2:$J$344,4,FALSE)="중간"),TRUE,FALSE) -> FALSE | I28: =IF(OR(VLOOKUP($C28,'#Data'!$B$2:$J$344,4,FALSE)="보스",VLOOKUP($C28,'#Data'!$B$2:$J$344,4,FALSE)="중간"),TRUE,FALSE) -> FALSE | J28: 10 | K28: =VLOOKUP($A28,쿼리1[[ID]:[열1]],3,FALSE) -> 10 | L28: =$B28&"."&VLOOKUP($C28,'#Data'!$B$2:$J$344,2,FALSE)&".attack0"&RIGHT(L$1,1) -> Sector02.scorpion_turretmk2_3.attack01 | O28: Sector02.scorpion_turretmk2_3.skill01 | V28: FALSE | W28: ="Character/Prefabs/"&VLOOKUP($C28,'#Data'!$B$3:$I$344,8,FALSE) -> Character/Prefabs/m_s_ranger_scorpion_turretmk2_3 | Y28: =VLOOKUP($C28,'#Data'!$B$3:$I$344,8,FALSE) -> m_s_ranger_scorpion_turretmk2_3 | AC28: 0.7 | AG28: AttributeNone
A29: 1110202103 | B29: Sector02 | C29: 라이노메카mk3 | D29: ="Monster.Name."&VLOOKUP($C29,'#Data'!$B$2:$J$344,2,FALSE) -> Monster.Name.rhino_mechamk3_3 | E29: Attacker | F29: Fac_nul_ind | G29: TRUE | H29: =IF(OR(VLOOKUP($C29,'#Data'!$B$2:$J$344,4,FALSE)="보스",VLOOKUP($C29,'#Data'!$B$2:$J$344,4,FALSE)="중간"),TRUE,FALSE) -> FALSE | I29: =IF(OR(VLOOKUP($C29,'#Data'!$B$2:$J$344,4,FALSE)="보스",VLOOKUP($C29,'#Data'!$B$2:$J$344,4,FALSE)="중간"),TRUE,FALSE) -> FALSE | J29: 10 | K29: =VLOOKUP($A29,쿼리1[[ID]:[열1]],3,FALSE) -> 10 | L29: =$B29&"."&VLOOKUP($C29,'#Data'!$B$2:$J$344,2,FALSE)&".attack0"&RIGHT(L$1,1) -> Sector02.rhino_mechamk3_3.attack01 | O29: Sector02.rhino_mechamk3_3.skill01 | V29: FALSE | W29: ="Character/Prefabs/"&VLOOKUP($C29,'#Data'!$B$3:$I$344,8,FALSE) -> Character/Prefabs/m_s_attacker_rhino_mechamk3_3 | Y29: =VLOOKUP($C29,'#Data'!$B$3:$I$344,8,FALSE) -> m_s_attacker_rhino_mechamk3_3 | AC29: 0.7 | AG29: AttributeNone
A30: 1110202104 | B30: Sector02 | C30: 스파이더터렛mk2 | D30: ="Monster.Name."&VLOOKUP($C30,'#Data'!$B$2:$J$344,2,FALSE) -> Monster.Name.spider_turretmk2_3 | E30: Ranger | F30: Fac_nul_ind | G30: TRUE | H30: =IF(OR(VLOOKUP($C30,'#Data'!$B$2:$J$344,4,FALSE)="보스",VLOOKUP($C30,'#Data'!$B$2:$J$344,4,FALSE)="중간"),TRUE,FALSE) -> FALSE | I30: =IF(OR(VLOOKUP($C30,'#Data'!$B$2:$J$344,4,FALSE)="보스",VLOOKUP($C30,'#Data'!$B$2:$J$344,4,FALSE)="중간"),TRUE,FALSE) -> FALSE | J30: 10 | K30: =VLOOKUP($A30,쿼리1[[ID]:[열1]],3,FALSE) -> 10 | L30: =$B30&"."&VLOOKUP($C30,'#Data'!$B$2:$J$344,2,FALSE)&".attack0"&RIGHT(L$1,1) -> Sector02.spider_turretmk2_3.attack01 | O30: Sector02.spider_turretmk2_3.skill01 | V30: FALSE | W30: ="Character/Prefabs/"&VLOOKUP($C30,'#Data'!$B$3:$I$344,8,FALSE) -> Character/Prefabs/m_s_ranger_spider_turretmk2_3 | Y30: =VLOOKUP($C30,'#Data'!$B$3:$I$344,8,FALSE) -> m_s_ranger_spider_turretmk2_3 | AC30: 0.7 | AG30: AttributeNone
A31: 1110202105 | B31: Sector02 | C31: 헬파이어드론 | D31: ="Monster.Name."&VLOOKUP($C31,'#Data'!$B$2:$J$344,2,FALSE) -> Monster.Name.hellfire_drone_3 | E31: Ranger | F31: Fac_nul_ind | G31: TRUE | H31: =IF(OR(VLOOKUP($C31,'#Data'!$B$2:$J$344,4,FALSE)="보스",VLOOKUP($C31,'#Data'!$B$2:$J$344,4,FALSE)="중간"),TRUE,FALSE) -> FALSE | I31: =IF(OR(VLOOKUP($C31,'#Data'!$B$2:$J$344,4,FALSE)="보스",VLOOKUP($C31,'#Data'!$B$2:$J$344,4,FALSE)="중간"),TRUE,FALSE) -> FALSE | J31: 10 | K31: =VLOOKUP($A31,쿼리1[[ID]:[열1]],3,FALSE) -> 10 | L31: =$B31&"."&VLOOKUP($C31,'#Data'!$B$2:$J$344,2,FALSE)&".attack0"&RIGHT(L$1,1) -> Sector02.hellfire_drone_3.attack01 | O31: =$B31&"."&VLOOKUP($C31,'#Data'!$B$2:$J$344,2,FALSE)&".skill0"&RIGHT(O$1,1) -> Sector02.hellfire_drone_3.skill01 | P31: Sector02.hellfire_drone_3.skill02 | V31: FALSE | W31: ="Character/Prefabs/"&VLOOKUP($C31,'#Data'!$B$3:$I$344,8,FALSE) -> Character/Prefabs/m_s_ranger_hellfire_drone_3 | Y31: =VLOOKUP($C31,'#Data'!$B$3:$I$344,8,FALSE) -> m_s_ranger_hellfire_drone_3 | AC31: 0.6 | AG31: AttributeNone
A32: 1110202106 | B32: Sector02 | C32: 실루엣건틀릿 | D32: ="Monster.Name."&VLOOKUP($C32,'#Data'!$B$2:$J$344,2,FALSE) -> Monster.Name.silhouette_champion_3 | E32: Attacker | F32: Fac_nul_ind | G32: TRUE | H32: =IF(OR(VLOOKUP($C32,'#Data'!$B$2:$J$344,4,FALSE)="보스",VLOOKUP($C32,'#Data'!$B$2:$J$344,4,FALSE)="중간"),TRUE,FALSE) -> FALSE | I32: =IF(OR(VLOOKUP($C32,'#Data'!$B$2:$J$344,4,FALSE)="보스",VLOOKUP($C32,'#Data'!$B$2:$J$344,4,FALSE)="중간"),TRUE,FALSE) -> FALSE | J32: 10 | K32: =VLOOKUP($A32,쿼리1[[ID]:[열1]],3,FALSE) -> 10 | L32: =$B32&"."&VLOOKUP($C32,'#Data'!$B$2:$J$344,2,FALSE)&".attack0"&RIGHT(L$1,1) -> Sector02.silhouette_champion_3.attack01 | O32: =$B32&"."&VLOOKUP($C32,'#Data'!$B$2:$J$344,2,FALSE)&".skill0"&RIGHT(O$1,1) -> Sector02.silhouette_champion_3.skill01 | P32: Sector02.silhouette_champion_3.skill02 | V32: FALSE | W32: ="Character/Prefabs/"&VLOOKUP($C32,'#Data'!$B$3:$I$344,8,FALSE) -> Character/Prefabs/m_m_attacker_silhouette_champion_3 | Y32: =VLOOKUP($C32,'#Data'!$B$3:$I$344,8,FALSE) -> m_m_attacker_silhouette_champion_3 | AC32: 0.8 | AG32: AttributeNone
A33: 1110202107 | B33: Sector02 | C33: 실루엣런처 | D33: ="Monster.Name."&VLOOKUP($C33,'#Data'!$B$2:$J$344,2,FALSE) -> Monster.Name.silhouette_demolisher_3 | E33: Ranger | F33: Fac_nul_ind | G33: TRUE | H33: =IF(OR(VLOOKUP($C33,'#Data'!$B$2:$J$344,4,FALSE)="보스",VLOOKUP($C33,'#Data'!$B$2:$J$344,4,FALSE)="중간"),TRUE,FALSE) -> FALSE | I33: =IF(OR(VLOOKUP($C33,'#Data'!$B$2:$J$344,4,FALSE)="보스",VLOOKUP($C33,'#Data'!$B$2:$J$344,4,FALSE)="중간"),TRUE,FALSE) -> FALSE | J33: 10 | K33: =VLOOKUP($A33,쿼리1[[ID]:[열1]],3,FALSE) -> 10 | L33: =$B33&"."&VLOOKUP($C33,'#Data'!$B$2:$J$344,2,FALSE)&".attack0"&RIGHT(L$1,1) -> Sector02.silhouette_demolisher_3.attack01 | O33: =$B33&"."&VLOOKUP($C33,'#Data'!$B$2:$J$344,2,FALSE)&".skill0"&RIGHT(O$1,1) -> Sector02.silhouette_demolisher_3.skill01 | P33: Sector02.silhouette_demolisher_3.skill02 | V33: FALSE | W33: ="Character/Prefabs/"&VLOOKUP($C33,'#Data'!$B$3:$I$344,8,FALSE) -> Character/Prefabs/m_m_ranger_silhouette_demolisher_3 | Y33: =VLOOKUP($C33,'#Data'!$B$3:$I$344,8,FALSE) -> m_m_ranger_silhouette_demolisher_3 | AC33: 0.8 | AG33: AttributeNone
A34: 1110202108 | B34: Sector02 | C34: 실루엣쉴드 | D34: ="Monster.Name."&VLOOKUP($C34,'#Data'!$B$2:$J$344,2,FALSE) -> Monster.Name.silhouette_guard_3 | E34: Tanker | F34: Fac_nul_ind | G34: TRUE | H34: =IF(OR(VLOOKUP($C34,'#Data'!$B$2:$J$344,4,FALSE)="보스",VLOOKUP($C34,'#Data'!$B$2:$J$344,4,FALSE)="중간"),TRUE,FALSE) -> FALSE | I34: =IF(OR(VLOOKUP($C34,'#Data'!$B$2:$J$344,4,FALSE)="보스",VLOOKUP($C34,'#Data'!$B$2:$J$344,4,FALSE)="중간"),TRUE,FALSE) -> FALSE | J34: 10 | K34: =VLOOKUP($A34,쿼리1[[ID]:[열1]],3,FALSE) -> 10 | L34: =$B34&"."&VLOOKUP($C34,'#Data'!$B$2:$J$344,2,FALSE)&".attack0"&RIGHT(L$1,1) -> Sector02.silhouette_guard_3.attack01 | O34: =$B34&"."&VLOOKUP($C34,'#Data'!$B$2:$J$344,2,FALSE)&".skill0"&RIGHT(O$1,1) -> Sector02.silhouette_guard_3.skill01 | P34: Sector02.silhouette_guard_3.skill02 | V34: FALSE | W34: ="Character/Prefabs/"&VLOOKUP($C34,'#Data'!$B$3:$I$344,8,FALSE) -> Character/Prefabs/m_m_tanker_silhouette_guard_3 | Y34: =VLOOKUP($C34,'#Data'!$B$3:$I$344,8,FALSE) -> m_m_tanker_silhouette_guard_3 | AC34: 0.8 | AG34: AttributeNone
A35: 1110202109 | B35: Sector02 | C35: 실루엣플레임 | D35: ="Monster.Name."&VLOOKUP($C35,'#Data'!$B$2:$J$344,2,FALSE) -> Monster.Name.silhouette_inferno_3 | E35: Attacker | F35: Fac_nul_ind | G35: TRUE | H35: =IF(OR(VLOOKUP($C35,'#Data'!$B$2:$J$344,4,FALSE)="보스",VLOOKUP($C35,'#Data'!$B$2:$J$344,4,FALSE)="중간"),TRUE,FALSE) -> FALSE | I35: =IF(OR(VLOOKUP($C35,'#Data'!$B$2:$J$344,4,FALSE)="보스",VLOOKUP($C35,'#Data'!$B$2:$J$344,4,FALSE)="중간"),TRUE,FALSE) -> FALSE | J35: 10 | K35: =VLOOKUP($A35,쿼리1[[ID]:[열1]],3,FALSE) -> 10 | L35: =$B35&"."&VLOOKUP($C35,'#Data'!$B$2:$J$344,2,FALSE)&".attack0"&RIGHT(L$1,1) -> Sector02.silhouette_inferno_3.attack01 | O35: =$B35&"."&VLOOKUP($C35,'#Data'!$B$2:$J$344,2,FALSE)&".skill0"&RIGHT(O$1,1) -> Sector02.silhouette_inferno_3.skill01 | P35: Sector02.silhouette_inferno_3.skill02 | V35: FALSE | W35: ="Character/Prefabs/"&VLOOKUP($C35,'#Data'!$B$3:$I$344,8,FALSE) -> Character/Prefabs/m_m_attacker_silhouette_inferno_3 | Y35: =VLOOKUP($C35,'#Data'!$B$3:$I$344,8,FALSE) -> m_m_attacker_silhouette_inferno_3 | AC35: 0.8 | AG35: AttributeNone
A36: 1110202110 | B36: Sector02 | C36: 터틀메카mk3베리 | D36: ="Monster.Name."&VLOOKUP($C36,'#Data'!$B$2:$J$344,2,FALSE) -> Monster.Name.turtle_mechamk3_4 | E36: Attacker | F36: Fac_nul_ind | G36: TRUE | H36: =IF(OR(VLOOKUP($C36,'#Data'!$B$2:$J$344,4,FALSE)="보스",VLOOKUP($C36,'#Data'!$B$2:$J$344,4,FALSE)="중간"),TRUE,FALSE) -> FALSE | I36: =IF(OR(VLOOKUP($C36,'#Data'!$B$2:$J$344,4,FALSE)="보스",VLOOKUP($C36,'#Data'!$B$2:$J$344,4,FALSE)="중간"),TRUE,FALSE) -> FALSE | J36: 10 | K36: =VLOOKUP($A36,쿼리1[[ID]:[열1]],3,FALSE) -> 10 | L36: Sector02.turtle_mechamk3_3.attack01 | O36: Sector02.turtle_mechamk3_3.skill01 | V36: FALSE | W36: ="Character/Prefabs/"&VLOOKUP($C36,'#Data'!$B$3:$I$344,8,FALSE) -> Character/Prefabs/m_s_attacker_turtle_mechamk3_4 | Y36: =VLOOKUP($C36,'#Data'!$B$3:$I$344,8,FALSE) -> m_s_attacker_turtle_mechamk3_4 | AC36: 0.7 | AG36: AttributeNone
A37: 1110202111 | B37: Sector02 | C37: 스콜피온터렛mk2베리 | D37: ="Monster.Name."&VLOOKUP($C37,'#Data'!$B$2:$J$344,2,FALSE) -> Monster.Name.scorpion_turretmk2_4 | E37: Ranger | F37: Fac_nul_ind | G37: TRUE | H37: =IF(OR(VLOOKUP($C37,'#Data'!$B$2:$J$344,4,FALSE)="보스",VLOOKUP($C37,'#Data'!$B$2:$J$344,4,FALSE)="중간"),TRUE,FALSE) -> FALSE | I37: FALSE | J37: 10 | K37: =VLOOKUP($A37,쿼리1[[ID]:[열1]],3,FALSE) -> 10 | L37: Sector02.scorpion_turretmk2_3.attack01 | O37: Sector02.scorpion_turretmk2_3.skill01 | V37: FALSE | W37: ="Character/Prefabs/"&VLOOKUP($C37,'#Data'!$B$3:$I$344,8,FALSE) -> Character/Prefabs/m_s_ranger_scorpion_turretmk2_4 | Y37: =VLOOKUP($C37,'#Data'!$B$3:$I$344,8,FALSE) -> m_s_ranger_scorpion_turretmk2_4 | AC37: 0.7 | AG37: AttributeNone
A38: 1110202112 | B38: Sector02 | C38: 라이노메카mk3베리 | D38: ="Monster.Name."&VLOOKUP($C38,'#Data'!$B$2:$J$344,2,FALSE) -> Monster.Name.rhino_mechamk3_4 | E38: Attacker | F38: Fac_nul_ind | G38: TRUE | H38: =IF(OR(VLOOKUP($C38,'#Data'!$B$2:$J$344,4,FALSE)="보스",VLOOKUP($C38,'#Data'!$B$2:$J$344,4,FALSE)="중간"),TRUE,FALSE) -> FALSE | I38: FALSE | J38: 10 | K38: =VLOOKUP($A38,쿼리1[[ID]:[열1]],3,FALSE) -> 10 | L38: Sector02.rhino_mechamk3_3.attack01 | O38: Sector02.rhino_mechamk3_3.skill01 | V38: FALSE | W38: ="Character/Prefabs/"&VLOOKUP($C38,'#Data'!$B$3:$I$344,8,FALSE) -> Character/Prefabs/m_s_attacker_rhino_mechamk3_4 | Y38: =VLOOKUP($C38,'#Data'!$B$3:$I$344,8,FALSE) -> m_s_attacker_rhino_mechamk3_4 | AC38: 0.7 | AG38: AttributeNone
A39: 1110202113 | B39: Sector02 | C39: 스파이더터렛mk2베리 | D39: ="Monster.Name."&VLOOKUP($C39,'#Data'!$B$2:$J$344,2,FALSE) -> Monster.Name.spider_turretmk2_4 | E39: Ranger | F39: Fac_nul_ind | G39: TRUE | H39: =IF(OR(VLOOKUP($C39,'#Data'!$B$2:$J$344,4,FALSE)="보스",VLOOKUP($C39,'#Data'!$B$2:$J$344,4,FALSE)="중간"),TRUE,FALSE) -> FALSE | I39: FALSE | J39: 10 | K39: =VLOOKUP($A39,쿼리1[[ID]:[열1]],3,FALSE) -> 10 | L39: Sector02.spider_turretmk2_3.attack01 | O39: Sector02.spider_turretmk2_3.skill01 | V39: FALSE | W39: ="Character/Prefabs/"&VLOOKUP($C39,'#Data'!$B$3:$I$344,8,FALSE) -> Character/Prefabs/m_s_ranger_spider_turretmk2_4 | Y39: =VLOOKUP($C39,'#Data'!$B$3:$I$344,8,FALSE) -> m_s_ranger_spider_turretmk2_4 | AC39: 0.7 | AG39: AttributeNone
A40: 1110202114 | B40: Sector02 | C40: 헬파이어드론베리 | D40: ="Monster.Name."&VLOOKUP($C40,'#Data'!$B$2:$J$344,2,FALSE) -> Monster.Name.hellfire_drone_4 | E40: Ranger | F40: Fac_nul_ind | G40: TRUE | H40: =IF(OR(VLOOKUP($C40,'#Data'!$B$2:$J$344,4,FALSE)="보스",VLOOKUP($C40,'#Data'!$B$2:$J$344,4,FALSE)="중간"),TRUE,FALSE) -> FALSE | I40: FALSE | J40: 10 | K40: =VLOOKUP($A40,쿼리1[[ID]:[열1]],3,FALSE) -> 10 | L40: Sector02.hellfire_drone_3.attack01 | O40: Sector02.hellfire_drone_3.skill01 | P40: Sector02.hellfire_drone_3.skill02 | V40: FALSE | W40: ="Character/Prefabs/"&VLOOKUP($C40,'#Data'!$B$3:$I$344,8,FALSE) -> Character/Prefabs/m_s_ranger_hellfire_drone_4 | Y40: =VLOOKUP($C40,'#Data'!$B$3:$I$344,8,FALSE) -> m_s_ranger_hellfire_drone_4 | AC40: 0.6 | AG40: AttributeNone
...

Sheet Monster.Etc
A1: Id | B1: #기획 | C1: #기획 | D1: Name | E1: Type | F1: FactionGroudId | G1: Attackable | H1: Boss | I1: UseHpSlice | J1: Radius | K1: MoveValue | L1: NormalSkill1 | M1: NormalSkill2 | N1: NormalSkill3 | O1: Skill1 | P1: Skill2 | Q1: Skill3 | R1: Skill4 | S1: Skill5 | T1: UltimateSkill | U1: UltimateExSkill | V1: Left | W1: PrefabBattle | X1: PrefabSpine | Y1: Icon | Z1: UltimateTimeline | AA1: VictoryTimeline | AB1: DieSound | AC1: Scale | AD1: CriticalEffect | AE1: StartTimeline | AF1: EndTimeline | AG1: Attribute
A2: *long | B2: # | C2: # | D2: string | E2: ClassType | F2: $FactionGroup? | G2: bool | H2: bool | I2: bool | J2: int | K2: int | L2: $SkillGroup? | M2: $SkillGroup? | N2: $SkillGroup? | O2: $SkillGroup? | P2: $SkillGroup? | Q2: $SkillGroup? | R2: $SkillGroup? | S2: $SkillGroup? | T2: $SkillGroup? | U2: $SkillGroup? | V2: bool | W2: string | X2: string | Y2: string | Z2: string | AA2: string | AB2: string | AC2: float | AD2: string | AE2: string | AF2: string | AG2: AttributeType
A3: common | B3: #사용처 | C3: #리소스명 | D3: client | E3: common | F3: common | G3: common | H3: common | I3: client | J3: common | K3: common | L3: common | M3: common | N3: common | O3: common | P3: common | Q3: common | R3: common | S3: common | T3: common | U3: common | V3: client | W3: client | X3: client | Y3: client | Z3: client | AA3: client | AB3: client | AC3: client | AD3: client | AE3: common | AF3: common | AG3: common
A4: 1110101001 | B4: 튜토리얼 | C4: 마나 | D4: Name.Character.mana | E4: Ranger | F4: Fac_rim_aki | G4: TRUE | H4: FALSE | I4: FALSE | J4: 10 | K4: =VLOOKUP($A4,쿼리1[[ID]:[열1]],3,FALSE) -> 10 | L4: tuto.mana.attack1 | M4: tuto.mana.attack2 | N4: tuto.mana.attack3 | O4: mana.active1 | P4: mana.active2 | Q4: mana.passive | T4: mana.ult | V4: TRUE | W4: Character/Prefabs/c_ranger_mana_1 | X4: CharacterSpine/c_ranger_mana_1 | Y4: character_mana_01 | Z4: Character/Timeline/01_CHA/ult_c_ranger_mana_1 | AB4: Voice_renas_retire | AC4: 0.9 | AG4: AttributeGreen
A5: 1110101002 | B5: 튜토리얼 | C5: 아이렌 | D5: Name.Character.airen | E5: Attacker | F5: Fac_sta_sec | G5: TRUE | H5: FALSE | I5: FALSE | J5: 10 | K5: =VLOOKUP($A5,쿼리1[[ID]:[열1]],3,FALSE) -> 10 | L5: tuto.airen.attack1 | M5: tuto.airen.attack2 | N5: tuto.airen.attack3 | O5: airen.active1 | P5: airen.active2 | Q5: airen.passive | T5: airen.ult | U5: airen.ult.B | V5: TRUE | W5: Character/Prefabs/c_attacker_airen_1 | X5: CharacterSpine/c_attacker_airen_1 | Y5: character_airen_01 | Z5: Character/Timeline/01_CHA/ult_c_attacker_airen_1 | AB5: Voice_Ann_retire | AC5: 0.9 | AG5: AttributeBlue
A6: 1110101003 | B6: 튜토리얼 | C6: 오로라 | D6: Name.Character.aurora | E6: Ranger | F6: Fac_rim_aki | G6: TRUE | H6: FALSE | I6: FALSE | J6: 10 | K6: =VLOOKUP($A6,쿼리1[[ID]:[열1]],3,FALSE) -> 10 | L6: tuto.aurora.attack1 | M6: tuto.aurora.attack2 | N6: tuto.aurora.attack3 | O6: aurora.active1 | P6: aurora.active2 | Q6: aurora.passive | T6: aurora.ult | V6: TRUE | W6: Character/Prefabs/c_ranger_aurora_1 | X6: CharacterSpine/c_ranger_aurora_1 | Y6: character_aurora_01 | Z6: Character/Timeline/01_CHA/ult_c_ranger_aurora_1 | AB6: Voice_assault_rifle_retire_001 | AC6: 0.9 | AG6: AttributeRed
A7: 1110101004 | B7: 튜토리얼 | C7: 카산드라 | D7: MonsterName.Cassandra | E7: Ranger | F7: Fac_nul_ind | G7: TRUE | H7: TRUE | I7: TRUE | J7: 20 | K7: =VLOOKUP($A7,쿼리1[[ID]:[열1]],3,FALSE) -> 10 | L7: tuto.cassandra.attack01 | O7: tuto.cassandra.skill01 | P7: tuto.cassandra.skill02 | R7: boss.immun.knockback | V7: FALSE | W7: Character/Prefabs/m_boss_ranger_cassandra_1 | Y7: m_boss_ranger_cassandra_1 | AB7: Die_machine | AC7: 0.9 | AG7: AttributeNone
A8: 1110101005 | B8: 튜토리얼 | C8: 일렉트릭드론 | D8: Monster.Name.electric_drone_1 | E8: Attacker | F8: Fac_nul_ind | G8: TRUE | H8: FALSE | I8: FALSE | J8: 10 | K8: =VLOOKUP($A8,쿼리1[[ID]:[열1]],3,FALSE) -> 10 | L8: tuto.electric_drone_1.attack01 | V8: FALSE | W8: Character/Prefabs/m_s_attacker_electric_drone_1 | Y8: m_s_attacker_electric_drone_1 | AC8: 0.7 | AG8: AttributeNone
A9: 1110101006 | B9: 튜토리얼 | C9: 재밍드론 | D9: Monster.Name.jamming_drone_1 | E9: Ranger | F9: Fac_nul_ind | G9: TRUE | H9: FALSE | I9: FALSE | J9: 10 | K9: =VLOOKUP($A9,쿼리1[[ID]:[열1]],3,FALSE) -> 10 | L9: tuto.jamming_drone_1.attack01 | V9: FALSE | W9: Character/Prefabs/m_s_ranger_jamming_drone_1 | Y9: m_s_ranger_jamming_drone_1 | AC9: 0.6 | AG9: AttributeNone
A10: 1110101007 | B10: tuto | C10: 엑시큐서너베타 | D10: ="Monster.Name."&VLOOKUP($C10,'#Data'!$B$2:$J$344,2,FALSE) -> Monster.Name.labmecha_launcher_1 | E10: =VLOOKUP($C10,'#Data'!$B$3:$J$344,6,FALSE) -> Ranger | F10: Fac_nul_ind | G10: TRUE | H10: =IF(OR(VLOOKUP($C10,'#Data'!$B$2:$J$344,4,FALSE)="보스",VLOOKUP($C10,'#Data'!$B$2:$J$344,4,FALSE)="중간"),TRUE,FALSE) -> TRUE | I10: TRUE | J10: 10 | K10: =VLOOKUP($A10,쿼리1[[ID]:[열1]],3,FALSE) -> 10 | L10: =$B10&"."&VLOOKUP($C10,'#Data'!$B$2:$J$344,2,FALSE)&".attack0"&RIGHT(L$1,1) -> tuto.labmecha_launcher_1.attack01 | O10: =$B10&"."&VLOOKUP($C10,'#Data'!$B$2:$J$344,2,FALSE)&".skill0"&RIGHT(O$1,1) -> tuto.labmecha_launcher_1.skill01 | P10: =$B10&"."&VLOOKUP($C10,'#Data'!$B$2:$J$344,2,FALSE)&".skill0"&RIGHT(P$1,1) -> tuto.labmecha_launcher_1.skill02 | V10: FALSE | W10: ="Character/Prefabs/"&VLOOKUP($C10,'#Data'!$B$3:$I$344,8,FALSE) -> Character/Prefabs/m_m_ranger_labmecha_launcher_1 | Y10: =VLOOKUP($C10,'#Data'!$B$3:$I$344,8,FALSE) -> m_m_ranger_labmecha_launcher_1 | AC10: 0.7 | AG10: AttributeNone
A11: 1110101008 | B11: 튜토리얼 | C11: 마나 | D11: Name.Character.mana | E11: Ranger | F11: Fac_rim_aki | G11: TRUE | H11: FALSE | I11: FALSE | J11: 10 | K11: =VLOOKUP($A11,쿼리1[[ID]:[열1]],3,FALSE) -> 10 | L11: tuto.mana.attack1 | M11: tuto.mana.attack2 | N11: tuto.mana.attack3 | O11: tuto.mana.active1 | P11: tuto.mana.active2 | Q11: mana.passive | T11: mana.ult | V11: TRUE | W11: Character/Prefabs/c_ranger_mana_1 | X11: CharacterSpine/c_ranger_mana_1 | Y11: character_mana_01 | Z11: Character/Timeline/01_CHA/ult_c_ranger_mana_1 | AB11: Voice_renas_retire | AC11: 0.9 | AG11: AttributeGreen
A12: 1110101009 | B12: 튜토리얼 | C12: 아이렌 | D12: Name.Character.airen | E12: Attacker | F12: Fac_sta_sec | G12: TRUE | H12: FALSE | I12: FALSE | J12: 10 | K12: =VLOOKUP($A12,쿼리1[[ID]:[열1]],3,FALSE) -> 10 | L12: tuto.airen.attack1 | M12: tuto.airen.attack2 | N12: tuto.airen.attack3 | O12: tuto.airen.active1 | P12: tuto.airen.active2 | Q12: airen.passive | T12: airen.ult | U12: airen.ult.B | V12: TRUE | W12: Character/Prefabs/c_attacker_airen_1 | X12: CharacterSpine/c_attacker_airen_1 | Y12: character_airen_01 | Z12: Character/Timeline/01_CHA/ult_c_attacker_airen_1 | AB12: Voice_Ann_retire | AC12: 0.9 | AG12: AttributeRed
A13: 1110101010 | B13: 튜토리얼 | C13: 오로라 | D13: Name.Character.aurora | E13: Ranger | F13: Fac_rim_aki | G13: TRUE | H13: FALSE | I13: FALSE | J13: 10 | K13: =VLOOKUP($A13,쿼리1[[ID]:[열1]],3,FALSE) -> 10 | L13: tuto.aurora.attack1 | M13: tuto.aurora.attack2 | N13: tuto.aurora.attack3 | O13: tuto.aurora.active1 | P13: tuto.aurora.active2 | Q13: aurora.passive | T13: aurora.ult | V13: TRUE | W13: Character/Prefabs/c_ranger_aurora_1 | X13: CharacterSpine/c_ranger_aurora_1 | Y13: character_aurora_01 | Z13: Character/Timeline/01_CHA/ult_c_ranger_aurora_1 | AB13: Voice_assault_rifle_retire_001 | AC13: 0.9 | AG13: AttributeBlue
A14: 1110101011 | B14: 튜토리얼 | C14: 일렉트릭드론베리 | D14: Monster.Name.electric_drone_2 | E14: Attacker | F14: Fac_nul_ind | G14: TRUE | H14: FALSE | I14: FALSE | J14: 10 | K14: =VLOOKUP($A14,쿼리1[[ID]:[열1]],3,FALSE) -> 10 | L14: tuto.electric_drone_1.attack01 | V14: FALSE | W14: Character/Prefabs/m_s_attacker_electric_drone_5 | Y14: m_s_attacker_electric_drone_5 | AC14: 0.7 | AG14: AttributeNone
A15: 1110101012 | B15: 튜토리얼 | C15: 트루퍼쉴드 | D15: Monster.Name.trooper_guard_1 | E15: Tanker | F15: Fac_nul_ind | G15: TRUE | H15: FALSE | I15: FALSE | J15: 10 | K15: =VLOOKUP($A15,쿼리1[[ID]:[열1]],3,FALSE) -> 10 | L15: Sector01.trooper_guard_1.attack01 | O15: Sector01.trooper_guard_1.skill01 | V15: FALSE | W15: Character/Prefabs/m_m_tanker_trooper_guard_1 | Y15: m_m_tanker_trooper_guard_1 | AC15: 0.8 | AG15: AttributeNone
A16: 1110101013 | B16: 튜토리얼 | C16: 엑시큐서너베타 | D16: Monster.Name.labmecha_launcher_1 | E16: Ranger | F16: Fac_nul_ind | G16: TRUE | H16: TRUE | I16: TRUE | J16: 10 | K16: =VLOOKUP($A16,쿼리1[[ID]:[열1]],3,FALSE) -> 10 | L16: tuto.labmecha_launcher_1.attack01 | O16: tuto.labmecha_launcher_1.skill01 | P16: tuto.labmecha_launcher_1.skill02 | V16: FALSE | W16: Character/Prefabs/m_m_ranger_labmecha_launcher_1 | Y16: m_m_ranger_labmecha_launcher_1 | AC16: 0.7 | AG16: AttributeNone
A17: 1110001001 | B17: 미리보기 | C17: 오로라 | D17: Character.Name.aurora | E17: Ranger | F17: Fac_rim_aki | G17: TRUE | H17: FALSE | I17: FALSE | J17: 10 | K17: =VLOOKUP($A17,쿼리1[[ID]:[열1]],3,FALSE) -> 10 | L17: aurora.attack1 | M17: aurora.attack2 | N17: aurora.attack3 | V17: TRUE | W17: Character/Prefabs/c_ranger_aurora_1 | Y17: character_aurora_01 | AC17: 0.9 | AG17: AttributeRed
A18: 1110001002 | B18: 미리보기 | C18: 샤레 | D18: Character.Name.aurora | E18: Ranger | F18: Fac_rim_aki | G18: TRUE | H18: FALSE | I18: FALSE | J18: 10 | K18: =VLOOKUP($A18,쿼리1[[ID]:[열1]],3,FALSE) -> 10 | L18: shale.attack1 | M18: shale.attack2 | N18: shale.attack3 | V18: TRUE | W18: Character/Prefabs/c_supporter_shale_1 | Y18: character_aurora_01 | AC18: 0.9 | AG18: AttributeBlue
A19: 1110001003 | B19: 미리보기 | C19: 친절한순찰대 | D19: MonsterName.Turret1 | E19: Attacker | F19: Fac_nul_ind | G19: TRUE | H19: FALSE | I19: FALSE | J19: 10 | K19: =VLOOKUP($A19,쿼리1[[ID]:[열1]],3,FALSE) -> 10 | L19: Sector04.friendly_patrol_1.attack01 | S19: stage.fever | V19: FALSE | W19: Character/Prefabs/m_s_attacker_friendly_patrol_1 | Y19: m_s_attacker_friendly_patrol_1 | AB19: Die_machine | AC19: 1 | AG19: AttributeNone
A20: 1110001004 | B20: 미리보기 | C20: 친절한화이트워킹아이볼 | D20: MonsterName.Turret1 | E20: Ranger | F20: Fac_nul_ind | G20: TRUE | H20: FALSE | I20: FALSE | J20: 10 | K20: =VLOOKUP($A20,쿼리1[[ID]:[열1]],3,FALSE) -> 10 | L20: Sector04.friendly_walking_eyeball_1.attack01 | S20: stage.fever | V20: FALSE | W20: Character/Prefabs/m_s_ranger_friendly_walking_eyeball_1 | Y20: m_s_ranger_friendly_walking_eyeball_1 | AB20: Die_machine | AC20: 1 | AG20: AttributeNone
A21: 1110001005 | B21: 미리보기 | C21: 친절한블랙워킹아이볼 | D21: MonsterName.Turret1 | E21: Ranger | F21: Fac_nul_ind | G21: TRUE | H21: FALSE | I21: FALSE | J21: 10 | K21: =VLOOKUP($A21,쿼리1[[ID]:[열1]],3,FALSE) -> 10 | L21: Sector04.friendly_walking_eyeball_2.attack01 | S21: stage.fever | V21: FALSE | W21: Character/Prefabs/m_s_ranger_friendly_walking_eyeball_2 | Y21: m_s_ranger_friendly_walking_eyeball_2 | AB21: Die_machine | AC21: 1 | AG21: AttributeNone
A22: 1110701001 | B22: 다이아나 | C22: diana | D22: Name.Character.diana | E22: Tanker | F22: Fac_sti_shi | G22: TRUE | H22: FALSE | I22: FALSE | J22: 10 | K22: =VLOOKUP($A22,쿼리1[[ID]:[열1]],3,FALSE) -> 10 | L22: diana.attack1 | M22: diana.attack2 | N22: diana.attack3 | O22: m.diana.active1 | P22: m.diana.active2 | Q22: m.diana.passive | T22: m.diana.ult | V22: TRUE | W22: Character/Prefabs/m_tanker_diana_enemy_1 | Y22: character_diana_01 | AC22: 0.9 | AG22: AttributeGreen
A23: 1110701002 | B23: 아이렌 | C23: airen | D23: Name.Character.airen | E23: Attacker | F23: Fac_sta_sec | G23: TRUE | H23: FALSE | I23: FALSE | J23: 10 | K23: =VLOOKUP($A23,쿼리1[[ID]:[열1]],3,FALSE) -> 10 | L23: airen.attack1 | M23: airen.attack2 | N23: airen.attack3 | O23: airen.active1 | P23: airen.active2 | Q23: airen.passive | R23: airen.passive.Ex | T23: airen.ult | U23: airen.ult.B | V23: TRUE | W23: Character/Prefabs/m_attacker_airen_enemy_1 | Y23: character_airen_01 | AC23: 0.9 | AG23: AttributeRed
A24: 1110701003 | B24: 시즈 | C24: siege | D24: Name.Character.siege | E24: Supporter | F24: Fac_sti_alt | G24: TRUE | H24: FALSE | I24: FALSE | J24: 10 | K24: =VLOOKUP($A24,쿼리1[[ID]:[열1]],3,FALSE) -> 10 | L24: siege.attack1 | M24: siege.attack2 | N24: siege.attack3 | O24: m.siege.active1 | P24: m.siege.active2 | Q24: m.siege.passive | T24: m.siege.ult | V24: TRUE | W24: Character/Prefabs/m_supporter_siege_enemy_1 | Y24: character_siege_01 | AC24: 0.9 | AG24: AttributeRed
A25: 1110701004 | B25: 마나 | C25: mana | D25: Name.Character.mana | E25: Ranger | F25: Fac_rim_aki | G25: TRUE | H25: FALSE | I25: FALSE | J25: 10 | K25: =VLOOKUP($A25,쿼리1[[ID]:[열1]],3,FALSE) -> 10 | L25: mana.attack1 | M25: mana.attack2 | N25: mana.attack3 | O25: m.mana.active1 | P25: m.mana.active2 | Q25: m.mana.passive | T25: m.mana.ult | V25: TRUE | W25: Character/Prefabs/m_ranger_mana_enemy_1 | Y25: character_mana_01 | AC25: 0.9 | AG25: AttributeGreen
A26: 1110701005 | B26: 오로라 | C26: aurora | D26: Name.Character.aurora | E26: Ranger | F26: Fac_rim_aki | G26: TRUE | H26: FALSE | I26: FALSE | J26: 10 | K26: =VLOOKUP($A26,쿼리1[[ID]:[열1]],3,FALSE) -> 10 | L26: aurora.attack1 | M26: aurora.attack2 | N26: aurora.attack3 | O26: m.aurora.active1 | P26: m.aurora.active2 | Q26: m.aurora.passive | T26: m.aurora.ult | V26: TRUE | W26: Character/Prefabs/m_ranger_aurora_enemy_1 | Y26: character_aurora_01 | AC26: 0.9 | AG26: AttributeBlue
A27: 1110701006 | B27: 앤 | C27: anne | D27: Name.Character.anne | E27: Tanker | F27: Fac_rim_ode | G27: TRUE | H27: FALSE | I27: FALSE | J27: 10 | K27: =VLOOKUP($A27,쿼리1[[ID]:[열1]],3,FALSE) -> 10 | L27: anne.attack1 | M27: anne.attack2 | N27: anne.attack3 | O27: anne.active1 | P27: anne.active2 | Q27: anne.passive | T27: anne.ult | U27: anne.ult.B | V27: TRUE | W27: Character/Prefabs/m_tanker_anne_enemy_1 | Y27: character_anne_01 | AC27: 0.9 | AG27: AttributeGreen
A28: 1110701007 | B28: 안젤리카 | C28: angelica | D28: Name.Character.angelica | E28: Attacker | F28: Fac_art_lib | G28: TRUE | H28: FALSE | I28: FALSE | J28: 10 | K28: =VLOOKUP($A28,쿼리1[[ID]:[열1]],3,FALSE) -> 10 | L28: angelica.attack1 | M28: angelica.attack2 | N28: angelica.attack3 | O28: m.angelica.active1 | P28: m.angelica.active2 | Q28: m.angelica.passive | R28: m.angelica.passive.Ex | T28: m.angelica.ult | U28: m.angelica.ult.B | V28: TRUE | W28: Character/Prefabs/m_attacker_angelica_enemy_1 | Y28: character_angelica_01 | AC28: 0.9 | AG28: AttributeGreen
A29: 1110701008 | B29: 페렐 | C29: ferrel | D29: Name.Character.ferrel | E29: Ranger | F29: Fac_sti_shi | G29: TRUE | H29: FALSE | I29: FALSE | J29: 10 | K29: =VLOOKUP($A29,쿼리1[[ID]:[열1]],3,FALSE) -> 10 | L29: ferrel.attack1 | M29: ferrel.attack2 | N29: ferrel.attack3 | O29: ferrel.active1 | P29: ferrel.active2 | Q29: ferrel.passive | R29: ferrel.passive.Ex | T29: ferrel.ult | U29: ferrel.ult.B | V29: TRUE | W29: Character/Prefabs/m_ranger_ferrel_enemy_1 | Y29: character_ferrel_01 | AC29: 0.9 | AG29: AttributeGreen
A30: 1110701009 | B30: 크림슨 | C30: crimson | D30: Name.Character.crimson | E30: Ranger | F30: Fac_sti_swo | G30: TRUE | H30: FALSE | I30: FALSE | J30: 10 | K30: =VLOOKUP($A30,쿼리1[[ID]:[열1]],3,FALSE) -> 10 | L30: m.crimson.attack1 | M30: m.crimson.attack2 | N30: m.crimson.attack3 | O30: m.crimson.active1 | P30: m.crimson.active2 | Q30: m.crimson.passive | R30: m.crimson.passive.Ex | T30: m.crimson.ult | U30: m.crimson.ult.B | V30: TRUE | W30: Character/Prefabs/m_ranger_crimson_enemy_1 | Y30: character_crimson_01 | AC30: 0.9 | AG30: AttributeRed
A31: 1110701010 | B31: 에이코 | C31: eiko | D31: Name.Character.eiko | E31: Ranger | F31: Fac_rim_aki | G31: TRUE | H31: FALSE | I31: FALSE | J31: 10 | K31: =VLOOKUP($A31,쿼리1[[ID]:[열1]],3,FALSE) -> 10 | L31: eiko.attack1 | M31: eiko.attack2 | N31: eiko.attack3 | O31: eiko.active1 | P31: eiko.active2 | Q31: eiko.passive | R31: eiko.passive.Ex | T31: eiko.ult | U31: eiko.ult.B | V31: TRUE | W31: Character/Prefabs/m_ranger_eiko_enemy_1 | Y31: character_eiko_01 | AC31: 0.9 | AG31: AttributeBlue
A32: 1110701011 | B32: 스노프릴 | C32: snopril | D32: Name.Character.snopril | E32: Tanker | F32: Fac_aut_gla | G32: TRUE | H32: FALSE | I32: FALSE | J32: 10 | K32: =VLOOKUP($A32,쿼리1[[ID]:[열1]],3,FALSE) -> 10 | L32: snopril.attack1 | M32: snopril.attack2 | N32: snopril.attack3 | O32: snopril.active1 | P32: snopril.active2 | Q32: snopril.passive | R32: snopril.passive.Ex | T32: snopril.ult | U32: snopril.ult.B | V32: TRUE | W32: Character/Prefabs/m_tanker_snopril_enemy_1 | Y32: character_snopril_01 | AC32: 0.9 | AG32: AttributeBlue
A33: 1110701012 | B33: 발렌시아 | C33: balencia | D33: Name.Character.balencia | E33: Attacker | F33: Fac_sti_ars | G33: TRUE | H33: FALSE | I33: FALSE | J33: 10 | K33: =VLOOKUP($A33,쿼리1[[ID]:[열1]],3,FALSE) -> 10 | L33: m.balencia.attack1 | M33: m.balencia.attack2 | N33: m.balencia.attack3 | O33: m.balencia.active1 | P33: m.balencia.active2 | Q33: m.balencia.passive | R33: m.balencia.passive.Ex | T33: m.balencia.ult | U33: m.balencia.ult.B | V33: TRUE | W33: Character/Prefabs/m_attacker_balencia_enemy_1 | Y33: character_balencia_01 | AC33: 0.9 | AG33: AttributeGreen
A34: 1110701013 | B34: 헬렌 | C34: hellen | D34: Name.Character.hellen | E34: Supporter | F34: Fac_art_app | G34: TRUE | H34: FALSE | I34: FALSE | J34: 10 | K34: =VLOOKUP($A34,쿼리1[[ID]:[열1]],3,FALSE) -> 10 | L34: hellen.attack1 | M34: hellen.attack2 | N34: hellen.attack3 | O34: m.hellen.active1 | P34: m.hellen.active2 | Q34: m.hellen.passive | R34: m.hellen.passive.Ex | T34: m.hellen.ult | U34: m.hellen.ult.B | V34: TRUE | W34: Character/Prefabs/m_supporter_hellen_enemy_1 | Y34: character_hellen_01 | AC34: 0.9 | AG34: AttributeRed
A35: 1110701014 | B35: 아셀스 | C35: arcels | D35: Name.Character.arcels | E35: Attacker | F35: Fac_aut_ter | G35: TRUE | H35: FALSE | I35: FALSE | J35: 10 | K35: =VLOOKUP($A35,쿼리1[[ID]:[열1]],3,FALSE) -> 10 | L35: arcels.attack1 | M35: arcels.attack2 | N35: arcels.attack3 | O35: arcels.active1 | P35: arcels.active2 | Q35: arcels.passive | R35: arcels.passive.Ex | T35: arcels.ult | U35: arcels.ult.B | V35: TRUE | W35: Character/Prefabs/m_attacker_arcels_enemy_1 | Y35: character_arcels_01 | AC35: 0.9 | AG35: AttributeBlue
A36: 1110701015 | B36: 쉐리 | C36: shery | D36: Name.Character.shery | E36: Ranger | F36: Fac_sti_swo | G36: TRUE | H36: FALSE | I36: FALSE | J36: 10 | K36: =VLOOKUP($A36,쿼리1[[ID]:[열1]],3,FALSE) -> 10 | L36: shery.attack1 | M36: shery.attack2 | N36: shery.attack3 | O36: m.shery.active1 | P36: m.shery.active2 | Q36: m.shery.passive | T36: m.shery.ult | V36: TRUE | W36: Character/Prefabs/m_ranger_shery_enemy_1 | Y36: character_shery_01 | AC36: 0.9 | AG36: AttributeRed
A37: 1110701016 | B37: 메리샤 | C37: melissa | D37: Name.Character.melissa | E37: Tanker | F37: Fac_art_app | G37: TRUE | H37: FALSE | I37: FALSE | J37: 10 | K37: =VLOOKUP($A37,쿼리1[[ID]:[열1]],3,FALSE) -> 10 | L37: melissa.attack1 | M37: melissa.attack2 | N37: melissa.attack3 | O37: melissa.active1 | P37: melissa.active2 | Q37: melissa.passive | R37: melissa.passive.Ex | T37: melissa.ult | U37: melissa.ult.B | V37: TRUE | W37: Character/Prefabs/m_tanker_melissa_enemy_1 | Y37: character_melissa_01 | AC37: 0.9 | AG37: AttributeGreen
A38: 1110701017 | B38: 시아 | C38: sia | D38: Name.Character.sia | E38: Attacker | F38: Fac_rim_ode | G38: TRUE | H38: FALSE | I38: FALSE | J38: 10 | K38: =VLOOKUP($A38,쿼리1[[ID]:[열1]],3,FALSE) -> 10 | L38: sia.attack1 | M38: sia.attack2 | N38: sia.attack3 | O38: sia.active1 | P38: sia.active2 | Q38: sia.passive | T38: sia.ult | U38: sia.ult.B | V38: TRUE | W38: Character/Prefabs/m_attacker_sia_enemy_1 | Y38: character_sia_01 | AC38: 0.9 | AG38: AttributeGreen
A39: 1110701018 | B39: 카나타 | C39: kanata | D39: Name.Character.kanata | E39: Ranger | F39: Fac_rim_its | G39: TRUE | H39: FALSE | I39: FALSE | J39: 10 | K39: =VLOOKUP($A39,쿼리1[[ID]:[열1]],3,FALSE) -> 10 | L39: kanata.attack1 | M39: kanata.attack2 | N39: kanata.attack3 | O39: kanata.active1 | P39: kanata.active2 | Q39: kanata.passive | T39: kanata.ult | U39: kanata.ult.B | V39: TRUE | W39: Character/Prefabs/m_ranger_kanata_enemy_1 | Y39: character_kanata_01 | AC39: 0.9 | AG39: AttributeBlue
A40: 1110701019 | B40: 레이호우 | C40: rayhou | D40: Name.Character.rayhou | E40: Supporter | F40: Fac_sti_ast | G40: TRUE | H40: FALSE | I40: FALSE | J40: 10 | K40: =VLOOKUP($A40,쿼리1[[ID]:[열1]],3,FALSE) -> 10 | L40: rayhou.attack1 | M40: rayhou.attack2 | N40: rayhou.attack3 | O40: m.rayhou.active1 | P40: m.rayhou.active2 | Q40: m.rayhou.passive | R40: m.rayhou.passive.Ex | T40: m.rayhou.ult | U40: m.rayhou.ult.B | V40: TRUE | W40: Character/Prefabs/m_supporter_rayhou_enemy_1 | Y40: character_rayhou_01 | AC40: 0.9 | AG40: AttributeGold
...

Sheet Monster.Contents
A1: Id | B1: #기획 | C1: #기획 | D1: Name | E1: Type | F1: FactionGroudId | G1: Attackable | H1: Boss | I1: UseHpSlice | J1: Radius | K1: MoveValue | L1: NormalSkill1 | M1: NormalSkill2 | N1: NormalSkill3 | O1: Skill1 | P1: Skill2 | Q1: Skill3 | R1: Skill4 | S1: Skill5 | T1: UltimateSkill | U1: UltimateExSkill | V1: Left | W1: PrefabBattle | X1: PrefabSpine | Y1: Icon | Z1: UltimateTimeline | AA1: VictoryTimeline | AB1: DieSound | AC1: Scale | AD1: CriticalEffect | AE1: StartTimeline | AF1: EndTimeline | AG1: Attribute
A2: *long | B2: # | C2: # | D2: string | E2: ClassType | F2: $FactionGroup? | G2: bool | H2: bool | I2: bool | J2: int | K2: int | L2: $SkillGroup? | M2: $SkillGroup? | N2: $SkillGroup? | O2: $SkillGroup? | P2: $SkillGroup? | Q2: $SkillGroup? | R2: $SkillGroup? | S2: $SkillGroup? | T2: $SkillGroup? | U2: $SkillGroup? | V2: bool | W2: string | X2: string | Y2: string | Z2: string | AA2: string | AB2: string | AC2: float | AD2: string | AE2: string | AF2: string | AG2: AttributeType
A3: common | B3: #사용처 | C3: #리소스명 | D3: client | E3: common | F3: common | G3: common | H3: common | I3: client | J3: common | K3: common | L3: common | M3: common | N3: common | O3: common | P3: common | Q3: common | R3: common | S3: common | T3: common | U3: common | V3: client | W3: client | X3: client | Y3: client | Z3: client | AA3: client | AB3: client | AC3: client | AD3: client | AE3: common | AF3: common | AG3: common
A4: 1110601001 | B4: WorldRaid | C4: 에페리우스 | D4: ="Monster.Name."&VLOOKUP($C4,'#Data'!$B$2:$J$344,2,FALSE) -> Monster.Name.eperiusunit_1 | E4: None | F4: Fac_nul_ind | G4: TRUE | H4: =IF(VLOOKUP($C4,'#Data'!$B$2:$J$344,4,FALSE)="보스",TRUE,FALSE) -> TRUE | I4: TRUE | J4: 40 | K4: 10 | L4: =$B4&"."&VLOOKUP($C4,'#Data'!$B$2:$J$344,2,FALSE)&".attack0"&RIGHT(L$1,1) -> WorldRaid.eperiusunit_1.attack01 | M4: =$B4&"."&VLOOKUP($C4,'#Data'!$B$2:$J$344,2,FALSE)&".attack0"&RIGHT(M$1,1) -> WorldRaid.eperiusunit_1.attack02 | N4: =$B4&"."&VLOOKUP($C4,'#Data'!$B$2:$J$344,2,FALSE)&".attack0"&RIGHT(N$1,1) -> WorldRaid.eperiusunit_1.attack03 | O4: =$B4&"."&VLOOKUP($C4,'#Data'!$B$2:$J$344,2,FALSE)&".skill0"&RIGHT(O$1,1) -> WorldRaid.eperiusunit_1.skill01 | P4: =$B4&"."&VLOOKUP($C4,'#Data'!$B$2:$J$344,2,FALSE)&".skill0"&RIGHT(P$1,1) -> WorldRaid.eperiusunit_1.skill02 | Q4: =$B4&"."&VLOOKUP($C4,'#Data'!$B$2:$J$344,2,FALSE)&".skill0"&RIGHT(Q$1,1) -> WorldRaid.eperiusunit_1.skill03 | R4: =$B4&"."&VLOOKUP($C4,'#Data'!$B$2:$J$344,2,FALSE)&".skill0"&RIGHT(R$1,1) -> WorldRaid.eperiusunit_1.skill04 | S4: WorldRaid.eperiusunit_1.passive01 | V4: FALSE | W4: ="Character/Prefabs/"&VLOOKUP($C4,'#Data'!$B$3:$I$344,8,FALSE) -> Character/Prefabs/m_boss_ranger_eperiusunit_1 | Y4: =VLOOKUP($C4,'#Data'!$B$3:$I$344,8,FALSE) -> m_boss_ranger_eperiusunit_1 | AB4: Die_machine | AC4: 1.4 | AE4: Character/Timeline/02_MON/eperiusunit_1/appearance | AF4: Character/Timeline/02_MON/eperiusunit_1/die | AG4: AttributeNone
